Workbook

Sheet Índice
B2: Información General | C2: Liga
B3: Resumen Ejecutivo | C3: Dashboard_Ex
B5: Funcionalidades | C5: Liga
B6: Funcionalidades Onboarding | C6: BD_Onboarding
B7: Funcionalidades Operaciones | C7: BD_Operaciones
B8: Funcionalidades Post Venta | C8: BD_PostVenta
B10: Service Blueprint | C10: Liga
B11: Onboarding TDC Apolo | C11: Onboarding TDC
B12: Operaciones | C12: Operaciones
B13: Post Venta | C13: Post Venta
B15: Inventario de Datos | C15: Liga
B16: Onboarding (Apolo) | C16: Inventario de Datos Apolo
B17: Operaciones (TDC)
B18: Post-Venta (TDC)

Sheet Dashboard_Ex
B2: FUNCIONALIDADES MVP TDC VISA
B3: Proceso | C3: Funcionalidades Totales | D3: Funcionalidades Habilitadas | E3: Grado de Avance
B4: Onboarding | C4: =Dashboard_Control!D17 -> 73 | D4: 31 | E4: =D4/C4 -> 0.42465753
B5: Operaciones | C5: =Dashboard_Control!D23 -> 66 | D5: 0 | E5: 0
B6: Post Venta | C6: =Dashboard_Control!D29 -> #REF! | D6: 0 | E6: 0
B7: Total | C7: =SUM(C4:C6) -> #REF! | D7: =SUM(D4:D6) -> 31 | E7: =SUM(E4:E6) -> 0.42465753
B10: APIs MVP TDC VISA
B11: Proceso | C11: Funcionalidades | D11: API's Estimadas | E11: Diseño BIAN | G11: Diseño Técnico Level Up | I11: Desarrollo Level Up | K11: Pruebas | M11: Liberación
B12: Onboarding | C12: =Dashboard_Control!D17 -> 73 | D12: =Dashboard_Control!G17 -> 294 | E12: 100 | F12: =E12/D12 -> 0.34013605 | G12: 21 | H12: =G12/D12 -> 0.071428571 | I12: 21 | J12: =I12/D12 -> 0.071428571 | K12: 0 | L12: =K12/D12 -> 0 | M12: 0 | N12: =M12/D12 -> 0
B13: Operaciones | C13: =Dashboard_Control!D23 -> 66 | D13: =Dashboard_Control!G23 -> 3080 | E13: =Dashboard_Control!H23 -> 65 | F13: =E13/D13 -> 0.021103896 | G13: 0 | H13: =G13/D13 -> 0 | I13: 0 | J13: =I13/D13 -> 0 | K13: 0 | L13: =K13/D13 -> 0 | M13: 0 | N13: =M13/D13 -> 0
B14: Post Venta | C14: =Dashboard_Control!D29 -> #REF! | D14: =Dashboard_Control!G29 -> 0 | E14: 0 | F14: =E14/D14 -> #DIV/0! | G14: 0 | H14: =G14/D14 -> #DIV/0! | I14: 0 | J14: =I14/D14 -> #DIV/0! | K14: 0 | L14: =K14/D14 -> #DIV/0! | M14: 0 | N14: =M14/D14 -> #DIV/0!
B15: Otros | C15: - | D15: - | E15: 149 | F15: -% | G15: - | H15: -% | I15: - | J15: -% | K15: - | L15: -% | M15: - | N15: -%
B16: Total | C16: =SUM(C12:C15) -> #REF! | D16: =SUM(D12:D15) -> 3374 | E16: =SUM(E12:E15) -> 314 | F16: =E16/D16 -> 0.093064612 | G16: =SUM(G12:G15) -> 21 | H16: =G16/D16 -> 0.0062240664 | I16: =SUM(I12:I15) -> 21 | J16: =I16/D16 -> 0.0062240664 | K16: =SUM(K12:K15) -> 0 | L16: =K16/D16 -> 0 | M16: =SUM(M12:M15) -> 0 | N16: =M16/D16 -> 0
C18: OB | D18: OPS | E18: P.Venta | F18: Reportes | G18: Carpeta CNBV
B19: FX | C19: 76 | D19: =C13 -> 66 | E19: =C14 -> #REF! | F19: 54 | G19: 24
B20: API's | C20: 273 | D20: =D13 -> 3080 | E20: =D14 -> 0
B21: Service BP (As Is)
B22: Service BP (To Be)
A23: Apificación | B23: Diseño BIAN
B24: Diseño Técnico
B25: Desarrollo
B26: Pruebas
B27: Liberación | C27: 5 DE 273
B28: Datos Aprovisionados | C28: 23 DE 605 | D28: 800 | E28: 350 | F28: 1
B29: Insumos Carpeta de Autorización | C29: 8 | D29: 19
B33: DATOS MVP TDC VISA
B34: Proceso | C34: Datos Totales Generados | D34: Datos Totales Aprovisionados | E34: Grado de Avance
B35: Onboarding | C35: 235 | D35: 5 | E35: =D35/C35 -> 0.021276596
B36: Operaciones | C36: =Dashboard_Control!D53 -> 0 | D36: 0 | E36: 0
B37: Post Venta | C37: =Dashboard_Control!D59 -> 0 | D37: 0 | E37: 0
B38: Total | C38: =SUM(C35:C37) -> 235 | D38: =SUM(D35:D37) -> 5 | E38: =SUM(E35:E37) -> 0.021276596

Sheet BD_Onboarding
D1: Apificación | N1: Canal | V1: Avance de Funcionalidad | AF1: Solo APIS | AK1: TOTAL | AQ1: diseñadas | AS1: Dominio | AT1: Sistema | AW1: totales | AY1: Dominio | AZ1: Sistema
A2: ID | B2: Tipo | C2: DESCRIPCION | D2: Base | E2: Recepción | F2: Negocio | G2: Dominio | H2: Sistema | I2: APIs proceso actual | J2: SPL proceso actual | K2: APIs Estimadas To Be | L2: Estatus de Api | M2: Responsable | N2: Apolo | O2: Sucursal | P2: MAD | Q2: App | R2: CAT | S2: BPI | T2: BO | U2: ATM | V2: Contemplado MVP | W2: Estatus | X2: Comentario | Y2: Fecha Inicio | Z2: Fecha Estimada | AB2: Funcionalidades Totales Habilitadas (SOLO APIS) | AC2: Funcionalidades Totales Habilitadas (diseñadas + SDK+ SAAS) | AD2: Conteo Fx | AF2: totales actuales | AG2: totales esperado | AH2: Completadas actual | AI2: Completas esperado | AK2: totales actuales | AL2: totales esperado | AM2: Completadas actual | AN2: Completas esperado | AP2: Apis diseñadas total | AQ2: Recepción | AR2: Negocio | AS2: Transformación | AT2: Sistema | AV2: Apis diseñadas total | AW2: Recepción | AX2: Negocio | AY2: Transformación | AZ2: Sistema
A3: IC-001 | B3: Onboarding | C3: Capturar la identificación | E3: /experience/sales/partyLifecycleManagement/v1/documentation/capture | F3: N/A | G3: /sales/partyLifecycleManagement/v1/documentation/capture | H3: /system/sales/partyLifecycleManagement/v1/documentation/capture | J3: 3 | K3: =J3*$J$147 -> 10.5 | L3: Backlog | M3: Rafael Elizalde | N3: x | V3: Sí | W3: Por definir | AB3: =IF(AG3=0,0,IF(AF3=AG3,1,0))*AD3 -> 0 | AC3: =IF(AK3=AL3,1,0)*AD3 -> 1 | AD3: =IF(ISNUMBER(MATCH(A3,$A$2:A2,0)),0,1) -> 1 | AF3: =SUMIFS(AH$3:AH$251,$A$3:$A$251,$A3) -> 1 | AG3: =SUMIFS(AI$3:AI$251,$A$3:$A$251,$A3) -> 2 | AH3: =IF(SUM(AW3:AZ3)=0,0,IF(SUM(AQ3:AT3)=SUM(AW3:AZ3),1,0)) -> 1 | AI3: 1 | AK3: =SUMIFS(AM$3:AM$251,$A$3:$A$251,$A3) -> 2 | AL3: =SUMIFS(AN$3:AN$251,$A$3:$A$251,$A3) -> 2 | AM3: =IF(SUM(AQ3:AT3)=SUM(AW3:AZ3),1,0) -> 1 | AN3: 1 | AP3: =SUM(AQ3:AT3) -> 3 | AQ3: =IF(OR(E3="",E3="TBD",E3="N/A",E3="SDK",E3="SAAS"),0,1) -> 1 | AR3: =IF(OR(F3="",F3="TBD",F3="N/A",F3="SDK",F3="SAAS"),0,1) -> 0 | AS3: =IF(OR(G3="",G3="TBD",G3="N/A",G3="SDK",G3="SAAS"),0,1) -> 1 | AT3: =IF(OR(H3="",H3="TBD",H3="N/A",H3="SDK",H3="SAAS"),0,1) -> 1 | AV3: =SUM(AW3:AZ3) -> 3 | AW3: =IF(OR(E3="",E3="N/A",E3="SDK",E3="SAAS"),0,1) -> 1 | AX3: =IF(OR(F3="",F3="N/A",F3="SDK",F3="SAAS"),0,1) -> 0 | AY3: =IF(OR(G3="",G3="N/A",G3="SDK",G3="SAAS"),0,1) -> 1 | AZ3: =IF(OR(H3="",H3="N/A",H3="SDK",H3="SAAS"),0,1) -> 1
A4: IC-001 | B4: Onboarding | C4: Capturar la identificación | D4: SDK | E4: SDK | F4: SDK | G4: SDK | H4: SDK | L4: Backlog | M4: Rafael Elizalde | N4: x | V4: Sí | W4: Por definir | AB4: =IF(AG4=0,0,IF(AF4=AG4,1,0))*AD4 -> 0 | AC4: =IF(AK4=AL4,1,0)*AD4 -> 0 | AD4: =IF(ISNUMBER(MATCH(A4,$A$2:A3,0)),0,1) -> 0 | AF4: =SUMIFS(AH$3:AH$251,$A$3:$A$251,$A4) -> 1 | AG4: =SUMIFS(AI$3:AI$77,$A$3:$A$77,$A4) -> 2 | AH4: =IF(SUM(AW4:AZ4)=0,0,IF(SUM(AQ4:AT4)=SUM(AW4:AZ4),1,0)) -> 0 | AI4: 1 | AK4: =SUMIFS(AM$3:AM$251,$A$3:$A$251,$A4) -> 2 | AL4: =SUMIFS(AN$3:AN$251,$A$3:$A$251,$A4) -> 2 | AM4: =IF(SUM(AQ4:AT4)=SUM(AW4:AZ4),1,0) -> 1 | AN4: 1 | AP4: =SUM(AQ4:AT4) -> 0 | AQ4: =IF(OR(E4="",E4="TBD",E4="N/A",E4="SDK",E4="SAAS"),0,1) -> 0 | AR4: =IF(OR(F4="",F4="TBD",F4="N/A",F4="SDK",F4="SAAS"),0,1) -> 0 | AS4: =IF(OR(G4="",G4="TBD",G4="N/A",G4="SDK",G4="SAAS"),0,1) -> 0 | AT4: =IF(OR(H4="",H4="TBD",H4="N/A",H4="SDK",H4="SAAS"),0,1) -> 0 | AV4: =SUM(AW4:AZ4) -> 0 | AW4: =IF(OR(E4="",E4="N/A",E4="SDK",E4="SAAS"),0,1) -> 0 | AX4: =IF(OR(F4="",F4="N/A",F4="SDK",F4="SAAS"),0,1) -> 0 | AY4: =IF(OR(G4="",G4="N/A",G4="SDK",G4="SAAS"),0,1) -> 0 | AZ4: =IF(OR(H4="",H4="N/A",H4="SDK",H4="SAAS"),0,1) -> 0
A5: IC-002 | B5: Onboarding | C5: Capacidad de Auto-clasificación de la identificación y retroalimentación en tiempo real (INE, Identificación de Extranjeros, Pasaporte) | D5: SDK | E5: SDK | F5: SDK | G5: SDK | H5: SDK | K5: =J5*$J$147 -> 0 | L5: Backlog | M5: Rafael Elizalde | N5: x | V5: Sí | W5: Por definir | AB5: =IF(AG5=0,0,IF(AF5=AG5,1,0))*AD5 -> 0 | AC5: =IF(AK5=AL5,1,0)*AD5 -> 1 | AD5: =IF(ISNUMBER(MATCH(A5,$A$2:A3,0)),0,1) -> 1 | AF5: =SUMIFS(AH$3:AH$251,$A$3:$A$251,$A5) -> 0 | AG5: =SUMIFS(AI$3:AI$77,$A$3:$A$77,$A5) -> 1 | AH5: =IF(SUM(AW5:AZ5)=0,0,IF(SUM(AQ5:AT5)=SUM(AW5:AZ5),1,0)) -> 0 | AI5: 1 | AK5: =SUMIFS(AM$3:AM$251,$A$3:$A$251,$A5) -> 1 | AL5: =SUMIFS(AN$3:AN$251,$A$3:$A$251,$A5) -> 1 | AM5: =IF(SUM(AQ5:AT5)=SUM(AW5:AZ5),1,0) -> 1 | AN5: 1 | AP5: =SUM(AQ5:AT5) -> 0 | AQ5: =IF(OR(E5="",E5="TBD",E5="N/A",E5="SDK",E5="SAAS"),0,1) -> 0 | AR5: =IF(OR(F5="",F5="TBD",F5="N/A",F5="SDK",F5="SAAS"),0,1) -> 0 | AS5: =IF(OR(G5="",G5="TBD",G5="N/A",G5="SDK",G5="SAAS"),0,1) -> 0 | AT5: =IF(OR(H5="",H5="TBD",H5="N/A",H5="SDK",H5="SAAS"),0,1) -> 0 | AV5: =SUM(AW5:AZ5) -> 0 | AW5: =IF(OR(E5="",E5="N/A",E5="SDK",E5="SAAS"),0,1) -> 0 | AX5: =IF(OR(F5="",F5="N/A",F5="SDK",F5="SAAS"),0,1) -> 0 | AY5: =IF(OR(G5="",G5="N/A",G5="SDK",G5="SAAS"),0,1) -> 0 | AZ5: =IF(OR(H5="",H5="N/A",H5="SDK",H5="SAAS"),0,1) -> 0
A6: IC-003 | B6: Onboarding | C6: Validar y contrastar el rostro del documento utilizado como documento de identificación en el proceso | E6: /experience/crossChannel/sessionDialogue/v1/customerContactSelfieProcedure/initiate | F6: N/A | G6: /crossChannel/sessionDialogue/v1/customerContactSelfieProcedure/initiate | H6: /system/crossChannel/sessionDialogue/v1/customerContactSessionProcedure/initiate | K6: =J6*$J$147 -> 0 | L6: Backlog | M6: Rafael Elizalde | N6: x | V6: Sí | W6: Por definir | AB6: =IF(AG6=0,0,IF(AF6=AG6,1,0))*AD6 -> 1 | AC6: =IF(AK6=AL6,1,0)*AD6 -> 1 | AD6: =IF(ISNUMBER(MATCH(A6,$A$2:A5,0)),0,1) -> 1 | AF6: =SUMIFS(AH$3:AH$251,$A$3:$A$251,$A6) -> 1 | AG6: =SUMIFS(AI$3:AI$77,$A$3:$A$77,$A6) -> 1 | AH6: =IF(SUM(AW6:AZ6)=0,0,IF(SUM(AQ6:AT6)=SUM(AW6:AZ6),1,0)) -> 1 | AI6: 1 | AK6: =SUMIFS(AM$3:AM$251,$A$3:$A$251,$A6) -> 1 | AL6: =SUMIFS(AN$3:AN$251,$A$3:$A$251,$A6) -> 1 | AM6: =IF(SUM(AQ6:AT6)=SUM(AW6:AZ6),1,0) -> 1 | AN6: 1 | AP6: =SUM(AQ6:AT6) -> 3 | AQ6: =IF(OR(E6="",E6="TBD",E6="N/A",E6="SDK",E6="SAAS"),0,1) -> 1 | AR6: =IF(OR(F6="",F6="TBD",F6="N/A",F6="SDK",F6="SAAS"),0,1) -> 0 | AS6: =IF(OR(G6="",G6="TBD",G6="N/A",G6="SDK",G6="SAAS"),0,1) -> 1 | AT6: =IF(OR(H6="",H6="TBD",H6="N/A",H6="SDK",H6="SAAS"),0,1) -> 1 | AV6: =SUM(AW6:AZ6) -> 3 | AW6: =IF(OR(E6="",E6="N/A",E6="SDK",E6="SAAS"),0,1) -> 1 | AX6: =IF(OR(F6="",F6="N/A",F6="SDK",F6="SAAS"),0,1) -> 0 | AY6: =IF(OR(G6="",G6="N/A",G6="SDK",G6="SAAS"),0,1) -> 1 | AZ6: =IF(OR(H6="",H6="N/A",H6="SDK",H6="SAAS"),0,1) -> 1
A7: IC-003 | B7: Onboarding | C7: Validar y contrastar el rostro del documento utilizado como documento de identificación en el proceso | D7: SDK | E7: SDK | F7: SDK | G7: SDK | H7: SDK
A8: IC-004 | B8: Onboarding | C8: Captura automática el rostro del solicitante / cliente de forma segura e inteligente | D8: SDK | E8: SDK | F8: SDK | G8: SDK | H8: SDK | K8: =J8*$J$147 -> 0 | L8: Backlog | M8: Rafael Elizalde | N8: x | V8: Sí | W8: Por definir | AB8: =IF(AG8=0,0,IF(AF8=AG8,1,0))*AD8 -> 0 | AC8: =IF(AK8=AL8,1,0)*AD8 -> 1 | AD8: =IF(ISNUMBER(MATCH(A8,$A$2:A6,0)),0,1) -> 1 | AF8: =SUMIFS(AH$3:AH$251,$A$3:$A$251,$A8) -> 0 | AG8: =SUMIFS(AI$3:AI$77,$A$3:$A$77,$A8) -> 1 | AH8: =IF(SUM(AW8:AZ8)=0,0,IF(SUM(AQ8:AT8)=SUM(AW8:AZ8),1,0)) -> 0 | AI8: 1 | AK8: =SUMIFS(AM$3:AM$251,$A$3:$A$251,$A8) -> 1 | AL8: =SUMIFS(AN$3:AN$251,$A$3:$A$251,$A8) -> 1 | AM8: =IF(SUM(AQ8:AT8)=SUM(AW8:AZ8),1,0) -> 1 | AN8: 1 | AP8: =SUM(AQ8:AT8) -> 0 | AQ8: =IF(OR(E8="",E8="TBD",E8="N/A",E8="SDK",E8="SAAS"),0,1) -> 0 | AR8: =IF(OR(F8="",F8="TBD",F8="N/A",F8="SDK",F8="SAAS"),0,1) -> 0 | AS8: =IF(OR(G8="",G8="TBD",G8="N/A",G8="SDK",G8="SAAS"),0,1) -> 0 | AT8: =IF(OR(H8="",H8="TBD",H8="N/A",H8="SDK",H8="SAAS"),0,1) -> 0 | AV8: =SUM(AW8:AZ8) -> 0 | AW8: =IF(OR(E8="",E8="N/A",E8="SDK",E8="SAAS"),0,1) -> 0 | AX8: =IF(OR(F8="",F8="N/A",F8="SDK",F8="SAAS"),0,1) -> 0 | AY8: =IF(OR(G8="",G8="N/A",G8="SDK",G8="SAAS"),0,1) -> 0 | AZ8: =IF(OR(H8="",H8="N/A",H8="SDK",H8="SAAS"),0,1) -> 0
A9: IC-005 | B9: Onboarding | C9: Probar la captura de dirección (OCR comprobante domicilio) | D9: SDK | E9: SDK | F9: SDK | G9: SDK | H9: SDK | K9: =J9*$J$147 -> 0 | L9: Backlog | M9: Rafael Elizalde | N9: x | V9: Sí | W9: Por definir | AB9: =IF(AG9=0,0,IF(AF9=AG9,1,0))*AD9 -> 0 | AC9: =IF(AK9=AL9,1,0)*AD9 -> 1 | AD9: =IF(ISNUMBER(MATCH(A9,$A$2:A8,0)),0,1) -> 1 | AF9: =SUMIFS(AH$3:AH$251,$A$3:$A$251,$A9) -> 0 | AG9: =SUMIFS(AI$3:AI$77,$A$3:$A$77,$A9) -> 1 | AH9: =IF(SUM(AW9:AZ9)=0,0,IF(SUM(AQ9:AT9)=SUM(AW9:AZ9),1,0)) -> 0 | AI9: 1 | AK9: =SUMIFS(AM$3:AM$251,$A$3:$A$251,$A9) -> 1 | AL9: =SUMIFS(AN$3:AN$251,$A$3:$A$251,$A9) -> 1 | AM9: =IF(SUM(AQ9:AT9)=SUM(AW9:AZ9),1,0) -> 1 | AN9: 1 | AP9: =SUM(AQ9:AT9) -> 0 | AQ9: =IF(OR(E9="",E9="TBD",E9="N/A",E9="SDK",E9="SAAS"),0,1) -> 0 | AR9: =IF(OR(F9="",F9="TBD",F9="N/A",F9="SDK",F9="SAAS"),0,1) -> 0 | AS9: =IF(OR(G9="",G9="TBD",G9="N/A",G9="SDK",G9="SAAS"),0,1) -> 0 | AT9: =IF(OR(H9="",H9="TBD",H9="N/A",H9="SDK",H9="SAAS"),0,1) -> 0 | AV9: =SUM(AW9:AZ9) -> 0 | AW9: =IF(OR(E9="",E9="N/A",E9="SDK",E9="SAAS"),0,1) -> 0 | AX9: =IF(OR(F9="",F9="N/A",F9="SDK",F9="SAAS"),0,1) -> 0 | AY9: =IF(OR(G9="",G9="N/A",G9="SDK",G9="SAAS"),0,1) -> 0 | AZ9: =IF(OR(H9="",H9="N/A",H9="SDK",H9="SAAS"),0,1) -> 0
A10: IC-006 | B10: Onboarding | C10: Validar el Celular a través de un OTP enviado por SMS | E10: /experience/salesAndService/v1/onBoardingPhoneParty/evaluate | F10: /channels/v1/onBoardingPhoneParty/evaluate | G10: /crossChannel/sessionDialogue/v1/customerContactSessionProcedure/capture /operationalServices/issuedDeviceAdministration/v1/tokenAssignment/initiate | H10: /system/crossChannel/sessionDialogue/v1/customerContactSessionProcedure/capture /system/operationalServices/issuedDeviceAdministration/v1/tokenAssignment/initiate | J10: 4 | K10: =J10*$J$147 -> 14 | L10: Backlog | M10: Rafael Elizalde | N10: x | V10: Sí | W10: Por definir | AB10: =IF(AG10=0,0,IF(AF10=AG10,1,0))*AD10 -> 1 | AC10: =IF(AK10=AL10,1,0)*AD10 -> 1 | AD10: =IF(ISNUMBER(MATCH(A10,$A$2:A9,0)),0,1) -> 1 | AF10: =SUMIFS(AH$3:AH$251,$A$3:$A$251,$A10) -> 2 | AG10: =SUMIFS(AI$3:AI$77,$A$3:$A$77,$A10) -> 2 | AH10: =IF(SUM(AW10:AZ10)=0,0,IF(SUM(AQ10:AT10)=SUM(AW10:AZ10),1,0)) -> 1 | AI10: 1 | AK10: =SUMIFS(AM$3:AM$251,$A$3:$A$251,$A10) -> 2 | AL10: =SUMIFS(AN$3:AN$251,$A$3:$A$251,$A10) -> 2 | AM10: =IF(SUM(AQ10:AT10)=SUM(AW10:AZ10),1,0) -> 1 | AN10: 1 | AP10: =SUM(AQ10:AT10) -> 4 | AQ10: =IF(OR(E10="",E10="TBD",E10="N/A",E10="SDK",E10="SAAS"),0,1) -> 1 | AR10: =IF(OR(F10="",F10="TBD",F10="N/A",F10="SDK",F10="SAAS"),0,1) -> 1 | AS10: =IF(OR(G10="",G10="TBD",G10="N/A",G10="SDK",G10="SAAS"),0,1) -> 1 | AT10: =IF(OR(H10="",H10="TBD",H10="N/A",H10="SDK",H10="SAAS"),0,1) -> 1 | AV10: =SUM(AW10:AZ10) -> 4 | AW10: =IF(OR(E10="",E10="N/A",E10="SDK",E10="SAAS"),0,1) -> 1 | AX10: =IF(OR(F10="",F10="N/A",F10="SDK",F10="SAAS"),0,1) -> 1 | AY10: =IF(OR(G10="",G10="N/A",G10="SDK",G10="SAAS"),0,1) -> 1 | AZ10: =IF(OR(H10="",H10="N/A",H10="SDK",H10="SAAS"),0,1) -> 1
A11: IC-006 | B11: Onboarding | C11: Validar el Celular a través de un OTP enviado por SMS | E11: /experience/operationalservices/issueddeviceadministration/v1/tokenAssignment/evaluate | F11: /customers/v1/ocrDocument/retrieve | G11: /operationalServices/issuedDeviceAdministration/v1/tokenAssignment/evaluate | H11: /system/operationalServices/issuedDeviceAdministration | K11: =J11*$J$147 -> 0 | L11: Backlog | M11: Rafael Elizalde | N11: x | V11: Sí | W11: Por definir | AB11: =IF(AG11=0,0,IF(AF11=AG11,1,0))*AD11 -> 0 | AC11: =IF(AK11=AL11,1,0)*AD11 -> 0 | AD11: =IF(ISNUMBER(MATCH(A11,$A$2:A10,0)),0,1) -> 0 | AF11: =SUMIFS(AH$3:AH$251,$A$3:$A$251,$A11) -> 2 | AG11: =SUMIFS(AI$3:AI$77,$A$3:$A$77,$A11) -> 2 | AH11: =IF(SUM(AW11:AZ11)=0,0,IF(SUM(AQ11:AT11)=SUM(AW11:AZ11),1,0)) -> 1 | AI11: 1 | AK11: =SUMIFS(AM$3:AM$251,$A$3:$A$251,$A11) -> 2 | AL11: =SUMIFS(AN$3:AN$251,$A$3:$A$251,$A11) -> 2 | AM11: =IF(SUM(AQ11:AT11)=SUM(AW11:AZ11),1,0) -> 1 | AN11: 1 | AP11: =SUM(AQ11:AT11) -> 4 | AQ11: =IF(OR(E11="",E11="TBD",E11="N/A",E11="SDK",E11="SAAS"),0,1) -> 1 | AR11: =IF(OR(F11="",F11="TBD",F11="N/A",F11="SDK",F11="SAAS"),0,1) -> 1 | AS11: =IF(OR(G11="",G11="TBD",G11="N/A",G11="SDK",G11="SAAS"),0,1) -> 1 | AT11: =IF(OR(H11="",H11="TBD",H11="N/A",H11="SDK",H11="SAAS"),0,1) -> 1 | AV11: =SUM(AW11:AZ11) -> 4 | AW11: =IF(OR(E11="",E11="N/A",E11="SDK",E11="SAAS"),0,1) -> 1 | AX11: =IF(OR(F11="",F11="N/A",F11="SDK",F11="SAAS"),0,1) -> 1 | AY11: =IF(OR(G11="",G11="N/A",G11="SDK",G11="SAAS"),0,1) -> 1 | AZ11: =IF(OR(H11="",H11="N/A",H11="SDK",H11="SAAS"),0,1) -> 1
A12: IC-007 | B12: Onboarding | C12: Validar el Email a través de un OTP enviado por correo electrónico | E12: /experience/channels/v1/onBoardingEmailParty/evaluate | F12: TBD | G12: TBD | H12: TBD | J12: 2 | K12: =J12*$J$147 -> 7 | L12: Backlog | M12: Rafael Elizalde | N12: x | V12: Sí | W12: Por definir | AB12: =IF(AG12=0,0,IF(AF12=AG12,1,0))*AD12 -> 0 | AC12: =IF(AK12=AL12,1,0)*AD12 -> 0 | AD12: =IF(ISNUMBER(MATCH(A12,$A$2:A11,0)),0,1) -> 1 | AF12: =SUMIFS(AH$3:AH$251,$A$3:$A$251,$A12) -> 0 | AG12: =SUMIFS(AI$3:AI$77,$A$3:$A$77,$A12) -> 1 | AH12: =IF(SUM(AW12:AZ12)=0,0,IF(SUM(AQ12:AT12)=SUM(AW12:AZ12),1,0)) -> 0 | AI12: 1 | AK12: =SUMIFS(AM$3:AM$251,$A$3:$A$251,$A12) -> 0 | AL12: =SUMIFS(AN$3:AN$251,$A$3:$A$251,$A12) -> 1 | AM12: =IF(SUM(AQ12:AT12)=SUM(AW12:AZ12),1,0) -> 0 | AN12: 1 | AP12: =SUM(AQ12:AT12) -> 1 | AQ12: =IF(OR(E12="",E12="TBD",E12="N/A",E12="SDK",E12="SAAS"),0,1) -> 1 | AR12: =IF(OR(F12="",F12="TBD",F12="N/A",F12="SDK",F12="SAAS"),0,1) -> 0 | AS12: =IF(OR(G12="",G12="TBD",G12="N/A",G12="SDK",G12="SAAS"),0,1) -> 0 | AT12: =IF(OR(H12="",H12="TBD",H12="N/A",H12="SDK",H12="SAAS"),0,1) -> 0 | AV12: =SUM(AW12:AZ12) -> 4 | AW12: =IF(OR(E12="",E12="N/A",E12="SDK",E12="SAAS"),0,1) -> 1 | AX12: =IF(OR(F12="",F12="N/A",F12="SDK",F12="SAAS"),0,1) -> 1 | AY12: =IF(OR(G12="",G12="N/A",G12="SDK",G12="SAAS"),0,1) -> 1 | AZ12: =IF(OR(H12="",H12="N/A",H12="SDK",H12="SAAS"),0,1) -> 1
A13: IC-008 | B13: Onboarding | C13: Extraer la información dentro del documento de identificación (OCR) | E13: /experience/customers/v1/ocrDocument/retrieve | F13: /customers/v1/ocrDocument/retrieve | G13: /sales/partyLifecycleManagement/v1/documentation/execute | H13: /system/sales/partyLifecycleManagement/v1/documentation/execute | J13: 1 | K13: =J13*$J$147 -> 3.5 | L13: Backlog | M13: Rafael Elizalde | N13: x | V13: Sí | W13: Por definir | AB13: =IF(AG13=0,0,IF(AF13=AG13,1,0))*AD13 -> 0 | AC13: =IF(AK13=AL13,1,0)*AD13 -> 1 | AD13: =IF(ISNUMBER(MATCH(A13,$A$2:A12,0)),0,1) -> 1 | AF13: =SUMIFS(AH$3:AH$251,$A$3:$A$251,$A13) -> 1 | AG13: =SUMIFS(AI$3:AI$77,$A$3:$A$77,$A13) -> 2 | AH13: =IF(SUM(AW13:AZ13)=0,0,IF(SUM(AQ13:AT13)=SUM(AW13:AZ13),1,0)) -> 1 | AI13: 1 | AK13: =SUMIFS(AM$3:AM$251,$A$3:$A$251,$A13) -> 2 | AL13: =SUMIFS(AN$3:AN$251,$A$3:$A$251,$A13) -> 2 | AM13: =IF(SUM(AQ13:AT13)=SUM(AW13:AZ13),1,0) -> 1 | AN13: 1 | AP13: =SUM(AQ13:AT13) -> 4 | AQ13: =IF(OR(E13="",E13="TBD",E13="N/A",E13="SDK",E13="SAAS"),0,1) -> 1 | AR13: =IF(OR(F13="",F13="TBD",F13="N/A",F13="SDK",F13="SAAS"),0,1) -> 1 | AS13: =IF(OR(G13="",G13="TBD",G13="N/A",G13="SDK",G13="SAAS"),0,1) -> 1 | AT13: =IF(OR(H13="",H13="TBD",H13="N/A",H13="SDK",H13="SAAS"),0,1) -> 1 | AV13: =SUM(AW13:AZ13) -> 4 | AW13: =IF(OR(E13="",E13="N/A",E13="SDK",E13="SAAS"),0,1) -> 1 | AX13: =IF(OR(F13="",F13="N/A",F13="SDK",F13="SAAS"),0,1) -> 1 | AY13: =IF(OR(G13="",G13="N/A",G13="SDK",G13="SAAS"),0,1) -> 1 | AZ13: =IF(OR(H13="",H13="N/A",H13="SDK",H13="SAAS"),0,1) -> 1
A14: IC-008 | B14: Onboarding | C14: Extraer la información dentro del documento de identificación (OCR) | D14: SDK | E14: SDK | F14: N/A | G14: N/A | H14: N/A | K14: =J14*$J$147 -> 0 | L14: Backlog | M14: Rafael Elizalde | N14: x | V14: Sí | W14: Por definir | AB14: =IF(AG14=0,0,IF(AF14=AG14,1,0))*AD14 -> 0 | AC14: =IF(AK14=AL14,1,0)*AD14 -> 0 | AD14: =IF(ISNUMBER(MATCH(A14,$A$2:A13,0)),0,1) -> 0 | AF14: =SUMIFS(AH$3:AH$251,$A$3:$A$251,$A14) -> 1 | AG14: =SUMIFS(AI$3:AI$77,$A$3:$A$77,$A14) -> 2 | AH14: =IF(SUM(AW14:AZ14)=0,0,IF(SUM(AQ14:AT14)=SUM(AW14:AZ14),1,0)) -> 0 | AI14: 1 | AK14: =SUMIFS(AM$3:AM$251,$A$3:$A$251,$A14) -> 2 | AL14: =SUMIFS(AN$3:AN$251,$A$3:$A$251,$A14) -> 2 | AM14: =IF(SUM(AQ14:AT14)=SUM(AW14:AZ14),1,0) -> 1 | AN14: 1 | AP14: =SUM(AQ14:AT14) -> 0 | AQ14: =IF(OR(E14="",E14="TBD",E14="N/A",E14="SDK",E14="SAAS"),0,1) -> 0 | AR14: =IF(OR(F14="",F14="TBD",F14="N/A",F14="SDK",F14="SAAS"),0,1) -> 0 | AS14: =IF(OR(G14="",G14="TBD",G14="N/A",G14="SDK",G14="SAAS"),0,1) -> 0 | AT14: =IF(OR(H14="",H14="TBD",H14="N/A",H14="SDK",H14="SAAS"),0,1) -> 0 | AV14: =SUM(AW14:AZ14) -> 0 | AW14: =IF(OR(E14="",E14="N/A",E14="SDK",E14="SAAS"),0,1) -> 0 | AX14: =IF(OR(F14="",F14="N/A",F14="SDK",F14="SAAS"),0,1) -> 0 | AY14: =IF(OR(G14="",G14="N/A",G14="SDK",G14="SAAS"),0,1) -> 0 | AZ14: =IF(OR(H14="",H14="N/A",H14="SDK",H14="SAAS"),0,1) -> 0
A15: IC-009 | B15: Onboarding | C15: Validar al prospecto / cliente contra la lista nominal del INE | E15: TBD | F15: TBD | G15: /sales/partyLifecycleManagement/v1/ine/evaluate | H15: /system/sales/partyLifecycleManagement/v1/ine/evaluate | K15: =J15*$J$147 -> 0 | L15: Backlog | M15: Rafael Elizalde | N15: x | V15: Sí | W15: Por definir | AB15: =IF(AG15=0,0,IF(AF15=AG15,1,0))*AD15 -> 0 | AC15: =IF(AK15=AL15,1,0)*AD15 -> 0 | AD15: =IF(ISNUMBER(MATCH(A15,$A$2:A13,0)),0,1) -> 1 | AF15: =SUMIFS(AH$3:AH$251,$A$3:$A$251,$A15) -> 0 | AG15: =SUMIFS(AI$3:AI$77,$A$3:$A$77,$A15) -> 2 | AH15: =IF(SUM(AW15:AZ15)=0,0,IF(SUM(AQ15:AT15)=SUM(AW15:AZ15),1,0)) -> 0 | AI15: 1 | AK15: =SUMIFS(AM$3:AM$251,$A$3:$A$251,$A15) -> 0 | AL15: =SUMIFS(AN$3:AN$251,$A$3:$A$251,$A15) -> 2 | AM15: =IF(SUM(AQ15:AT15)=SUM(AW15:AZ15),1,0) -> 0 | AN15: 1 | AP15: =SUM(AQ15:AT15) -> 2 | AQ15: =IF(OR(E15="",E15="TBD",E15="N/A",E15="SDK",E15="SAAS"),0,1) -> 0 | AR15: =IF(OR(F15="",F15="TBD",F15="N/A",F15="SDK",F15="SAAS"),0,1) -> 0 | AS15: =IF(OR(G15="",G15="TBD",G15="N/A",G15="SDK",G15="SAAS"),0,1) -> 1 | AT15: =IF(OR(H15="",H15="TBD",H15="N/A",H15="SDK",H15="SAAS"),0,1) -> 1 | AV15: =SUM(AW15:AZ15) -> 4 | AW15: =IF(OR(E15="",E15="N/A",E15="SDK",E15="SAAS"),0,1) -> 1 | AX15: =IF(OR(F15="",F15="N/A",F15="SDK",F15="SAAS"),0,1) -> 1 | AY15: =IF(OR(G15="",G15="N/A",G15="SDK",G15="SAAS"),0,1) -> 1 | AZ15: =IF(OR(H15="",H15="N/A",H15="SDK",H15="SAAS"),0,1) -> 1
A16: IC-009 | B16: Onboarding | C16: Validar al prospecto / cliente contra la lista nominal del INE | E16: TBD | F16: TBD | G16: /sales/partyLifecycleManagement/v1/ine/retrieve | H16: /system/sales/partyLifecycleManagement/v1/ine/retrieve | K16: =J16*$J$147 -> 0 | L16: Backlog | M16: Rafael Elizalde | N16: x | V16: Sí | W16: Por definir | AB16: =IF(AG16=0,0,IF(AF16=AG16,1,0))*AD16 -> 0 | AC16: =IF(AK16=AL16,1,0)*AD16 -> 0 | AD16: =IF(ISNUMBER(MATCH(A16,$A$2:A14,0)),0,1) -> 1 | AF16: =SUMIFS(AH$3:AH$251,$A$3:$A$251,$A16) -> 0 | AG16: =SUMIFS(AI$3:AI$77,$A$3:$A$77,$A16) -> 2 | AH16: =IF(SUM(AW16:AZ16)=0,0,IF(SUM(AQ16:AT16)=SUM(AW16:AZ16),1,0)) -> 0 | AI16: 1 | AK16: =SUMIFS(AM$3:AM$251,$A$3:$A$251,$A16) -> 0 | AL16: =SUMIFS(AN$3:AN$251,$A$3:$A$251,$A16) -> 2 | AM16: =IF(SUM(AQ16:AT16)=SUM(AW16:AZ16),1,0) -> 0 | AN16: 1 | AP16: =SUM(AQ16:AT16) -> 2 | AQ16: =IF(OR(E16="",E16="TBD",E16="N/A",E16="SDK",E16="SAAS"),0,1) -> 0 | AR16: =IF(OR(F16="",F16="TBD",F16="N/A",F16="SDK",F16="SAAS"),0,1) -> 0 | AS16: =IF(OR(G16="",G16="TBD",G16="N/A",G16="SDK",G16="SAAS"),0,1) -> 1 | AT16: =IF(OR(H16="",H16="TBD",H16="N/A",H16="SDK",H16="SAAS"),0,1) -> 1 | AV16: =SUM(AW16:AZ16) -> 4 | AW16: =IF(OR(E16="",E16="N/A",E16="SDK",E16="SAAS"),0,1) -> 1 | AX16: =IF(OR(F16="",F16="N/A",F16="SDK",F16="SAAS"),0,1) -> 1 | AY16: =IF(OR(G16="",G16="N/A",G16="SDK",G16="SAAS"),0,1) -> 1 | AZ16: =IF(OR(H16="",H16="N/A",H16="SDK",H16="SAAS"),0,1) -> 1
A17: IC-010 | B17: Onboarding | C17: Validar la coincidencia facial contra el INE | E17: /experience/CrossChannel/SessionDialogue/v1/customerContactSelfieProcedure/initiate | K17: =J17*$J$147 -> 0 | L17: Backlog | M17: Rafael Elizalde | N17: x | V17: Sí | W17: Por definir | AB17: =IF(AG17=0,0,IF(AF17=AG17,1,0))*AD17 -> 1 | AC17: =IF(AK17=AL17,1,0)*AD17 -> 1 | AD17: =IF(ISNUMBER(MATCH(A17,$A$2:A15,0)),0,1) -> 1 | AF17: =SUMIFS(AH$3:AH$251,$A$3:$A$251,$A17) -> 1 | AG17: =SUMIFS(AI$3:AI$77,$A$3:$A$77,$A17) -> 1 | AH17: =IF(SUM(AW17:AZ17)=0,0,IF(SUM(AQ17:AT17)=SUM(AW17:AZ17),1,0)) -> 1 | AI17: 1 | AK17: =SUMIFS(AM$3:AM$251,$A$3:$A$251,$A17) -> 1 | AL17: =SUMIFS(AN$3:AN$251,$A$3:$A$251,$A17) -> 1 | AM17: =IF(SUM(AQ17:AT17)=SUM(AW17:AZ17),1,0) -> 1 | AN17: 1 | AP17: =SUM(AQ17:AT17) -> 1 | AQ17: =IF(OR(E17="",E17="TBD",E17="N/A",E17="SDK",E17="SAAS"),0,1) -> 1 | AR17: =IF(OR(F17="",F17="TBD",F17="N/A",F17="SDK",F17="SAAS"),0,1) -> 0 | AS17: =IF(OR(G17="",G17="TBD",G17="N/A",G17="SDK",G17="SAAS"),0,1) -> 0 | AT17: =IF(OR(H17="",H17="TBD",H17="N/A",H17="SDK",H17="SAAS"),0,1) -> 0 | AV17: =SUM(AW17:AZ17) -> 1 | AW17: =IF(OR(E17="",E17="N/A",E17="SDK",E17="SAAS"),0,1) -> 1 | AX17: =IF(OR(F17="",F17="N/A",F17="SDK",F17="SAAS"),0,1) -> 0 | AY17: =IF(OR(G17="",G17="N/A",G17="SDK",G17="SAAS"),0,1) -> 0 | AZ17: =IF(OR(H17="",H17="N/A",H17="SDK",H17="SAAS"),0,1) -> 0
A18: IC-011 | B18: Onboarding | C18: Calcular el RFC del cliente / prospecto | E18: N/A | F18: N/A | G18: /sales/partyLifecycleManagement/v1/rfc/evaluate | H18: /system/sales/partyLifecycleManagement/v1/rfc/evaluate | J18: 1 | K18: =J18*$J$147 -> 3.5 | L18: Backlog | M18: Rafael Elizalde | N18: x | V18: Sí | W18: Por definir | AB18: =IF(AG18=0,0,IF(AF18=AG18,1,0))*AD18 -> 1 | AC18: =IF(AK18=AL18,1,0)*AD18 -> 1 | AD18: =IF(ISNUMBER(MATCH(A18,$A$2:A17,0)),0,1) -> 1 | AF18: =SUMIFS(AH$3:AH$251,$A$3:$A$251,$A18) -> 1 | AG18: =SUMIFS(AI$3:AI$77,$A$3:$A$77,$A18) -> 1 | AH18: =IF(SUM(AW18:AZ18)=0,0,IF(SUM(AQ18:AT18)=SUM(AW18:AZ18),1,0)) -> 1 | AI18: 1 | AK18: =SUMIFS(AM$3:AM$251,$A$3:$A$251,$A18) -> 1 | AL18: =SUMIFS(AN$3:AN$251,$A$3:$A$251,$A18) -> 1 | AM18: =IF(SUM(AQ18:AT18)=SUM(AW18:AZ18),1,0) -> 1 | AN18: 1 | AP18: =SUM(AQ18:AT18) -> 2 | AQ18: =IF(OR(E18="",E18="TBD",E18="N/A",E18="SDK",E18="SAAS"),0,1) -> 0 | AR18: =IF(OR(F18="",F18="TBD",F18="N/A",F18="SDK",F18="SAAS"),0,1) -> 0 | AS18: =IF(OR(G18="",G18="TBD",G18="N/A",G18="SDK",G18="SAAS"),0,1) -> 1 | AT18: =IF(OR(H18="",H18="TBD",H18="N/A",H18="SDK",H18="SAAS"),0,1) -> 1 | AV18: =SUM(AW18:AZ18) -> 2 | AW18: =IF(OR(E18="",E18="N/A",E18="SDK",E18="SAAS"),0,1) -> 0 | AX18: =IF(OR(F18="",F18="N/A",F18="SDK",F18="SAAS"),0,1) -> 0 | AY18: =IF(OR(G18="",G18="N/A",G18="SDK",G18="SAAS"),0,1) -> 1 | AZ18: =IF(OR(H18="",H18="N/A",H18="SDK",H18="SAAS"),0,1) -> 1
A19: IC-012 | B19: Onboarding | C19: Validar el CURP ante RENAPO | E19: N/A | F19: N/A | G19: /sales/partyLifecycleManagement/v1/renapo/{curp}/retrieve | H19: /system/sales/partyLifecycleManagement/v1/renapo/{curp}/retrieve | J19: 1 | K19: =J19*$J$147 -> 3.5 | L19: Backlog | M19: Rafael Elizalde | N19: x | V19: Sí | W19: Por definir | AB19: =IF(AG19=0,0,IF(AF19=AG19,1,0))*AD19 -> 1 | AC19: =IF(AK19=AL19,1,0)*AD19 -> 1 | AD19: =IF(ISNUMBER(MATCH(A19,$A$2:A18,0)),0,1) -> 1 | AF19: =SUMIFS(AH$3:AH$251,$A$3:$A$251,$A19) -> 1 | AG19: =SUMIFS(AI$3:AI$77,$A$3:$A$77,$A19) -> 1 | AH19: =IF(SUM(AW19:AZ19)=0,0,IF(SUM(AQ19:AT19)=SUM(AW19:AZ19),1,0)) -> 1 | AI19: 1 | AK19: =SUMIFS(AM$3:AM$251,$A$3:$A$251,$A19) -> 1 | AL19: =SUMIFS(AN$3:AN$251,$A$3:$A$251,$A19) -> 1 | AM19: =IF(SUM(AQ19:AT19)=SUM(AW19:AZ19),1,0) -> 1 | AN19: 1 | AP19: =SUM(AQ19:AT19) -> 2 | AQ19: =IF(OR(E19="",E19="TBD",E19="N/A",E19="SDK",E19="SAAS"),0,1) -> 0 | AR19: =IF(OR(F19="",F19="TBD",F19="N/A",F19="SDK",F19="SAAS"),0,1) -> 0 | AS19: =IF(OR(G19="",G19="TBD",G19="N/A",G19="SDK",G19="SAAS"),0,1) -> 1 | AT19: =IF(OR(H19="",H19="TBD",H19="N/A",H19="SDK",H19="SAAS"),0,1) -> 1 | AV19: =SUM(AW19:AZ19) -> 2 | AW19: =IF(OR(E19="",E19="N/A",E19="SDK",E19="SAAS"),0,1) -> 0 | AX19: =IF(OR(F19="",F19="N/A",F19="SDK",F19="SAAS"),0,1) -> 0 | AY19: =IF(OR(G19="",G19="N/A",G19="SDK",G19="SAAS"),0,1) -> 1 | AZ19: =IF(OR(H19="",H19="N/A",H19="SDK",H19="SAAS"),0,1) -> 1
A20: IC-013 | B20: Onboarding | C20: Extraer la información dentro del comprobante de domicilio (OCR) | E20: /experience/customers/v1/ocrDocument/retrieve | F20: /customers/v1/ocrDocument/retrieve | G20: /sales/partyLifecycleManagement/v1/documentation/execute | H20: /system/sales/partyLifecycleManagement/v1/documentation/execute | K20: =J20*$J$147 -> 0 | L20: Backlog | M20: Rafael Elizalde | N20: x | V20: Sí | W20: Por definir | AB20: =IF(AG20=0,0,IF(AF20=AG20,1,0))*AD20 -> 1 | AC20: =IF(AK20=AL20,1,0)*AD20 -> 1 | AD20: =IF(ISNUMBER(MATCH(A20,$A$2:A19,0)),0,1) -> 1 | AF20: =SUMIFS(AH$3:AH$251,$A$3:$A$251,$A20) -> 1 | AG20: =SUMIFS(AI$3:AI$77,$A$3:$A$77,$A20) -> 1 | AH20: =IF(SUM(AW20:AZ20)=0,0,IF(SUM(AQ20:AT20)=SUM(AW20:AZ20),1,0)) -> 1 | AI20: 1 | AK20: =SUMIFS(AM$3:AM$251,$A$3:$A$251,$A20) -> 1 | AL20: =SUMIFS(AN$3:AN$251,$A$3:$A$251,$A20) -> 1 | AM20: =IF(SUM(AQ20:AT20)=SUM(AW20:AZ20),1,0) -> 1 | AN20: 1 | AP20: =SUM(AQ20:AT20) -> 4 | AQ20: =IF(OR(E20="",E20="TBD",E20="N/A",E20="SDK",E20="SAAS"),0,1) -> 1 | AR20: =IF(OR(F20="",F20="TBD",F20="N/A",F20="SDK",F20="SAAS"),0,1) -> 1 | AS20: =IF(OR(G20="",G20="TBD",G20="N/A",G20="SDK",G20="SAAS"),0,1) -> 1 | AT20: =IF(OR(H20="",H20="TBD",H20="N/A",H20="SDK",H20="SAAS"),0,1) -> 1 | AV20: =SUM(AW20:AZ20) -> 4 | AW20: =IF(OR(E20="",E20="N/A",E20="SDK",E20="SAAS"),0,1) -> 1 | AX20: =IF(OR(F20="",F20="N/A",F20="SDK",F20="SAAS"),0,1) -> 1 | AY20: =IF(OR(G20="",G20="N/A",G20="SDK",G20="SAAS"),0,1) -> 1 | AZ20: =IF(OR(H20="",H20="N/A",H20="SDK",H20="SAAS"),0,1) -> 1
A21: IC-016 | B21: Onboarding | C21: Validar la coincidencia facial contra la identificación (1:1) | D21: SDK | E21: SDK | F21: SDK | G21: SDK | H21: SDK | K21: =J21*$J$147 -> 0 | L21: Backlog | M21: Rafael Elizalde | N21: x | V21: Sí | W21: Por definir | AB21: =IF(AG21=0,0,IF(AF21=AG21,1,0))*AD21 -> 0 | AC21: =IF(AK21=AL21,1,0)*AD21 -> 1 | AD21: =IF(ISNUMBER(MATCH(A21,$A$2:A20,0)),0,1) -> 1 | AF21: =SUMIFS(AH$3:AH$251,$A$3:$A$251,$A21) -> 0 | AG21: =SUMIFS(AI$3:AI$77,$A$3:$A$77,$A21) -> 1 | AH21: =IF(SUM(AW21:AZ21)=0,0,IF(SUM(AQ21:AT21)=SUM(AW21:AZ21),1,0)) -> 0 | AI21: 1 | AK21: =SUMIFS(AM$3:AM$251,$A$3:$A$251,$A21) -> 1 | AL21: =SUMIFS(AN$3:AN$251,$A$3:$A$251,$A21) -> 1 | AM21: =IF(SUM(AQ21:AT21)=SUM(AW21:AZ21),1,0) -> 1 | AN21: 1 | AP21: =SUM(AQ21:AT21) -> 0 | AQ21: =IF(OR(E21="",E21="TBD",E21="N/A",E21="SDK",E21="SAAS"),0,1) -> 0 | AR21: =IF(OR(F21="",F21="TBD",F21="N/A",F21="SDK",F21="SAAS"),0,1) -> 0 | AS21: =IF(OR(G21="",G21="TBD",G21="N/A",G21="SDK",G21="SAAS"),0,1) -> 0 | AT21: =IF(OR(H21="",H21="TBD",H21="N/A",H21="SDK",H21="SAAS"),0,1) -> 0 | AV21: =SUM(AW21:AZ21) -> 0 | AW21: =IF(OR(E21="",E21="N/A",E21="SDK",E21="SAAS"),0,1) -> 0 | AX21: =IF(OR(F21="",F21="N/A",F21="SDK",F21="SAAS"),0,1) -> 0 | AY21: =IF(OR(G21="",G21="N/A",G21="SDK",G21="SAAS"),0,1) -> 0 | AZ21: =IF(OR(H21="",H21="N/A",H21="SDK",H21="SAAS"),0,1) -> 0
A22: IC-017 | B22: Onboarding | C22: Reconocimiento facial 1:N para evitar duplicidades | D22: SDK | E22: SDK | F22: SDK | G22: SDK | H22: SDK | K22: =J22*$J$147 -> 0 | L22: Backlog | M22: Rafael Elizalde | N22: x | V22: Sí | W22: Por definir | AB22: =IF(AG22=0,0,IF(AF22=AG22,1,0))*AD22 -> 0 | AC22: =IF(AK22=AL22,1,0)*AD22 -> 1 | AD22: =IF(ISNUMBER(MATCH(A22,$A$2:A21,0)),0,1) -> 1 | AF22: =SUMIFS(AH$3:AH$251,$A$3:$A$251,$A22) -> 0 | AG22: =SUMIFS(AI$3:AI$77,$A$3:$A$77,$A22) -> 1 | AH22: =IF(SUM(AW22:AZ22)=0,0,IF(SUM(AQ22:AT22)=SUM(AW22:AZ22),1,0)) -> 0 | AI22: 1 | AK22: =SUMIFS(AM$3:AM$251,$A$3:$A$251,$A22) -> 1 | AL22: =SUMIFS(AN$3:AN$251,$A$3:$A$251,$A22) -> 1 | AM22: =IF(SUM(AQ22:AT22)=SUM(AW22:AZ22),1,0) -> 1 | AN22: 1 | AP22: =SUM(AQ22:AT22) -> 0 | AQ22: =IF(OR(E22="",E22="TBD",E22="N/A",E22="SDK",E22="SAAS"),0,1) -> 0 | AR22: =IF(OR(F22="",F22="TBD",F22="N/A",F22="SDK",F22="SAAS"),0,1) -> 0 | AS22: =IF(OR(G22="",G22="TBD",G22="N/A",G22="SDK",G22="SAAS"),0,1) -> 0 | AT22: =IF(OR(H22="",H22="TBD",H22="N/A",H22="SDK",H22="SAAS"),0,1) -> 0 | AV22: =SUM(AW22:AZ22) -> 0 | AW22: =IF(OR(E22="",E22="N/A",E22="SDK",E22="SAAS"),0,1) -> 0 | AX22: =IF(OR(F22="",F22="N/A",F22="SDK",F22="SAAS"),0,1) -> 0 | AY22: =IF(OR(G22="",G22="N/A",G22="SDK",G22="SAAS"),0,1) -> 0 | AZ22: =IF(OR(H22="",H22="N/A",H22="SDK",H22="SAAS"),0,1) -> 0
A23: IC-018 | B23: Onboarding | C23: Validación de Personas Políticamentes Expuestas (PPEs), Listas negras internacionales y locales, así como otras listas de bloqueo | E23: /experience/Customers/v1/onboardingPartySuitability/evaluate | F23: /customers/v1/onboardingPartySuitability/evaluate | G23: /sales/partyLifecycleManagement/v1/qualification/retrieve | H23: /system/sales/partyLifecycleManagement/v1/qualification/retrieve | J23: 6 | K23: =J23*$J$147 -> 21 | L23: Backlog | M23: Rafael Elizalde | N23: x | V23: Sí | W23: Por definir | AB23: =IF(AG23=0,0,IF(AF23=AG23,1,0))*AD23 -> 1 | AC23: =IF(AK23=AL23,1,0)*AD23 -> 1 | AD23: =IF(ISNUMBER(MATCH(A23,$A$2:A22,0)),0,1) -> 1 | AF23: =SUMIFS(AH$3:AH$251,$A$3:$A$251,$A23) -> 1 | AG23: =SUMIFS(AI$3:AI$77,$A$3:$A$77,$A23) -> 1 | AH23: =IF(SUM(AW23:AZ23)=0,0,IF(SUM(AQ23:AT23)=SUM(AW23:AZ23),1,0)) -> 1 | AI23: 1 | AK23: =SUMIFS(AM$3:AM$251,$A$3:$A$251,$A23) -> 1 | AL23: =SUMIFS(AN$3:AN$251,$A$3:$A$251,$A23) -> 1 | AM23: =IF(SUM(AQ23:AT23)=SUM(AW23:AZ23),1,0) -> 1 | AN23: 1 | AP23: =SUM(AQ23:AT23) -> 4 | AQ23: =IF(OR(E23="",E23="TBD",E23="N/A",E23="SDK",E23="SAAS"),0,1) -> 1 | AR23: =IF(OR(F23="",F23="TBD",F23="N/A",F23="SDK",F23="SAAS"),0,1) -> 1 | AS23: =IF(OR(G23="",G23="TBD",G23="N/A",G23="SDK",G23="SAAS"),0,1) -> 1 | AT23: =IF(OR(H23="",H23="TBD",H23="N/A",H23="SDK",H23="SAAS"),0,1) -> 1 | AV23: =SUM(AW23:AZ23) -> 4 | AW23: =IF(OR(E23="",E23="N/A",E23="SDK",E23="SAAS"),0,1) -> 1 | AX23: =IF(OR(F23="",F23="N/A",F23="SDK",F23="SAAS"),0,1) -> 1 | AY23: =IF(OR(G23="",G23="N/A",G23="SDK",G23="SAAS"),0,1) -> 1 | AZ23: =IF(OR(H23="",H23="N/A",H23="SDK",H23="SAAS"),0,1) -> 1
A24: IC-019 | B24: Onboarding | C24: Obtener la Dirección IP del dispositivo en donde se está ejecutando el proceso | E24: /experience/channels/v1/onBoardingParty/initiate | F24: /salesAndService/v1/onBoardingParty/initiate | G24: /crossChannel/sessionDialogue/v1/customerContactSessionProcedure/initiate | K24: =J24*$J$147 -> 0 | L24: Backlog | M24: Rafael Elizalde | N24: x | V24: Sí | W24: Por definir | AB24: =IF(AG24=0,0,IF(AF24=AG24,1,0))*AD24 -> 1 | AC24: =IF(AK24=AL24,1,0)*AD24 -> 1 | AD24: =IF(ISNUMBER(MATCH(A24,$A$2:A23,0)),0,1) -> 1 | AF24: =SUMIFS(AH$3:AH$251,$A$3:$A$251,$A24) -> 1 | AG24: =SUMIFS(AI$3:AI$77,$A$3:$A$77,$A24) -> 1 | AH24: =IF(SUM(AW24:AZ24)=0,0,IF(SUM(AQ24:AT24)=SUM(AW24:AZ24),1,0)) -> 1 | AI24: 1 | AK24: =SUMIFS(AM$3:AM$251,$A$3:$A$251,$A24) -> 1 | AL24: =SUMIFS(AN$3:AN$251,$A$3:$A$251,$A24) -> 1 | AM24: =IF(SUM(AQ24:AT24)=SUM(AW24:AZ24),1,0) -> 1 | AN24: 1 | AP24: =SUM(AQ24:AT24) -> 3 | AQ24: =IF(OR(E24="",E24="TBD",E24="N/A",E24="SDK",E24="SAAS"),0,1) -> 1 | AR24: =IF(OR(F24="",F24="TBD",F24="N/A",F24="SDK",F24="SAAS"),0,1) -> 1 | AS24: =IF(OR(G24="",G24="TBD",G24="N/A",G24="SDK",G24="SAAS"),0,1) -> 1 | AT24: =IF(OR(H24="",H24="TBD",H24="N/A",H24="SDK",H24="SAAS"),0,1) -> 0 | AV24: =SUM(AW24:AZ24) -> 3 | AW24: =IF(OR(E24="",E24="N/A",E24="SDK",E24="SAAS"),0,1) -> 1 | AX24: =IF(OR(F24="",F24="N/A",F24="SDK",F24="SAAS"),0,1) -> 1 | AY24: =IF(OR(G24="",G24="N/A",G24="SDK",G24="SAAS"),0,1) -> 1 | AZ24: =IF(OR(H24="",H24="N/A",H24="SDK",H24="SAAS"),0,1) -> 0
A25: IC-020 | B25: Onboarding | C25: Obtener la Geolocalización (longitud y altitud) | E25: /experience/channels/v1/onBoardingParty/initiate | F25: /salesAndService/v1/onBoardingParty/initiate | G25: /crossChannel/sessionDialogue/v1/customerContactSessionProcedure/initiate | K25: =J25*$J$147 -> 0 | L25: Backlog | M25: Rafael Elizalde | N25: x | V25: Sí | W25: Por definir | AB25: =IF(AG25=0,0,IF(AF25=AG25,1,0))*AD25 -> 1 | AC25: =IF(AK25=AL25,1,0)*AD25 -> 1 | AD25: =IF(ISNUMBER(MATCH(A25,$A$2:A24,0)),0,1) -> 1 | AF25: =SUMIFS(AH$3:AH$251,$A$3:$A$251,$A25) -> 1 | AG25: =SUMIFS(AI$3:AI$77,$A$3:$A$77,$A25) -> 1 | AH25: =IF(SUM(AW25:AZ25)=0,0,IF(SUM(AQ25:AT25)=SUM(AW25:AZ25),1,0)) -> 1 | AI25: 1 | AK25: =SUMIFS(AM$3:AM$251,$A$3:$A$251,$A25) -> 1 | AL25: =SUMIFS(AN$3:AN$251,$A$3:$A$251,$A25) -> 1 | AM25: =IF(SUM(AQ25:AT25)=SUM(AW25:AZ25),1,0) -> 1 | AN25: 1 | AP25: =SUM(AQ25:AT25) -> 3 | AQ25: =IF(OR(E25="",E25="TBD",E25="N/A",E25="SDK",E25="SAAS"),0,1) -> 1 | AR25: =IF(OR(F25="",F25="TBD",F25="N/A",F25="SDK",F25="SAAS"),0,1) -> 1 | AS25: =IF(OR(G25="",G25="TBD",G25="N/A",G25="SDK",G25="SAAS"),0,1) -> 1 | AT25: =IF(OR(H25="",H25="TBD",H25="N/A",H25="SDK",H25="SAAS"),0,1) -> 0 | AV25: =SUM(AW25:AZ25) -> 3 | AW25: =IF(OR(E25="",E25="N/A",E25="SDK",E25="SAAS"),0,1) -> 1 | AX25: =IF(OR(F25="",F25="N/A",F25="SDK",F25="SAAS"),0,1) -> 1 | AY25: =IF(OR(G25="",G25="N/A",G25="SDK",G25="SAAS"),0,1) -> 1 | AZ25: =IF(OR(H25="",H25="N/A",H25="SDK",H25="SAAS"),0,1) -> 0
A26: IC-021 | B26: Onboarding | C26: Generar el Hash ID del dispositivo | E26: /experience/channels/v1/onBoardingParty/initiate | F26: /salesAndService/v1/onBoardingParty/initiate | G26: /crossChannel/sessionDialogue/v1/customerContactSessionProcedure/initiate | K26: =J26*$J$147 -> 0 | L26: Backlog | M26: Rafael Elizalde | N26: x | V26: Sí | W26: Por definir | AB26: =IF(AG26=0,0,IF(AF26=AG26,1,0))*AD26 -> 1 | AC26: =IF(AK26=AL26,1,0)*AD26 -> 1 | AD26: =IF(ISNUMBER(MATCH(A26,$A$2:A25,0)),0,1) -> 1 | AF26: =SUMIFS(AH$3:AH$251,$A$3:$A$251,$A26) -> 1 | AG26: =SUMIFS(AI$3:AI$77,$A$3:$A$77,$A26) -> 1 | AH26: =IF(SUM(AW26:AZ26)=0,0,IF(SUM(AQ26:AT26)=SUM(AW26:AZ26),1,0)) -> 1 | AI26: 1 | AK26: =SUMIFS(AM$3:AM$251,$A$3:$A$251,$A26) -> 1 | AL26: =SUMIFS(AN$3:AN$251,$A$3:$A$251,$A26) -> 1 | AM26: =IF(SUM(AQ26:AT26)=SUM(AW26:AZ26),1,0) -> 1 | AN26: 1 | AP26: =SUM(AQ26:AT26) -> 3 | AQ26: =IF(OR(E26="",E26="TBD",E26="N/A",E26="SDK",E26="SAAS"),0,1) -> 1 | AR26: =IF(OR(F26="",F26="TBD",F26="N/A",F26="SDK",F26="SAAS"),0,1) -> 1 | AS26: =IF(OR(G26="",G26="TBD",G26="N/A",G26="SDK",G26="SAAS"),0,1) -> 1 | AT26: =IF(OR(H26="",H26="TBD",H26="N/A",H26="SDK",H26="SAAS"),0,1) -> 0 | AV26: =SUM(AW26:AZ26) -> 3 | AW26: =IF(OR(E26="",E26="N/A",E26="SDK",E26="SAAS"),0,1) -> 1 | AX26: =IF(OR(F26="",F26="N/A",F26="SDK",F26="SAAS"),0,1) -> 1 | AY26: =IF(OR(G26="",G26="N/A",G26="SDK",G26="SAAS"),0,1) -> 1 | AZ26: =IF(OR(H26="",H26="N/A",H26="SDK",H26="SAAS"),0,1) -> 0
A27: IC-022 | B27: Onboarding | C27: Validar comprobante de ingresos (estados de cuenta bancarios) | E27: TBD | F27: TBD | G27: TBD | H27: TBD | K27: =J27*$J$147 -> 0 | L27: Backlog | M27: Rafael Elizalde | N27: x | V27: Post MVP | W27: Por definir | AB27: =IF(AG27=0,0,IF(AF27=AG27,1,0))*AD27 -> 0 | AC27: =IF(AK27=AL27,1,0)*AD27 -> 0 | AD27: =IF(ISNUMBER(MATCH(A27,$A$2:A26,0)),0,1) -> 1 | AF27: =SUMIFS(AH$3:AH$251,$A$3:$A$251,$A27) -> 0 | AG27: =SUMIFS(AI$3:AI$77,$A$3:$A$77,$A27) -> 1 | AH27: =IF(SUM(AW27:AZ27)=0,0,IF(SUM(AQ27:AT27)=SUM(AW27:AZ27),1,0)) -> 0 | AI27: 1 | AK27: =SUMIFS(AM$3:AM$251,$A$3:$A$251,$A27) -> 0 | AL27: =SUMIFS(AN$3:AN$251,$A$3:$A$251,$A27) -> 1 | AM27: =IF(SUM(AQ27:AT27)=SUM(AW27:AZ27),1,0) -> 0 | AN27: 1 | AP27: =SUM(AQ27:AT27) -> 0 | AQ27: =IF(OR(E27="",E27="TBD",E27="N/A",E27="SDK",E27="SAAS"),0,1) -> 0 | AR27: =IF(OR(F27="",F27="TBD",F27="N/A",F27="SDK",F27="SAAS"),0,1) -> 0 | AS27: =IF(OR(G27="",G27="TBD",G27="N/A",G27="SDK",G27="SAAS"),0,1) -> 0 | AT27: =IF(OR(H27="",H27="TBD",H27="N/A",H27="SDK",H27="SAAS"),0,1) -> 0 | AV27: =SUM(AW27:AZ27) -> 4 | AW27: =IF(OR(E27="",E27="N/A",E27="SDK",E27="SAAS"),0,1) -> 1 | AX27: =IF(OR(F27="",F27="N/A",F27="SDK",F27="SAAS"),0,1) -> 1 | AY27: =IF(OR(G27="",G27="N/A",G27="SDK",G27="SAAS"),0,1) -> 1 | AZ27: =IF(OR(H27="",H27="N/A",H27="SDK",H27="SAAS"),0,1) -> 1
A28: IC-024 | B28: Onboarding | C28: Generar la videograbación como parte de la prueba de vida (Video Selfie) | E28: /experience/crossChannel/sessionDialogue/v1/customerContactVideoSelfieProcedure/initiate | J28: 1 | K28: =J28*$J$147 -> 3.5 | L28: Backlog | M28: Rafael Elizalde | N28: x | V28: Sí | W28: Por definir | AB28: =IF(AG28=0,0,IF(AF28=AG28,1,0))*AD28 -> 1 | AC28: =IF(AK28=AL28,1,0)*AD28 -> 1 | AD28: =IF(ISNUMBER(MATCH(A28,$A$2:A27,0)),0,1) -> 1 | AF28: =SUMIFS(AH$3:AH$251,$A$3:$A$251,$A28) -> 2 | AG28: =SUMIFS(AI$3:AI$77,$A$3:$A$77,$A28) -> 2 | AH28: =IF(SUM(AW28:AZ28)=0,0,IF(SUM(AQ28:AT28)=SUM(AW28:AZ28),1,0)) -> 1 | AI28: 1 | AK28: =SUMIFS(AM$3:AM$251,$A$3:$A$251,$A28) -> 2 | AL28: =SUMIFS(AN$3:AN$251,$A$3:$A$251,$A28) -> 2 | AM28: =IF(SUM(AQ28:AT28)=SUM(AW28:AZ28),1,0) -> 1 | AN28: 1 | AP28: =SUM(AQ28:AT28) -> 1 | AQ28: =IF(OR(E28="",E28="TBD",E28="N/A",E28="SDK",E28="SAAS"),0,1) -> 1 | AR28: =IF(OR(F28="",F28="TBD",F28="N/A",F28="SDK",F28="SAAS"),0,1) -> 0 | AS28: =IF(OR(G28="",G28="TBD",G28="N/A",G28="SDK",G28="SAAS"),0,1) -> 0 | AT28: =IF(OR(H28="",H28="TBD",H28="N/A",H28="SDK",H28="SAAS"),0,1) -> 0 | AV28: =SUM(AW28:AZ28) -> 1 | AW28: =IF(OR(E28="",E28="N/A",E28="SDK",E28="SAAS"),0,1) -> 1 | AX28: =IF(OR(F28="",F28="N/A",F28="SDK",F28="SAAS"),0,1) -> 0 | AY28: =IF(OR(G28="",G28="N/A",G28="SDK",G28="SAAS"),0,1) -> 0 | AZ28: =IF(OR(H28="",H28="N/A",H28="SDK",H28="SAAS"),0,1) -> 0
A29: IC-024 | B29: Onboarding | C29: Generar la videograbación como parte de la prueba de vida (Video Selfie) | E29: /experience/crossChannel/sessionDialogue/v1/customerContactVideoSelfieProcedure/retrieve | J29: 1 | K29: =J29*$J$147 -> 3.5 | L29: Backlog | M29: Rafael Elizalde | N29: x | V29: Sí | W29: Por definir | AB29: =IF(AG29=0,0,IF(AF29=AG29,1,0))*AD29 -> 0 | AC29: =IF(AK29=AL29,1,0)*AD29 -> 0 | AD29: =IF(ISNUMBER(MATCH(A29,$A$2:A28,0)),0,1) -> 0 | AF29: =SUMIFS(AH$3:AH$251,$A$3:$A$251,$A29) -> 2 | AG29: =SUMIFS(AI$3:AI$77,$A$3:$A$77,$A29) -> 2 | AH29: =IF(SUM(AW29:AZ29)=0,0,IF(SUM(AQ29:AT29)=SUM(AW29:AZ29),1,0)) -> 1 | AI29: 1 | AK29: =SUMIFS(AM$3:AM$251,$A$3:$A$251,$A29) -> 2 | AL29: =SUMIFS(AN$3:AN$251,$A$3:$A$251,$A29) -> 2 | AM29: =IF(SUM(AQ29:AT29)=SUM(AW29:AZ29),1,0) -> 1 | AN29: 1 | AP29: =SUM(AQ29:AT29) -> 1 | AQ29: =IF(OR(E29="",E29="TBD",E29="N/A",E29="SDK",E29="SAAS"),0,1) -> 1 | AR29: =IF(OR(F29="",F29="TBD",F29="N/A",F29="SDK",F29="SAAS"),0,1) -> 0 | AS29: =IF(OR(G29="",G29="TBD",G29="N/A",G29="SDK",G29="SAAS"),0,1) -> 0 | AT29: =IF(OR(H29="",H29="TBD",H29="N/A",H29="SDK",H29="SAAS"),0,1) -> 0 | AV29: =SUM(AW29:AZ29) -> 1 | AW29: =IF(OR(E29="",E29="N/A",E29="SDK",E29="SAAS"),0,1) -> 1 | AX29: =IF(OR(F29="",F29="N/A",F29="SDK",F29="SAAS"),0,1) -> 0 | AY29: =IF(OR(G29="",G29="N/A",G29="SDK",G29="SAAS"),0,1) -> 0 | AZ29: =IF(OR(H29="",H29="N/A",H29="SDK",H29="SAAS"),0,1) -> 0
A30: IC-025 | B30: Onboarding | C30: Firmar del contrato (Non Repudiation) | E30: TBD | F30: TBD | G30: TBD | H30: TBD | K30: =J30*$J$147 -> 0 | L30: Backlog | M30: Rafael Elizalde | N30: x | V30: Sí | W30: Por definir | AB30: =IF(AG30=0,0,IF(AF30=AG30,1,0))*AD30 -> 0 | AC30: =IF(AK30=AL30,1,0)*AD30 -> 0 | AD30: =IF(ISNUMBER(MATCH(A30,$A$2:A28,0)),0,1) -> 1 | AF30: =SUMIFS(AH$3:AH$251,$A$3:$A$251,$A30) -> 0 | AG30: =SUMIFS(AI$3:AI$77,$A$3:$A$77,$A30) -> 1 | AH30: =IF(SUM(AW30:AZ30)=0,0,IF(SUM(AQ30:AT30)=SUM(AW30:AZ30),1,0)) -> 0 | AI30: 1 | AK30: =SUMIFS(AM$3:AM$251,$A$3:$A$251,$A30) -> 0 | AL30: =SUMIFS(AN$3:AN$251,$A$3:$A$251,$A30) -> 1 | AM30: =IF(SUM(AQ30:AT30)=SUM(AW30:AZ30),1,0) -> 0 | AN30: 1 | AP30: =SUM(AQ30:AT30) -> 0 | AQ30: =IF(OR(E30="",E30="TBD",E30="N/A",E30="SDK",E30="SAAS"),0,1) -> 0 | AR30: =IF(OR(F30="",F30="TBD",F30="N/A",F30="SDK",F30="SAAS"),0,1) -> 0 | AS30: =IF(OR(G30="",G30="TBD",G30="N/A",G30="SDK",G30="SAAS"),0,1) -> 0 | AT30: =IF(OR(H30="",H30="TBD",H30="N/A",H30="SDK",H30="SAAS"),0,1) -> 0 | AV30: =SUM(AW30:AZ30) -> 4 | AW30: =IF(OR(E30="",E30="N/A",E30="SDK",E30="SAAS"),0,1) -> 1 | AX30: =IF(OR(F30="",F30="N/A",F30="SDK",F30="SAAS"),0,1) -> 1 | AY30: =IF(OR(G30="",G30="N/A",G30="SDK",G30="SAAS"),0,1) -> 1 | AZ30: =IF(OR(H30="",H30="N/A",H30="SDK",H30="SAAS"),0,1) -> 1
A31: IC-027 | B31: Onboarding | C31: Firmar con NOM 151 | E31: TBD | F31: TBD | G31: TBD | H31: TBD | K31: =J31*$J$147 -> 0 | L31: Backlog | M31: Rafael Elizalde | N31: x | V31: Sí | W31: Por definir | AB31: =IF(AG31=0,0,IF(AF31=AG31,1,0))*AD31 -> 0 | AC31: =IF(AK31=AL31,1,0)*AD31 -> 0 | AD31: =IF(ISNUMBER(MATCH(A31,$A$2:A30,0)),0,1) -> 1 | AF31: =SUMIFS(AH$3:AH$251,$A$3:$A$251,$A31) -> 0 | AG31: =SUMIFS(AI$3:AI$77,$A$3:$A$77,$A31) -> 1 | AH31: =IF(SUM(AW31:AZ31)=0,0,IF(SUM(AQ31:AT31)=SUM(AW31:AZ31),1,0)) -> 0 | AI31: 1 | AK31: =SUMIFS(AM$3:AM$251,$A$3:$A$251,$A31) -> 0 | AL31: =SUMIFS(AN$3:AN$251,$A$3:$A$251,$A31) -> 1 | AM31: =IF(SUM(AQ31:AT31)=SUM(AW31:AZ31),1,0) -> 0 | AN31: 1 | AP31: =SUM(AQ31:AT31) -> 0 | AQ31: =IF(OR(E31="",E31="TBD",E31="N/A",E31="SDK",E31="SAAS"),0,1) -> 0 | AR31: =IF(OR(F31="",F31="TBD",F31="N/A",F31="SDK",F31="SAAS"),0,1) -> 0 | AS31: =IF(OR(G31="",G31="TBD",G31="N/A",G31="SDK",G31="SAAS"),0,1) -> 0 | AT31: =IF(OR(H31="",H31="TBD",H31="N/A",H31="SDK",H31="SAAS"),0,1) -> 0 | AV31: =SUM(AW31:AZ31) -> 4 | AW31: =IF(OR(E31="",E31="N/A",E31="SDK",E31="SAAS"),0,1) -> 1 | AX31: =IF(OR(F31="",F31="N/A",F31="SDK",F31="SAAS"),0,1) -> 1 | AY31: =IF(OR(G31="",G31="N/A",G31="SDK",G31="SAAS"),0,1) -> 1 | AZ31: =IF(OR(H31="",H31="N/A",H31="SDK",H31="SAAS"),0,1) -> 1
A32: IC-028 | B32: Onboarding | C32: Firmar los eventos con un certificado | E32: TBD | F32: TBD | G32: TBD | H32: TBD | K32: =J32*$J$147 -> 0 | L32: Backlog | M32: Rafael Elizalde | N32: x | V32: Sí | W32: Por definir | AB32: =IF(AG32=0,0,IF(AF32=AG32,1,0))*AD32 -> 0 | AC32: =IF(AK32=AL32,1,0)*AD32 -> 0 | AD32: =IF(ISNUMBER(MATCH(A32,$A$2:A31,0)),0,1) -> 1 | AF32: =SUMIFS(AH$3:AH$251,$A$3:$A$251,$A32) -> 0 | AG32: =SUMIFS(AI$3:AI$77,$A$3:$A$77,$A32) -> 1 | AH32: =IF(SUM(AW32:AZ32)=0,0,IF(SUM(AQ32:AT32)=SUM(AW32:AZ32),1,0)) -> 0 | AI32: 1 | AK32: =SUMIFS(AM$3:AM$251,$A$3:$A$251,$A32) -> 0 | AL32: =SUMIFS(AN$3:AN$251,$A$3:$A$251,$A32) -> 1 | AM32: =IF(SUM(AQ32:AT32)=SUM(AW32:AZ32),1,0) -> 0 | AN32: 1 | AP32: =SUM(AQ32:AT32) -> 0 | AQ32: =IF(OR(E32="",E32="TBD",E32="N/A",E32="SDK",E32="SAAS"),0,1) -> 0 | AR32: =IF(OR(F32="",F32="TBD",F32="N/A",F32="SDK",F32="SAAS"),0,1) -> 0 | AS32: =IF(OR(G32="",G32="TBD",G32="N/A",G32="SDK",G32="SAAS"),0,1) -> 0 | AT32: =IF(OR(H32="",H32="TBD",H32="N/A",H32="SDK",H32="SAAS"),0,1) -> 0 | AV32: =SUM(AW32:AZ32) -> 4 | AW32: =IF(OR(E32="",E32="N/A",E32="SDK",E32="SAAS"),0,1) -> 1 | AX32: =IF(OR(F32="",F32="N/A",F32="SDK",F32="SAAS"),0,1) -> 1 | AY32: =IF(OR(G32="",G32="N/A",G32="SDK",G32="SAAS"),0,1) -> 1 | AZ32: =IF(OR(H32="",H32="N/A",H32="SDK",H32="SAAS"),0,1) -> 1
A33: MD - 001 | B33: Onboarding | C33: Generación y versionamiento de Plantillas HTML asociadas a la experiencia digital | D33: SAAS | E33: SAAS | F33: SAAS | G33: SAAS | H33: SAAS | K33: =J33*$J$147 -> 0 | L33: Backlog | M33: Rafael Elizalde | N33: x | V33: Sí | W33: Por definir | AB33: =IF(AG33=0,0,IF(AF33=AG33,1,0))*AD33 -> 0 | AC33: =IF(AK33=AL33,1,0)*AD33 -> 1 | AD33: =IF(ISNUMBER(MATCH(A33,$A$2:A32,0)),0,1) -> 1 | AF33: =SUMIFS(AH$3:AH$251,$A$3:$A$251,$A33) -> 0 | AG33: =SUMIFS(AI$3:AI$77,$A$3:$A$77,$A33) -> 1 | AH33: =IF(SUM(AW33:AZ33)=0,0,IF(SUM(AQ33:AT33)=SUM(AW33:AZ33),1,0)) -> 0 | AI33: 1 | AK33: =SUMIFS(AM$3:AM$251,$A$3:$A$251,$A33) -> 1 | AL33: =SUMIFS(AN$3:AN$251,$A$3:$A$251,$A33) -> 1 | AM33: =IF(SUM(AQ33:AT33)=SUM(AW33:AZ33),1,0) -> 1 | AN33: 1 | AP33: =SUM(AQ33:AT33) -> 0 | AQ33: =IF(OR(E33="",E33="TBD",E33="N/A",E33="SDK",E33="SAAS"),0,1) -> 0 | AR33: =IF(OR(F33="",F33="TBD",F33="N/A",F33="SDK",F33="SAAS"),0,1) -> 0 | AS33: =IF(OR(G33="",G33="TBD",G33="N/A",G33="SDK",G33="SAAS"),0,1) -> 0 | AT33: =IF(OR(H33="",H33="TBD",H33="N/A",H33="SDK",H33="SAAS"),0,1) -> 0 | AV33: =SUM(AW33:AZ33) -> 0 | AW33: =IF(OR(E33="",E33="N/A",E33="SDK",E33="SAAS"),0,1) -> 0 | AX33: =IF(OR(F33="",F33="N/A",F33="SDK",F33="SAAS"),0,1) -> 0 | AY33: =IF(OR(G33="",G33="N/A",G33="SDK",G33="SAAS"),0,1) -> 0 | AZ33: =IF(OR(H33="",H33="N/A",H33="SDK",H33="SAAS"),0,1) -> 0
A34: MD - 002 | B34: Onboarding | C34: Contar con catálogo de plantillas HTML que permitan la reutilización de código | D34: SAAS | E34: SAAS | F34: SAAS | G34: SAAS | H34: SAAS | K34: =J34*$J$147 -> 0 | L34: Backlog | M34: Rafael Elizalde | N34: x | V34: Sí | W34: Por definir | AB34: =IF(AG34=0,0,IF(AF34=AG34,1,0))*AD34 -> 0 | AC34: =IF(AK34=AL34,1,0)*AD34 -> 1 | AD34: =IF(ISNUMBER(MATCH(A34,$A$2:A33,0)),0,1) -> 1 | AF34: =SUMIFS(AH$3:AH$251,$A$3:$A$251,$A34) -> 0 | AG34: =SUMIFS(AI$3:AI$77,$A$3:$A$77,$A34) -> 1 | AH34: =IF(SUM(AW34:AZ34)=0,0,IF(SUM(AQ34:AT34)=SUM(AW34:AZ34),1,0)) -> 0 | AI34: 1 | AK34: =SUMIFS(AM$3:AM$251,$A$3:$A$251,$A34) -> 1 | AL34: =SUMIFS(AN$3:AN$251,$A$3:$A$251,$A34) -> 1 | AM34: =IF(SUM(AQ34:AT34)=SUM(AW34:AZ34),1,0) -> 1 | AN34: 1 | AP34: =SUM(AQ34:AT34) -> 0 | AQ34: =IF(OR(E34="",E34="TBD",E34="N/A",E34="SDK",E34="SAAS"),0,1) -> 0 | AR34: =IF(OR(F34="",F34="TBD",F34="N/A",F34="SDK",F34="SAAS"),0,1) -> 0 | AS34: =IF(OR(G34="",G34="TBD",G34="N/A",G34="SDK",G34="SAAS"),0,1) -> 0 | AT34: =IF(OR(H34="",H34="TBD",H34="N/A",H34="SDK",H34="SAAS"),0,1) -> 0 | AV34: =SUM(AW34:AZ34) -> 0 | AW34: =IF(OR(E34="",E34="N/A",E34="SDK",E34="SAAS"),0,1) -> 0 | AX34: =IF(OR(F34="",F34="N/A",F34="SDK",F34="SAAS"),0,1) -> 0 | AY34: =IF(OR(G34="",G34="N/A",G34="SDK",G34="SAAS"),0,1) -> 0 | AZ34: =IF(OR(H34="",H34="N/A",H34="SDK",H34="SAAS"),0,1) -> 0
A35: MD - 003 | B35: Onboarding | C35: Gestión de sitios para organizar los canales digitales de la compañía | D35: SAAS | E35: SAAS | F35: SAAS | G35: SAAS | H35: SAAS | K35: =J35*$J$147 -> 0 | L35: Backlog | M35: Rafael Elizalde | N35: x | V35: Sí | W35: Por definir | AB35: =IF(AG35=0,0,IF(AF35=AG35,1,0))*AD35 -> 0 | AC35: =IF(AK35=AL35,1,0)*AD35 -> 1 | AD35: =IF(ISNUMBER(MATCH(A35,$A$2:A34,0)),0,1) -> 1 | AF35: =SUMIFS(AH$3:AH$251,$A$3:$A$251,$A35) -> 0 | AG35: =SUMIFS(AI$3:AI$77,$A$3:$A$77,$A35) -> 1 | AH35: =IF(SUM(AW35:AZ35)=0,0,IF(SUM(AQ35:AT35)=SUM(AW35:AZ35),1,0)) -> 0 | AI35: 1 | AK35: =SUMIFS(AM$3:AM$251,$A$3:$A$251,$A35) -> 1 | AL35: =SUMIFS(AN$3:AN$251,$A$3:$A$251,$A35) -> 1 | AM35: =IF(SUM(AQ35:AT35)=SUM(AW35:AZ35),1,0) -> 1 | AN35: 1 | AP35: =SUM(AQ35:AT35) -> 0 | AQ35: =IF(OR(E35="",E35="TBD",E35="N/A",E35="SDK",E35="SAAS"),0,1) -> 0 | AR35: =IF(OR(F35="",F35="TBD",F35="N/A",F35="SDK",F35="SAAS"),0,1) -> 0 | AS35: =IF(OR(G35="",G35="TBD",G35="N/A",G35="SDK",G35="SAAS"),0,1) -> 0 | AT35: =IF(OR(H35="",H35="TBD",H35="N/A",H35="SDK",H35="SAAS"),0,1) -> 0 | AV35: =SUM(AW35:AZ35) -> 0 | AW35: =IF(OR(E35="",E35="N/A",E35="SDK",E35="SAAS"),0,1) -> 0 | AX35: =IF(OR(F35="",F35="N/A",F35="SDK",F35="SAAS"),0,1) -> 0 | AY35: =IF(OR(G35="",G35="N/A",G35="SDK",G35="SAAS"),0,1) -> 0 | AZ35: =IF(OR(H35="",H35="N/A",H35="SDK",H35="SAAS"),0,1) -> 0
A36: MD - 004 | B36: Onboarding | C36: Páginas dinámicas para definir la estructura de cada sitio y agregar contenido | D36: SAAS | E36: SAAS | F36: SAAS | G36: SAAS | H36: SAAS | K36: =J36*$J$147 -> 0 | L36: Backlog | M36: Rafael Elizalde | N36: x | V36: Sí | W36: Por definir | AB36: =IF(AG36=0,0,IF(AF36=AG36,1,0))*AD36 -> 0 | AC36: =IF(AK36=AL36,1,0)*AD36 -> 1 | AD36: =IF(ISNUMBER(MATCH(A36,$A$2:A35,0)),0,1) -> 1 | AF36: =SUMIFS(AH$3:AH$251,$A$3:$A$251,$A36) -> 0 | AG36: =SUMIFS(AI$3:AI$77,$A$3:$A$77,$A36) -> 1 | AH36: =IF(SUM(AW36:AZ36)=0,0,IF(SUM(AQ36:AT36)=SUM(AW36:AZ36),1,0)) -> 0 | AI36: 1 | AK36: =SUMIFS(AM$3:AM$251,$A$3:$A$251,$A36) -> 1 | AL36: =SUMIFS(AN$3:AN$251,$A$3:$A$251,$A36) -> 1 | AM36: =IF(SUM(AQ36:AT36)=SUM(AW36:AZ36),1,0) -> 1 | AN36: 1 | AP36: =SUM(AQ36:AT36) -> 0 | AQ36: =IF(OR(E36="",E36="TBD",E36="N/A",E36="SDK",E36="SAAS"),0,1) -> 0 | AR36: =IF(OR(F36="",F36="TBD",F36="N/A",F36="SDK",F36="SAAS"),0,1) -> 0 | AS36: =IF(OR(G36="",G36="TBD",G36="N/A",G36="SDK",G36="SAAS"),0,1) -> 0 | AT36: =IF(OR(H36="",H36="TBD",H36="N/A",H36="SDK",H36="SAAS"),0,1) -> 0 | AV36: =SUM(AW36:AZ36) -> 0 | AW36: =IF(OR(E36="",E36="N/A",E36="SDK",E36="SAAS"),0,1) -> 0 | AX36: =IF(OR(F36="",F36="N/A",F36="SDK",F36="SAAS"),0,1) -> 0 | AY36: =IF(OR(G36="",G36="N/A",G36="SDK",G36="SAAS"),0,1) -> 0 | AZ36: =IF(OR(H36="",H36="N/A",H36="SDK",H36="SAAS"),0,1) -> 0
A37: MD - 005 | B37: Onboarding | C37: Capacidad de crear componentes reutilizables usando tecnologías de Javascript, HTML y CSS | D37: SAAS | E37: SAAS | F37: SAAS | G37: SAAS | H37: SAAS | K37: =J37*$J$147 -> 0 | L37: Backlog | M37: Rafael Elizalde | N37: x | V37: Sí | W37: Por definir | AB37: =IF(AG37=0,0,IF(AF37=AG37,1,0))*AD37 -> 0 | AC37: =IF(AK37=AL37,1,0)*AD37 -> 1 | AD37: =IF(ISNUMBER(MATCH(A37,$A$2:A36,0)),0,1) -> 1 | AF37: =SUMIFS(AH$3:AH$251,$A$3:$A$251,$A37) -> 0 | AG37: =SUMIFS(AI$3:AI$77,$A$3:$A$77,$A37) -> 1 | AH37: =IF(SUM(AW37:AZ37)=0,0,IF(SUM(AQ37:AT37)=SUM(AW37:AZ37),1,0)) -> 0 | AI37: 1 | AK37: =SUMIFS(AM$3:AM$251,$A$3:$A$251,$A37) -> 1 | AL37: =SUMIFS(AN$3:AN$251,$A$3:$A$251,$A37) -> 1 | AM37: =IF(SUM(AQ37:AT37)=SUM(AW37:AZ37),1,0) -> 1 | AN37: 1 | AP37: =SUM(AQ37:AT37) -> 0 | AQ37: =IF(OR(E37="",E37="TBD",E37="N/A",E37="SDK",E37="SAAS"),0,1) -> 0 | AR37: =IF(OR(F37="",F37="TBD",F37="N/A",F37="SDK",F37="SAAS"),0,1) -> 0 | AS37: =IF(OR(G37="",G37="TBD",G37="N/A",G37="SDK",G37="SAAS"),0,1) -> 0 | AT37: =IF(OR(H37="",H37="TBD",H37="N/A",H37="SDK",H37="SAAS"),0,1) -> 0 | AV37: =SUM(AW37:AZ37) -> 0 | AW37: =IF(OR(E37="",E37="N/A",E37="SDK",E37="SAAS"),0,1) -> 0 | AX37: =IF(OR(F37="",F37="N/A",F37="SDK",F37="SAAS"),0,1) -> 0 | AY37: =IF(OR(G37="",G37="N/A",G37="SDK",G37="SAAS"),0,1) -> 0 | AZ37: =IF(OR(H37="",H37="N/A",H37="SDK",H37="SAAS"),0,1) -> 0
A38: MD - 006 | B38: Onboarding | C38: Capacidad para crear micro frontends para múltiples sitios y aplicaciones | D38: SAAS | E38: SAAS | F38: SAAS | G38: SAAS | H38: SAAS | K38: =J38*$J$147 -> 0 | L38: Backlog | M38: Rafael Elizalde | N38: x | V38: Sí | W38: Por definir | AB38: =IF(AG38=0,0,IF(AF38=AG38,1,0))*AD38 -> 0 | AC38: =IF(AK38=AL38,1,0)*AD38 -> 1 | AD38: =IF(ISNUMBER(MATCH(A38,$A$2:A37,0)),0,1) -> 1 | AF38: =SUMIFS(AH$3:AH$251,$A$3:$A$251,$A38) -> 0 | AG38: =SUMIFS(AI$3:AI$77,$A$3:$A$77,$A38) -> 1 | AH38: =IF(SUM(AW38:AZ38)=0,0,IF(SUM(AQ38:AT38)=SUM(AW38:AZ38),1,0)) -> 0 | AI38: 1 | AK38: =SUMIFS(AM$3:AM$251,$A$3:$A$251,$A38) -> 1 | AL38: =SUMIFS(AN$3:AN$251,$A$3:$A$251,$A38) -> 1 | AM38: =IF(SUM(AQ38:AT38)=SUM(AW38:AZ38),1,0) -> 1 | AN38: 1 | AP38: =SUM(AQ38:AT38) -> 0 | AQ38: =IF(OR(E38="",E38="TBD",E38="N/A",E38="SDK",E38="SAAS"),0,1) -> 0 | AR38: =IF(OR(F38="",F38="TBD",F38="N/A",F38="SDK",F38="SAAS"),0,1) -> 0 | AS38: =IF(OR(G38="",G38="TBD",G38="N/A",G38="SDK",G38="SAAS"),0,1) -> 0 | AT38: =IF(OR(H38="",H38="TBD",H38="N/A",H38="SDK",H38="SAAS"),0,1) -> 0 | AV38: =SUM(AW38:AZ38) -> 0 | AW38: =IF(OR(E38="",E38="N/A",E38="SDK",E38="SAAS"),0,1) -> 0 | AX38: =IF(OR(F38="",F38="N/A",F38="SDK",F38="SAAS"),0,1) -> 0 | AY38: =IF(OR(G38="",G38="N/A",G38="SDK",G38="SAAS"),0,1) -> 0 | AZ38: =IF(OR(H38="",H38="N/A",H38="SDK",H38="SAAS"),0,1) -> 0
A39: MD - 007 | B39: Onboarding | C39: Capacidad para extender funcionalidades a diferentes sitios y aplicaciones incluso con una entidad separada | D39: SAAS | E39: SAAS | F39: SAAS | G39: SAAS | H39: SAAS | K39: =J39*$J$147 -> 0 | L39: Backlog | M39: Rafael Elizalde | N39: x | V39: Sí | W39: Por definir | AB39: =IF(AG39=0,0,IF(AF39=AG39,1,0))*AD39 -> 0 | AC39: =IF(AK39=AL39,1,0)*AD39 -> 1 | AD39: =IF(ISNUMBER(MATCH(A39,$A$2:A38,0)),0,1) -> 1 | AF39: =SUMIFS(AH$3:AH$251,$A$3:$A$251,$A39) -> 0 | AG39: =SUMIFS(AI$3:AI$77,$A$3:$A$77,$A39) -> 1 | AH39: =IF(SUM(AW39:AZ39)=0,0,IF(SUM(AQ39:AT39)=SUM(AW39:AZ39),1,0)) -> 0 | AI39: 1 | AK39: =SUMIFS(AM$3:AM$251,$A$3:$A$251,$A39) -> 1 | AL39: =SUMIFS(AN$3:AN$251,$A$3:$A$251,$A39) -> 1 | AM39: =IF(SUM(AQ39:AT39)=SUM(AW39:AZ39),1,0) -> 1 | AN39: 1 | AP39: =SUM(AQ39:AT39) -> 0 | AQ39: =IF(OR(E39="",E39="TBD",E39="N/A",E39="SDK",E39="SAAS"),0,1) -> 0 | AR39: =IF(OR(F39="",F39="TBD",F39="N/A",F39="SDK",F39="SAAS"),0,1) -> 0 | AS39: =IF(OR(G39="",G39="TBD",G39="N/A",G39="SDK",G39="SAAS"),0,1) -> 0 | AT39: =IF(OR(H39="",H39="TBD",H39="N/A",H39="SDK",H39="SAAS"),0,1) -> 0 | AV39: =SUM(AW39:AZ39) -> 0 | AW39: =IF(OR(E39="",E39="N/A",E39="SDK",E39="SAAS"),0,1) -> 0 | AX39: =IF(OR(F39="",F39="N/A",F39="SDK",F39="SAAS"),0,1) -> 0 | AY39: =IF(OR(G39="",G39="N/A",G39="SDK",G39="SAAS"),0,1) -> 0 | AZ39: =IF(OR(H39="",H39="N/A",H39="SDK",H39="SAAS"),0,1) -> 0
A40: MD - 008 | B40: Onboarding | C40: Segmentación de componentes de acuerdo a su estado, autor, tags o por nombre de la funcionalidad | D40: SAAS | E40: SAAS | F40: SAAS | G40: SAAS | H40: SAAS | K40: =J40*$J$147 -> 0 | L40: Backlog | M40: Rafael Elizalde | N40: x | V40: Sí | W40: Por definir | AB40: =IF(AG40=0,0,IF(AF40=AG40,1,0))*AD40 -> 0 | AC40: =IF(AK40=AL40,1,0)*AD40 -> 1 | AD40: =IF(ISNUMBER(MATCH(A40,$A$2:A39,0)),0,1) -> 1 | AF40: =SUMIFS(AH$3:AH$251,$A$3:$A$251,$A40) -> 0 | AG40: =SUMIFS(AI$3:AI$77,$A$3:$A$77,$A40) -> 1 | AH40: =IF(SUM(AW40:AZ40)=0,0,IF(SUM(AQ40:AT40)=SUM(AW40:AZ40),1,0)) -> 0 | AI40: 1 | AK40: =SUMIFS(AM$3:AM$251,$A$3:$A$251,$A40) -> 1 | AL40: =SUMIFS(AN$3:AN$251,$A$3:$A$251,$A40) -> 1 | AM40: =IF(SUM(AQ40:AT40)=SUM(AW40:AZ40),1,0) -> 1 | AN40: 1 | AP40: =SUM(AQ40:AT40) -> 0 | AQ40: =IF(OR(E40="",E40="TBD",E40="N/A",E40="SDK",E40="SAAS"),0,1) -> 0 | AR40: =IF(OR(F40="",F40="TBD",F40="N/A",F40="SDK",F40="SAAS"),0,1) -> 0 | AS40: =IF(OR(G40="",G40="TBD",G40="N/A",G40="SDK",G40="SAAS"),0,1) -> 0 | AT40: =IF(OR(H40="",H40="TBD",H40="N/A",H40="SDK",H40="SAAS"),0,1) -> 0 | AV40: =SUM(AW40:AZ40) -> 0 | AW40: =IF(OR(E40="",E40="N/A",E40="SDK",E40="SAAS"),0,1) -> 0 | AX40: =IF(OR(F40="",F40="N/A",F40="SDK",F40="SAAS"),0,1) -> 0 | AY40: =IF(OR(G40="",G40="N/A",G40="SDK",G40="SAAS"),0,1) -> 0 | AZ40: =IF(OR(H40="",H40="N/A",H40="SDK",H40="SAAS"),0,1) -> 0
...

Sheet BD_OnboardingSim
F1: Apificación | P1: Canal | X1: Avance de Funcionalidad | AH1: Solo APIS | AM1: TOTAL | AS1: diseñadas | AU1: Dominio | AV1: Sistema | AY1: totales | BA1: Dominio | BB1: Sistema
A2: ID | B2: Tipo | C2: DESCRIPCION | F2: Base | G2: Recepción | H2: Negocio | I2: Dominio | J2: Sistema | K2: APIs proceso actual | L2: SPL proceso actual | M2: APIs Estimadas To Be | N2: Estatus de Api | O2: Responsable | P2: Apolo | Q2: Sucursal | R2: MAD | S2: App | T2: CAT | U2: BPI | V2: BO | W2: ATM | X2: Contemplado MVP | Y2: Estatus | Z2: Comentario | AA2: Fecha Inicio | AB2: Fecha Estimada | AD2: Funcionalidades Totales Habilitadas (SOLO APIS) | AE2: Funcionalidades Totales Habilitadas (diseñadas + SDK+ SAAS) | AF2: Conteo Fx | AH2: totales actuales | AI2: totales esperado | AJ2: Completadas actual | AK2: Completas esperado | AM2: totales actuales | AN2: totales esperado | AO2: Completadas actual | AP2: Completas esperado | AR2: Apis diseñadas total | AS2: Recepción | AT2: Negocio | AU2: Transformación | AV2: Sistema | AX2: Apis diseñadas total | AY2: Recepción | AZ2: Negocio | BA2: Transformación | BB2: Sistema
A3: IC-001 | B3: Onboarding | C3: Capturar la identificación | D3: Digitalización de Identificación (INE) | E3: =VLOOKUP(D3,C:C,1,FALSE) -> #N/A | F3: =VLOOKUP(E3,D3,1,FALSE) -> #N/A | G3: /experience/sales/partyLifecycleManagement/v1/documentation/capture | H3: N/A | I3: /sales/partyLifecycleManagement/v1/documentation/capture | J3: /system/sales/partyLifecycleManagement/v1/documentation/capture | L3: 3 | M3: =L3*$L$147 -> 10.5 | N3: Backlog | O3: Rafael Elizalde | P3: x | X3: Sí | Y3: Por definir | AD3: =IF(AI3=0,0,IF(AH3=AI3,1,0))*AF3 -> 0 | AE3: =IF(AM3=AN3,1,0)*AF3 -> 1 | AF3: =IF(ISNUMBER(MATCH(A3,$A$2:A2,0)),0,1) -> 1 | AH3: =SUMIFS(AJ$3:AJ$251,$A$3:$A$251,$A3) -> 1 | AI3: =SUMIFS(AK$3:AK$251,$A$3:$A$251,$A3) -> 2 | AJ3: =IF(SUM(AY3:BB3)=0,0,IF(SUM(AS3:AV3)=SUM(AY3:BB3),1,0)) -> 1 | AK3: 1 | AM3: =SUMIFS(AO$3:AO$251,$A$3:$A$251,$A3) -> 2 | AN3: =SUMIFS(AP$3:AP$251,$A$3:$A$251,$A3) -> 2 | AO3: =IF(SUM(AS3:AV3)=SUM(AY3:BB3),1,0) -> 1 | AP3: 1 | AR3: =SUM(AS3:AV3) -> 3 | AS3: =IF(OR(G3="",G3="TBD",G3="N/A",G3="SDK",G3="SAAS"),0,1) -> 1 | AT3: =IF(OR(H3="",H3="TBD",H3="N/A",H3="SDK",H3="SAAS"),0,1) -> 0 | AU3: =IF(OR(I3="",I3="TBD",I3="N/A",I3="SDK",I3="SAAS"),0,1) -> 1 | AV3: =IF(OR(J3="",J3="TBD",J3="N/A",J3="SDK",J3="SAAS"),0,1) -> 1 | AX3: =SUM(AY3:BB3) -> 3 | AY3: =IF(OR(G3="",G3="N/A",G3="SDK",G3="SAAS"),0,1) -> 1 | AZ3: =IF(OR(H3="",H3="N/A",H3="SDK",H3="SAAS"),0,1) -> 0 | BA3: =IF(OR(I3="",I3="N/A",I3="SDK",I3="SAAS"),0,1) -> 1 | BB3: =IF(OR(J3="",J3="N/A",J3="SDK",J3="SAAS"),0,1) -> 1
