Workbook

Sheet metrics
B2: Layer | C2: API Component | E2: Layer | F2: API Operations | H2: Layer | I2: API Component | K2: Total Of Records
B3: Business Rule | C3: =IFERROR(__xludf.DUMMYFUNCTION("COUNTUNIQUEIFS(develop!F2:F1001,develop!D2:D1001,""BUSINESS RULE"")"),4.0) -> 4 | E3: Business Rule | F3: =COUNTIF(develop!D1:D1001,"BUSINESS RULE") -> 11 | H3: Business Rule | I3: =IFERROR(__xludf.DUMMYFUNCTION("COUNTUNIQUEIFS('api-register-id'!B2:B1001,'api-register-id'!D2:D1001,""BUSINESS RULES"")"),5.0) -> 5 | K3: =IFERROR(__xludf.DUMMYFUNCTION("COUNTUNIQUE(develop!G2:G1001)"),1652.0) -> 1652
B4: Reception | C4: =IFERROR(__xludf.DUMMYFUNCTION("COUNTUNIQUEIFS(develop!F2:F1001,develop!D2:D1001,""RECEPTION"")"),72.0) -> 72 | E4: Reception | F4: =COUNTIF(develop!D2:D1001,"RECEPTION") -> 410 | H4: Reception | I4: =IFERROR(__xludf.DUMMYFUNCTION("COUNTUNIQUEIFS('api-register-id'!B2:B1001,'api-register-id'!D2:D1001,""RECEPTION"")"),72.0) -> 72
B5: Business | C5: =IFERROR(__xludf.DUMMYFUNCTION("COUNTUNIQUEIFS(develop!F2:F1001,develop!D2:D1001,""BUSINESS"")"),26.0) -> 26 | E5: Business | F5: =COUNTIF(develop!D2:D1001,"BUSINESS") -> 138 | H5: Business | I5: =IFERROR(__xludf.DUMMYFUNCTION("COUNTUNIQUEIFS('api-register-id'!B2:B1001,'api-register-id'!D2:D1001,""BUSINESS"")"),28.0) -> 28
B6: Domain | C6: =IFERROR(__xludf.DUMMYFUNCTION("COUNTUNIQUEIFS(develop!F2:F1001,develop!D2:D1001,""DOMAIN"")"),76.0) -> 76 | E6: Domain | F6: =COUNTIF(develop!D2:D1001,"DOMAIN") -> 515 | H6: Domain | I6: =IFERROR(__xludf.DUMMYFUNCTION("COUNTUNIQUEIFS('api-register-id'!B2:B1001,'api-register-id'!D2:D1001,""DOMAIN"")"),74.0) -> 74
B7: Proxy | C7: =IFERROR(__xludf.DUMMYFUNCTION("COUNTUNIQUEIFS(develop!F2:F1001,develop!D2:D1001,""PROXY"")"),91.0) -> 91 | E7: Proxy | F7: =COUNTIF(develop!D2:D1001,"PROXY") -> 554 | H7: Proxy | I7: =IFERROR(__xludf.DUMMYFUNCTION("COUNTUNIQUEIFS('api-register-id'!B2:B1001,'api-register-id'!D2:D1001,""PROXY"")"),89.0) -> 89
B9: Total | C9: =SUM(C3:C7) -> 269 | E9: Total | F9: =SUM(F3:F7) -> 1628 | H9: Total | I9: =SUM(I3:I7) -> 268
B11: Specification | C11: API Component | E11: Specification | F11: API Operations
B12: RAML | C12: =IFERROR(__xludf.DUMMYFUNCTION("COUNTUNIQUEIFS(develop!F2:F1001,develop!C2:C1001,""RAML"")"),195.0) -> 195 | E12: RAML | F12: =COUNTIF(develop!C:C,"RAML") -> 1209
B13: OAS | C13: =IFERROR(__xludf.DUMMYFUNCTION("COUNTUNIQUEIFS(develop!F2:F1001,develop!C2:C1001,""OAS"")"),76.0) -> 76 | E13: OAS | F13: =COUNTIF(develop!C:C,"OAS") -> 419
B15: Total | C15: =IFERROR(__xludf.DUMMYFUNCTION("COUNTUNIQUE(develop!F2:F1001)"),271.0) -> 271 | E15: Total | F15: =SUM(F12:F13) -> 1628

Sheet develop
A1: Organización | B1: API Repository | C1: API Specification | D1: API Type | E1: API Register ID | F1: API Name | G1: API Resource ID | H1: API Operation ID | I1: API Version | J1: API Base Path | K1: Resource Version | L1: HTTP Method | M1: API Operation Resource | N1: API Operation Full Path | O1: API Operation Description | P1: API Error | Q1: Confluence | R1: Status | S1: Link GitHub | T1: Complejidad API | V1: Persona asignada (carga liga Confluence) | W1: Observaciones carga liga de Confluence
A2: {=IFERROR( INDEX( 'api-register-id'!A:A, MATCH(F2, 'api-register-id'!B:B, 0) ), "Not found Organization" )} -> SSFF | B2: =IFERROR(VLOOKUP(F2, 'api-register-id'!B:F, 4, FALSE), "Not found path.") -> mx-api-bc-bus-business-support | C2: RAML | D2: BUSINESS | E2: =IFERROR(VLOOKUP(F2, 'api-register-id'!B:F, 5, FALSE), "Not found path.") -> APIMX000001 | F2: Bus Business Support | G2: RESMX000001 | H2: Bus_ExecuteSmsNotificationV1 | I2: =IFERROR(VLOOKUP(F2, 'api-register-id'!B:I, 8, FALSE), "Not found path.") -> 1.3.0 | J2: /businessSupport | K2: v1 | L2: POST | M2: /v1/smsNotification/execute | N2: =CONCATENATE(L2," ",J2,M2) -> POST /businessSupport/v1/smsNotification/execute | O2: Operación encargada de realizar el envío de notificaciones SMS al cliente. | P2: Invalid Action Term "execute" for HTTP method "POST". For Action Term "execute" use "PUT,PATCH" | Q2: https://coppelmx.atlassian.net/wiki/spaces/GAC/pages/edit-v2/2157347017 | R2: Design | S2: ="https://github.com/SF-Bancoppel/"&B2 -> https://github.com/SF-Bancoppel/mx-api-bc-bus-business-support
A3: {=IFERROR( INDEX( 'api-register-id'!A:A, MATCH(F3, 'api-register-id'!B:B, 0) ), "Not found Organization" )} -> SSFF | B3: =IFERROR(VLOOKUP(F3, 'api-register-id'!B:F, 4, FALSE), "Not found path.") -> mx-api-bc-bus-business-support | C3: RAML | D3: BUSINESS | E3: =IFERROR(VLOOKUP(F3, 'api-register-id'!B:F, 5, FALSE), "Not found path.") -> APIMX000001 | F3: Bus Business Support | G3: RESMX000002 | H3: Bus_ExecuteExecuteOrderConfirmationV1 | I3: =IFERROR(VLOOKUP(F3, 'api-register-id'!B:I, 8, FALSE), "Not found path.") -> 1.3.0 | J3: /businessSupport | K3: v1 | L3: PUT | M3: /v1/executeOrderConfirmation/execute | N3: =CONCATENATE(L3," ",J3,M3) -> PUT /businessSupport/v1/executeOrderConfirmation/execute | O3: Operación encargada de confirmar el registro de un movimiento generado para Coppel. | P3: The Behavior Qualifier cannot include the action term value "execute". Remove the Action Term of "executeOrderConfirmation". | Q3: https://coppelmx.atlassian.net/wiki/spaces/GAC/pages/2158362691/RESMX000002_Bus_ExecuteExecuteOrderConfirmation_V1 | R3: Design | S3: ="https://github.com/SF-Bancoppel/"&B3 -> https://github.com/SF-Bancoppel/mx-api-bc-bus-business-support
A4: {=IFERROR( INDEX( 'api-register-id'!A:A, MATCH(F4, 'api-register-id'!B:B, 0) ), "Not found Organization" )} -> SSFF | B4: =IFERROR(VLOOKUP(F4, 'api-register-id'!B:F, 4, FALSE), "Not found path.") -> mx-api-bc-bus-business-support | C4: RAML | D4: BUSINESS | E4: =IFERROR(VLOOKUP(F4, 'api-register-id'!B:F, 5, FALSE), "Not found path.") -> APIMX000001 | F4: Bus Business Support | G4: RESMX000003 | H4: Bus_RetrieveOrderCancellationV1 | I4: =IFERROR(VLOOKUP(F4, 'api-register-id'!B:I, 8, FALSE), "Not found path.") -> 1.3.0 | J4: /businessSupport | K4: v1 | L4: POST | M4: /v1/orderCancellation/retrieve | N4: =CONCATENATE(L4," ",J4,M4) -> POST /businessSupport/v1/orderCancellation/retrieve | O4: Operación encargada de obtener la información de la orden de cancelación de transferencia. | Q4: https://coppelmx.atlassian.net/wiki/spaces/GAC/pages/2157936745/RESMX000003_Bus_RetrieveOrderCancellation_V1 | R4: Design | S4: ="https://github.com/SF-Bancoppel/"&B4 -> https://github.com/SF-Bancoppel/mx-api-bc-bus-business-support
A5: {=IFERROR( INDEX( 'api-register-id'!A:A, MATCH(F5, 'api-register-id'!B:B, 0) ), "Not found Organization" )} -> SSFF | B5: =IFERROR(VLOOKUP(F5, 'api-register-id'!B:F, 4, FALSE), "Not found path.") -> mx-api-bc-bus-business-support | C5: RAML | D5: BUSINESS | E5: =IFERROR(VLOOKUP(F5, 'api-register-id'!B:F, 5, FALSE), "Not found path.") -> APIMX000001 | F5: Bus Business Support | G5: RESMX000004 | H5: Bus_InitiatePaymentOrderProcedureV1 | I5: =IFERROR(VLOOKUP(F5, 'api-register-id'!B:I, 8, FALSE), "Not found path.") -> 1.3.0 | J5: /businessSupport | K5: v1 | L5: POST | M5: /v1/paymentOrderProcedure/initiate | N5: =CONCATENATE(L5," ",J5,M5) -> POST /businessSupport/v1/paymentOrderProcedure/initiate | O5: Operación encargada de generar la trama de Pago ANTAD para Interact. | Q5: https://coppelmx.atlassian.net/wiki/spaces/GAC/pages/2159214684/RESMX000004_Bus_InitiatePaymentOrderProcedure_V1 | R5: Design | S5: ="https://github.com/SF-Bancoppel/"&B5 -> https://github.com/SF-Bancoppel/mx-api-bc-bus-business-support
A6: {=IFERROR( INDEX( 'api-register-id'!A:A, MATCH(F6, 'api-register-id'!B:B, 0) ), "Not found Organization" )} -> SSFF | B6: =IFERROR(VLOOKUP(F6, 'api-register-id'!B:F, 4, FALSE), "Not found path.") -> mx-api-bc-bus-operations-and-execution | C6: RAML | D6: BUSINESS | E6: =IFERROR(VLOOKUP(F6, 'api-register-id'!B:F, 5, FALSE), "Not found path.") -> APIMX000002 | F6: Bus Operations and Execution | G6: RESMX000005 | H6: Bus_InitiateLoanFacilityV1 | I6: =IFERROR(VLOOKUP(F6, 'api-register-id'!B:I, 8, FALSE), "Not found path.") -> 1.16.1 | J6: /operationsAndExecution | K6: v1 | L6: POST | M6: /v1/loanFacility/initiate | N6: =CONCATENATE(L6," ",J6,M6) -> POST /operationsAndExecution/v1/loanFacility/initiate | O6: API que permite orquestar las funcionalidades para registrar un préstamo de Coppel | Q6: Pending load documentation... | R6: Design | S6: ="https://github.com/SF-Bancoppel/"&B6 -> https://github.com/SF-Bancoppel/mx-api-bc-bus-operations-and-execution | V6: Manuel
A7: {=IFERROR( INDEX( 'api-register-id'!A:A, MATCH(F7, 'api-register-id'!B:B, 0) ), "Not found Organization" )} -> SSFF | B7: =IFERROR(VLOOKUP(F7, 'api-register-id'!B:F, 4, FALSE), "Not found path.") -> mx-api-bc-bus-operations-and-execution | C7: RAML | D7: BUSINESS | E7: =IFERROR(VLOOKUP(F7, 'api-register-id'!B:F, 5, FALSE), "Not found path.") -> APIMX000002 | F7: Bus Operations and Execution | G7: RESMX000006 | H7: Bus_RetrieveCreditDataDocumentV1 | I7: =IFERROR(VLOOKUP(F7, 'api-register-id'!B:I, 8, FALSE), "Not found path.") -> 1.16.1 | J7: /operationsAndExecution | K7: v1 | L7: GET | M7: /v1/creditDataDocument/retrieve | N7: =CONCATENATE(L7," ",J7,M7) -> GET /operationsAndExecution/v1/creditDataDocument/retrieve | O7: API que obtiene los datos de la caratula de los prestamos del cliente. | Q7: Pending load documentation... | R7: Design | S7: ="https://github.com/SF-Bancoppel/"&B7 -> https://github.com/SF-Bancoppel/mx-api-bc-bus-operations-and-execution | V7: Manuel
A8: {=IFERROR( INDEX( 'api-register-id'!A:A, MATCH(F8, 'api-register-id'!B:B, 0) ), "Not found Organization" )} -> SSFF | B8: =IFERROR(VLOOKUP(F8, 'api-register-id'!B:F, 4, FALSE), "Not found path.") -> mx-api-bc-bus-operations-and-execution | C8: RAML | D8: BUSINESS | E8: =IFERROR(VLOOKUP(F8, 'api-register-id'!B:F, 5, FALSE), "Not found path.") -> APIMX000002 | F8: Bus Operations and Execution | G8: RESMX000007 | H8: Bus_RetrieveCustomerCreditBalanceV1 | I8: =IFERROR(VLOOKUP(F8, 'api-register-id'!B:I, 8, FALSE), "Not found path.") -> 1.16.1 | J8: /operationsAndExecution | K8: v1 | L8: GET | M8: /v1/customerCreditBalance/retrieve | N8: =CONCATENATE(L8," ",J8,M8) -> GET /operationsAndExecution/v1/customerCreditBalance/retrieve | O8: API que permite consultar el saldo y plazo del crédito. | Q8: Pending load documentation... | R8: Design | S8: ="https://github.com/SF-Bancoppel/"&B8 -> https://github.com/SF-Bancoppel/mx-api-bc-bus-operations-and-execution | V8: Manuel
A9: {=IFERROR( INDEX( 'api-register-id'!A:A, MATCH(F9, 'api-register-id'!B:B, 0) ), "Not found Organization" )} -> SSFF | B9: =IFERROR(VLOOKUP(F9, 'api-register-id'!B:F, 4, FALSE), "Not found path.") -> mx-api-bc-bus-operations-and-execution | C9: RAML | D9: BUSINESS | E9: =IFERROR(VLOOKUP(F9, 'api-register-id'!B:F, 5, FALSE), "Not found path.") -> APIMX000002 | F9: Bus Operations and Execution | G9: RESMX000008 | H9: Bus_RetrieveCustomerProductInformationV1 | I9: =IFERROR(VLOOKUP(F9, 'api-register-id'!B:I, 8, FALSE), "Not found path.") -> 1.16.1 | J9: /operationsAndExecution | K9: v1 | L9: GET | M9: /v1/customerProductInformation/{companyReference}/retrieve | N9: =CONCATENATE(L9," ",J9,M9) -> GET /operationsAndExecution/v1/customerProductInformation/{companyReference}/retrieve | O9: API que permite consultar los datos generales de un producto (tarjeta de crédito,cheque,préstamos) por número de cliente | Q9: Pending load documentation... | R9: Design | S9: ="https://github.com/SF-Bancoppel/"&B9 -> https://github.com/SF-Bancoppel/mx-api-bc-bus-operations-and-execution | V9: Manuel
A10: {=IFERROR( INDEX( 'api-register-id'!A:A, MATCH(F10, 'api-register-id'!B:B, 0) ), "Not found Organization" )} -> SSFF | B10: =IFERROR(VLOOKUP(F10, 'api-register-id'!B:F, 4, FALSE), "Not found path.") -> mx-api-bc-bus-operations-and-execution | C10: RAML | D10: BUSINESS | E10: =IFERROR(VLOOKUP(F10, 'api-register-id'!B:F, 5, FALSE), "Not found path.") -> APIMX000002 | F10: Bus Operations and Execution | G10: RESMX000009 | H10: Bus_RetrieveBalanceCreditProductV1 | I10: =IFERROR(VLOOKUP(F10, 'api-register-id'!B:I, 8, FALSE), "Not found path.") -> 1.16.1 | J10: /operationsAndExecution | K10: v1 | L10: GET | M10: /v1/balanceCreditProduct/retrieve | N10: =CONCATENATE(L10," ",J10,M10) -> GET /operationsAndExecution/v1/balanceCreditProduct/retrieve | O10: API que permite consultar los saldos generales de un producto de crédito | Q10: Pending load documentation... | R10: Design | S10: ="https://github.com/SF-Bancoppel/"&B10 -> https://github.com/SF-Bancoppel/mx-api-bc-bus-operations-and-execution | V10: Manuel
A11: {=IFERROR( INDEX( 'api-register-id'!A:A, MATCH(F11, 'api-register-id'!B:B, 0) ), "Not found Organization" )} -> SSFF | B11: =IFERROR(VLOOKUP(F11, 'api-register-id'!B:F, 4, FALSE), "Not found path.") -> mx-api-bc-bus-operations-and-execution | C11: RAML | D11: BUSINESS | E11: =IFERROR(VLOOKUP(F11, 'api-register-id'!B:F, 5, FALSE), "Not found path.") -> APIMX000002 | F11: Bus Operations and Execution | G11: RESMX000010 | H11: Bus_RetrieveBalanceCreditInformationV1 | I11: =IFERROR(VLOOKUP(F11, 'api-register-id'!B:I, 8, FALSE), "Not found path.") -> 1.16.1 | J11: /operationsAndExecution | K11: v1 | L11: GET | M11: /v1/balanceCreditInformation/retrieve | N11: =CONCATENATE(L11," ",J11,M11) -> GET /operationsAndExecution/v1/balanceCreditInformation/retrieve | O11: API que permite consultar los saldos generales de un producto de crédito | Q11: Pending load documentation... | R11: Design | S11: ="https://github.com/SF-Bancoppel/"&B11 -> https://github.com/SF-Bancoppel/mx-api-bc-bus-operations-and-execution | V11: Manuel
A12: {=IFERROR( INDEX( 'api-register-id'!A:A, MATCH(F12, 'api-register-id'!B:B, 0) ), "Not found Organization" )} -> SSFF | B12: =IFERROR(VLOOKUP(F12, 'api-register-id'!B:F, 4, FALSE), "Not found path.") -> mx-api-bc-bus-operations-and-execution | C12: RAML | D12: BUSINESS | E12: =IFERROR(VLOOKUP(F12, 'api-register-id'!B:F, 5, FALSE), "Not found path.") -> APIMX000002 | F12: Bus Operations and Execution | G12: RESMX000011 | H12: Bus_RetrieveLoanAgreementV1 | I12: =IFERROR(VLOOKUP(F12, 'api-register-id'!B:I, 8, FALSE), "Not found path.") -> 1.16.1 | J12: /operationsAndExecution | K12: v1 | L12: GET | M12: /v1/loanAgreement/retrieve | N12: =CONCATENATE(L12," ",J12,M12) -> GET /operationsAndExecution/v1/loanAgreement/retrieve | O12: API que permite consulta el saldo y plazo de un préstamo | Q12: Pending load documentation... | R12: Design | S12: ="https://github.com/SF-Bancoppel/"&B12 -> https://github.com/SF-Bancoppel/mx-api-bc-bus-operations-and-execution | V12: Manuel
A13: {=IFERROR( INDEX( 'api-register-id'!A:A, MATCH(F13, 'api-register-id'!B:B, 0) ), "Not found Organization" )} -> SSFF | B13: =IFERROR(VLOOKUP(F13, 'api-register-id'!B:F, 4, FALSE), "Not found path.") -> mx-api-bc-bus-operations-and-execution | C13: RAML | D13: BUSINESS | E13: =IFERROR(VLOOKUP(F13, 'api-register-id'!B:F, 5, FALSE), "Not found path.") -> APIMX000002 | F13: Bus Operations and Execution | G13: RESMX000012 | H13: Bus_RetrieveSavingAccountBalanceV1 | I13: =IFERROR(VLOOKUP(F13, 'api-register-id'!B:I, 8, FALSE), "Not found path.") -> 1.16.1 | J13: /operationsAndExecution | K13: v1 | L13: GET | M13: /v1/savingAccountBalance/{companyReference}/retrieve | N13: =CONCATENATE(L13," ",J13,M13) -> GET /operationsAndExecution/v1/savingAccountBalance/{companyReference}/retrieve | O13: API que permite orquestar la consulta de saldo de cuenta de ahorro | Q13: Pending load documentation... | R13: Design | S13: ="https://github.com/SF-Bancoppel/"&B13 -> https://github.com/SF-Bancoppel/mx-api-bc-bus-operations-and-execution | V13: Manuel
A14: {=IFERROR( INDEX( 'api-register-id'!A:A, MATCH(F14, 'api-register-id'!B:B, 0) ), "Not found Organization" )} -> SSFF | B14: =IFERROR(VLOOKUP(F14, 'api-register-id'!B:F, 4, FALSE), "Not found path.") -> mx-api-bc-bus-operations-and-execution | C14: RAML | D14: BUSINESS | E14: =IFERROR(VLOOKUP(F14, 'api-register-id'!B:F, 5, FALSE), "Not found path.") -> APIMX000002 | F14: Bus Operations and Execution | G14: RESMX000013 | H14: Bus_RequestCreditCardFacilityApplicationV1 | I14: =IFERROR(VLOOKUP(F14, 'api-register-id'!B:I, 8, FALSE), "Not found path.") -> 1.16.1 | J14: /operationsAndExecution | K14: v1 | L14: POST | M14: /v1/creditCardFacilityApplication/request | N14: =CONCATENATE(L14," ",J14,M14) -> POST /operationsAndExecution/v1/creditCardFacilityApplication/request | O14: Permite ejecutar diferentes acciones sobre el producto Tarjeta de Crédito Oro (1- Verifica si aplica a TDC Oro, 2- Clonar Información Clásica a Oro, 3- Limpiar Clonación Clásica a Oro) | P14: Invalid Action Term "request" for HTTP method "POST". For Action Term "request" use "PUT,PATCH" | Q14: Pending load documentation... | R14: Design | S14: ="https://github.com/SF-Bancoppel/"&B14 -> https://github.com/SF-Bancoppel/mx-api-bc-bus-operations-and-execution | V14: Manuel
A15: {=IFERROR( INDEX( 'api-register-id'!A:A, MATCH(F15, 'api-register-id'!B:B, 0) ), "Not found Organization" )} -> SSFF | B15: =IFERROR(VLOOKUP(F15, 'api-register-id'!B:F, 4, FALSE), "Not found path.") -> mx-api-bc-bus-operations-and-execution | C15: RAML | D15: BUSINESS | E15: =IFERROR(VLOOKUP(F15, 'api-register-id'!B:F, 5, FALSE), "Not found path.") -> APIMX000002 | F15: Bus Operations and Execution | G15: RESMX000014 | H15: Bus_InitiateCreditCardFacilityV1 | I15: =IFERROR(VLOOKUP(F15, 'api-register-id'!B:I, 8, FALSE), "Not found path.") -> 1.16.1 | J15: /operationsAndExecution | K15: v1 | L15: POST | M15: /v1/creditCardFacility/initiate | N15: =CONCATENATE(L15," ",J15,M15) -> POST /operationsAndExecution/v1/creditCardFacility/initiate | O15: Apertura y asignación de tarjeta de crédito | Q15: Pending load documentation... | R15: Design | S15: ="https://github.com/SF-Bancoppel/"&B15 -> https://github.com/SF-Bancoppel/mx-api-bc-bus-operations-and-execution | V15: Manuel
A16: {=IFERROR( INDEX( 'api-register-id'!A:A, MATCH(F16, 'api-register-id'!B:B, 0) ), "Not found Organization" )} -> SSFF | B16: =IFERROR(VLOOKUP(F16, 'api-register-id'!B:F, 4, FALSE), "Not found path.") -> mx-api-bc-bus-operations-and-execution | C16: RAML | D16: BUSINESS | E16: =IFERROR(VLOOKUP(F16, 'api-register-id'!B:F, 5, FALSE), "Not found path.") -> APIMX000002 | F16: Bus Operations and Execution | G16: RESMX000015 | H16: Bus_RetrieveCreditCardInformationV1 | I16: =IFERROR(VLOOKUP(F16, 'api-register-id'!B:I, 8, FALSE), "Not found path.") -> 1.16.1 | J16: /operationsAndExecution | K16: v1 | L16: GET | M16: /v1/creditCardInformation/retrieve | N16: =CONCATENATE(L16," ",J16,M16) -> GET /operationsAndExecution/v1/creditCardInformation/retrieve | O16: API que permite consultar una tarjeta de crédito por número de tarjeta | Q16: Pending load documentation... | R16: Design | S16: ="https://github.com/SF-Bancoppel/"&B16 -> https://github.com/SF-Bancoppel/mx-api-bc-bus-operations-and-execution | V16: Manuel
A17: {=IFERROR( INDEX( 'api-register-id'!A:A, MATCH(F17, 'api-register-id'!B:B, 0) ), "Not found Organization" )} -> SSFF | B17: =IFERROR(VLOOKUP(F17, 'api-register-id'!B:F, 4, FALSE), "Not found path.") -> mx-api-bc-bus-operations-and-execution | C17: RAML | D17: BUSINESS | E17: =IFERROR(VLOOKUP(F17, 'api-register-id'!B:F, 5, FALSE), "Not found path.") -> APIMX000002 | F17: Bus Operations and Execution | G17: RESMX000016 | H17: Bus_RetrieveCreditCardCashProvisionV1 | I17: =IFERROR(VLOOKUP(F17, 'api-register-id'!B:I, 8, FALSE), "Not found path.") -> 1.16.1 | J17: /operationsAndExecution | K17: v1 | L17: GET | M17: /v1/creditCardCashProvision/retrieve | N17: =CONCATENATE(L17," ",J17,M17) -> GET /operationsAndExecution/v1/creditCardCashProvision/retrieve | O17: API que permite orquestar la consulta de disposición de efectivo y la regla de negocio asociada a la funcionalidad | Q17: Pending load documentation... | R17: Design | S17: ="https://github.com/SF-Bancoppel/"&B17 -> https://github.com/SF-Bancoppel/mx-api-bc-bus-operations-and-execution | V17: Manuel
A18: {=IFERROR( INDEX( 'api-register-id'!A:A, MATCH(F18, 'api-register-id'!B:B, 0) ), "Not found Organization" )} -> SSFF | B18: =IFERROR(VLOOKUP(F18, 'api-register-id'!B:F, 4, FALSE), "Not found path.") -> mx-api-bc-bus-operations-and-execution | C18: RAML | D18: BUSINESS | E18: =IFERROR(VLOOKUP(F18, 'api-register-id'!B:F, 5, FALSE), "Not found path.") -> APIMX000002 | F18: Bus Operations and Execution | G18: RESMX000017 | H18: Bus_InitiateCreditCardActivationLogV1 | I18: =IFERROR(VLOOKUP(F18, 'api-register-id'!B:I, 8, FALSE), "Not found path.") -> 1.16.1 | J18: /operationsAndExecution | K18: v1 | L18: POST | M18: /v1/creditCardActivationLog/initiate | N18: =CONCATENATE(L18," ",J18,M18) -> POST /operationsAndExecution/v1/creditCardActivationLog/initiate | O18: Permite grabar una bitácora de la activación de las tarjetas de crédito Bancoppel en ventanilla | Q18: Pending load documentation... | R18: Design | S18: ="https://github.com/SF-Bancoppel/"&B18 -> https://github.com/SF-Bancoppel/mx-api-bc-bus-operations-and-execution | V18: Manuel
A19: {=IFERROR( INDEX( 'api-register-id'!A:A, MATCH(F19, 'api-register-id'!B:B, 0) ), "Not found Organization" )} -> SSFF | B19: =IFERROR(VLOOKUP(F19, 'api-register-id'!B:F, 4, FALSE), "Not found path.") -> mx-api-bc-bus-operations-and-execution | C19: RAML | D19: BUSINESS | E19: =IFERROR(VLOOKUP(F19, 'api-register-id'!B:F, 5, FALSE), "Not found path.") -> APIMX000002 | F19: Bus Operations and Execution | G19: RESMX000018 | H19: Bus_RetrieveCreditCardHolderV1 | I19: =IFERROR(VLOOKUP(F19, 'api-register-id'!B:I, 8, FALSE), "Not found path.") -> 1.16.1 | J19: /operationsAndExecution | K19: v1 | L19: POST | M19: /v1/creditCardHolder/retrieve | N19: =CONCATENATE(L19," ",J19,M19) -> POST /operationsAndExecution/v1/creditCardHolder/retrieve | O19: Permite consultar los tarjetahabientes asociados a una cuenta | Q19: Pending load documentation... | R19: Design | S19: ="https://github.com/SF-Bancoppel/"&B19 -> https://github.com/SF-Bancoppel/mx-api-bc-bus-operations-and-execution | V19: Manuel
A20: {=IFERROR( INDEX( 'api-register-id'!A:A, MATCH(F20, 'api-register-id'!B:B, 0) ), "Not found Organization" )} -> SSFF | B20: =IFERROR(VLOOKUP(F20, 'api-register-id'!B:F, 4, FALSE), "Not found path.") -> mx-api-bc-bus-operations-and-execution | C20: RAML | D20: BUSINESS | E20: =IFERROR(VLOOKUP(F20, 'api-register-id'!B:F, 5, FALSE), "Not found path.") -> APIMX000002 | F20: Bus Operations and Execution | G20: RESMX000019 | H20: Bus_RegisterCustomerUpgradeV1 | I20: =IFERROR(VLOOKUP(F20, 'api-register-id'!B:I, 8, FALSE), "Not found path.") -> 1.16.1 | J20: /operationsAndExecution | K20: v1 | L20: POST | M20: /v1/customerUpgrade/register | N20: =CONCATENATE(L20," ",J20,M20) -> POST /operationsAndExecution/v1/customerUpgrade/register | O20: Api que permite guarda la información del reporte referente a la solicitud de la mejora del producto y plásticos para reposición | Q20: Pending load documentation... | R20: Design | S20: ="https://github.com/SF-Bancoppel/"&B20 -> https://github.com/SF-Bancoppel/mx-api-bc-bus-operations-and-execution | V20: Manuel
A21: {=IFERROR( INDEX( 'api-register-id'!A:A, MATCH(F21, 'api-register-id'!B:B, 0) ), "Not found Organization" )} -> SSFF | B21: =IFERROR(VLOOKUP(F21, 'api-register-id'!B:F, 4, FALSE), "Not found path.") -> mx-api-bc-bus-operations-and-execution | C21: RAML | D21: BUSINESS | E21: =IFERROR(VLOOKUP(F21, 'api-register-id'!B:F, 5, FALSE), "Not found path.") -> APIMX000002 | F21: Bus Operations and Execution | G21: RESMX000020 | H21: Bus_InitiateCustomerUpgradeV1 | I21: =IFERROR(VLOOKUP(F21, 'api-register-id'!B:I, 8, FALSE), "Not found path.") -> 1.16.1 | J21: /operationsAndExecution | K21: v1 | L21: POST | M21: /v1/customerUpgrade/initiate | N21: =CONCATENATE(L21," ",J21,M21) -> POST /operationsAndExecution/v1/customerUpgrade/initiate | O21: Api que permite grabar la información referente a la solicitud del upgrade del producto | Q21: Pending load documentation... | R21: Design | S21: ="https://github.com/SF-Bancoppel/"&B21 -> https://github.com/SF-Bancoppel/mx-api-bc-bus-operations-and-execution | V21: Manuel
A22: {=IFERROR( INDEX( 'api-register-id'!A:A, MATCH(F22, 'api-register-id'!B:B, 0) ), "Not found Organization" )} -> SSFF | B22: =IFERROR(VLOOKUP(F22, 'api-register-id'!B:F, 4, FALSE), "Not found path.") -> mx-api-bc-bus-operations-and-execution | C22: RAML | D22: BUSINESS | E22: =IFERROR(VLOOKUP(F22, 'api-register-id'!B:F, 5, FALSE), "Not found path.") -> APIMX000002 | F22: Bus Operations and Execution | G22: RESMX000021 | H22: Bus_RetrieveCustomerUpgradeV1 | I22: =IFERROR(VLOOKUP(F22, 'api-register-id'!B:I, 8, FALSE), "Not found path.") -> 1.16.1 | J22: /operationsAndExecution | K22: v1 | L22: POST | M22: /v1/customerUpgrade/retrieve | N22: =CONCATENATE(L22," ",J22,M22) -> POST /operationsAndExecution/v1/customerUpgrade/retrieve | O22: Api que permite consultar la información referente a la solicitud del upgrade del producto | Q22: Pending load documentation... | R22: Design | S22: ="https://github.com/SF-Bancoppel/"&B22 -> https://github.com/SF-Bancoppel/mx-api-bc-bus-operations-and-execution | V22: Manuel
A23: {=IFERROR( INDEX( 'api-register-id'!A:A, MATCH(F23, 'api-register-id'!B:B, 0) ), "Not found Organization" )} -> SSFF | B23: =IFERROR(VLOOKUP(F23, 'api-register-id'!B:F, 4, FALSE), "Not found path.") -> mx-api-bc-bus-operations-and-execution | C23: RAML | D23: BUSINESS | E23: =IFERROR(VLOOKUP(F23, 'api-register-id'!B:F, 5, FALSE), "Not found path.") -> APIMX000002 | F23: Bus Operations and Execution | G23: RESMX000022 | H23: Bus_RetrieveBalanceProductV1 | I23: =IFERROR(VLOOKUP(F23, 'api-register-id'!B:I, 8, FALSE), "Not found path.") -> 1.16.1 | J23: /operationsAndExecution | K23: v1 | L23: POST | M23: /v1/balanceProduct/retrieve | N23: =CONCATENATE(L23," ",J23,M23) -> POST /operationsAndExecution/v1/balanceProduct/retrieve | O23: API que permite consultar si un producto posee un saldo pendiente | Q23: Pending load documentation... | R23: Design | S23: ="https://github.com/SF-Bancoppel/"&B23 -> https://github.com/SF-Bancoppel/mx-api-bc-bus-operations-and-execution | V23: Manuel
A24: {=IFERROR( INDEX( 'api-register-id'!A:A, MATCH(F24, 'api-register-id'!B:B, 0) ), "Not found Organization" )} -> SSFF | B24: =IFERROR(VLOOKUP(F24, 'api-register-id'!B:F, 4, FALSE), "Not found path.") -> mx-api-bc-bus-operations-and-execution | C24: RAML | D24: BUSINESS | E24: =IFERROR(VLOOKUP(F24, 'api-register-id'!B:F, 5, FALSE), "Not found path.") -> APIMX000002 | F24: Bus Operations and Execution | G24: RESMX000023 | H24: Bus_ControlCreditCardStatusV1 | I24: =IFERROR(VLOOKUP(F24, 'api-register-id'!B:I, 8, FALSE), "Not found path.") -> 1.16.1 | J24: /operationsAndExecution | K24: v1 | L24: PUT | M24: /v1/creditCardStatus/control | N24: =CONCATENATE(L24," ",J24,M24) -> PUT /operationsAndExecution/v1/creditCardStatus/control | O24: Consulta los datos de la tarjeta de credito y actualiza el estatus a "A" desde caja. | Q24: Pending load documentation... | R24: Design | S24: ="https://github.com/SF-Bancoppel/"&B24 -> https://github.com/SF-Bancoppel/mx-api-bc-bus-operations-and-execution | V24: Manuel
A25: {=IFERROR( INDEX( 'api-register-id'!A:A, MATCH(F25, 'api-register-id'!B:B, 0) ), "Not found Organization" )} -> SSFF | B25: =IFERROR(VLOOKUP(F25, 'api-register-id'!B:F, 4, FALSE), "Not found path.") -> mx-api-bc-bus-operations-and-execution | C25: RAML | D25: BUSINESS | E25: =IFERROR(VLOOKUP(F25, 'api-register-id'!B:F, 5, FALSE), "Not found path.") -> APIMX000002 | F25: Bus Operations and Execution | G25: RESMX000024 | H25: Bus_InitiateExecutionCashAdvanceV1 | I25: =IFERROR(VLOOKUP(F25, 'api-register-id'!B:I, 8, FALSE), "Not found path.") -> 1.16.1 | J25: /operationsAndExecution | K25: v1 | L25: POST | M25: /v1/executionCashAdvance/initiate | N25: =CONCATENATE(L25," ",J25,M25) -> POST /operationsAndExecution/v1/executionCashAdvance/initiate | O25: Api de negocio que realiza cálculos de comisiones e intereses, cancelación de anualidad o devolución de anualidad. Los movimientos calculados son registrados en la base de datos de TDC. | Q25: Pending load documentation... | R25: Design | S25: ="https://github.com/SF-Bancoppel/"&B25 -> https://github.com/SF-Bancoppel/mx-api-bc-bus-operations-and-execution | V25: Martha
A26: {=IFERROR( INDEX( 'api-register-id'!A:A, MATCH(F26, 'api-register-id'!B:B, 0) ), "Not found Organization" )} -> SSFF | B26: =IFERROR(VLOOKUP(F26, 'api-register-id'!B:F, 4, FALSE), "Not found path.") -> mx-api-bc-bus-reference-data | C26: RAML | D26: BUSINESS | E26: =IFERROR(VLOOKUP(F26, 'api-register-id'!B:F, 5, FALSE), "Not found path.") -> APIMX000003 | F26: Bus Reference Data | G26: RESMX000025 | H26: Bus_RetrieveOcrDocumentV1 | I26: =IFERROR(VLOOKUP(F26, 'api-register-id'!B:I, 8, FALSE), "Not found path.") -> 1.7.0 | J26: /referenceData | K26: v1 | L26: GET | M26: /v1/ocrDocument/retrieve | N26: =CONCATENATE(L26," ",J26,M26) -> GET /referenceData/v1/ocrDocument/retrieve | O26: Servicio de experiencia que se encarga de retornar datos sobre la lectura del usuario de la declaración de identificación y dirección envuelta en el objeto ocrData. | Q26: https://coppelmx.atlassian.net/wiki/x/GgDpPQ | R26: Design | S26: ="https://github.com/SF-Bancoppel/"&B26 -> https://github.com/SF-Bancoppel/mx-api-bc-bus-reference-data
A27: {=IFERROR( INDEX( 'api-register-id'!A:A, MATCH(F27, 'api-register-id'!B:B, 0) ), "Not found Organization" )} -> SSFF | B27: =IFERROR(VLOOKUP(F27, 'api-register-id'!B:F, 4, FALSE), "Not found path.") -> mx-api-bc-bus-reference-data | C27: RAML | D27: BUSINESS | E27: =IFERROR(VLOOKUP(F27, 'api-register-id'!B:F, 5, FALSE), "Not found path.") -> APIMX000003 | F27: Bus Reference Data | G27: RESMX000026 | H27: Bus_EvaluateOnboardingPartySuitabilityV1 | I27: =IFERROR(VLOOKUP(F27, 'api-register-id'!B:I, 8, FALSE), "Not found path.") -> 1.7.0 | J27: /referenceData | K27: v1 | L27: POST | M27: /v1/onboardingPartySuitability/evaluate | N27: =CONCATENATE(L27," ",J27,M27) -> POST /referenceData/v1/onboardingPartySuitability/evaluate | O27: Servicio de negocio que se encarga de consultar al cliente en las listas negras respectivas | Q27: https://coppelmx.atlassian.net/wiki/x/GgDpPQ | R27: Design | S27: ="https://github.com/SF-Bancoppel/"&B27 -> https://github.com/SF-Bancoppel/mx-api-bc-bus-reference-data
A28: {=IFERROR( INDEX( 'api-register-id'!A:A, MATCH(F28, 'api-register-id'!B:B, 0) ), "Not found Organization" )} -> SSFF | B28: =IFERROR(VLOOKUP(F28, 'api-register-id'!B:F, 4, FALSE), "Not found path.") -> mx-api-bc-bus-reference-data | C28: RAML | D28: BUSINESS | E28: =IFERROR(VLOOKUP(F28, 'api-register-id'!B:F, 5, FALSE), "Not found path.") -> APIMX000003 | F28: Bus Reference Data | G28: RESMX000027 | H28: Bus_EvaluateReviewCustomerAccountV1 | I28: =IFERROR(VLOOKUP(F28, 'api-register-id'!B:I, 8, FALSE), "Not found path.") -> 1.7.0 | J28: /referenceData | K28: v1 | L28: POST | M28: /v1/reviewCustomerAccount/evaluate | N28: =CONCATENATE(L28," ",J28,M28) -> POST /referenceData/v1/reviewCustomerAccount/evaluate | O28: Servicio encargado de evaluar datos específicos del cliente. | Q28: Pending load documentation... | R28: Design | S28: ="https://github.com/SF-Bancoppel/"&B28 -> https://github.com/SF-Bancoppel/mx-api-bc-bus-reference-data | V28: Martha
A29: {=IFERROR( INDEX( 'api-register-id'!A:A, MATCH(F29, 'api-register-id'!B:B, 0) ), "Not found Organization" )} -> SSFF | B29: =IFERROR(VLOOKUP(F29, 'api-register-id'!B:F, 4, FALSE), "Not found path.") -> mx-api-bc-bus-reference-data | C29: RAML | D29: BUSINESS | E29: =IFERROR(VLOOKUP(F29, 'api-register-id'!B:F, 5, FALSE), "Not found path.") -> APIMX000003 | F29: Bus Reference Data | G29: RESMX000028 | H29: Bus_RegisterGeneratePartyV1 | I29: =IFERROR(VLOOKUP(F29, 'api-register-id'!B:I, 8, FALSE), "Not found path.") -> 1.7.0 | J29: /referenceData | K29: v1 | L29: POST | M29: /v1/generateParty/register | N29: =CONCATENATE(L29," ",J29,M29) -> POST /referenceData/v1/generateParty/register | O29: Operación encargada de realizar el registro de un cliente físico. | Q29: Pending load documentation... | R29: Design | S29: ="https://github.com/SF-Bancoppel/"&B29 -> https://github.com/SF-Bancoppel/mx-api-bc-bus-reference-data | V29: Martha
A30: {=IFERROR( INDEX( 'api-register-id'!A:A, MATCH(F30, 'api-register-id'!B:B, 0) ), "Not found Organization" )} -> SSFF | B30: =IFERROR(VLOOKUP(F30, 'api-register-id'!B:F, 4, FALSE), "Not found path.") -> mx-api-bc-bus-reference-data | C30: RAML | D30: BUSINESS | E30: =IFERROR(VLOOKUP(F30, 'api-register-id'!B:F, 5, FALSE), "Not found path.") -> APIMX000003 | F30: Bus Reference Data | G30: RESMX000029 | H30: Bus_RetrieveRetrievePaymentBalancesV1 | I30: =IFERROR(VLOOKUP(F30, 'api-register-id'!B:I, 8, FALSE), "Not found path.") -> 1.7.0 | J30: /referenceData | K30: v1 | L30: POST | M30: /v1/retrievePaymentBalances/retrieve | N30: =CONCATENATE(L30," ",J30,M30) -> POST /referenceData/v1/retrievePaymentBalances/retrieve | O30: Obtener los totales de pagos referenciados, pagos de WU/OV/VG para que se consultan las transacciones de abono a cuenta. | P30: The Behavior Qualifier cannot include the action term value "retrieve". Remove the Action Term of "retrievePaymentBalances". | Q30: Pending load documentation... | R30: Design | S30: ="https://github.com/SF-Bancoppel/"&B30 -> https://github.com/SF-Bancoppel/mx-api-bc-bus-reference-data | V30: Martha
A31: {=IFERROR( INDEX( 'api-register-id'!A:A, MATCH(F31, 'api-register-id'!B:B, 0) ), "Not found Organization" )} -> SSFF | B31: =IFERROR(VLOOKUP(F31, 'api-register-id'!B:F, 4, FALSE), "Not found path.") -> mx-api-bc-bus-reference-data | C31: RAML | D31: BUSINESS | E31: =IFERROR(VLOOKUP(F31, 'api-register-id'!B:F, 5, FALSE), "Not found path.") -> APIMX000003 | F31: Bus Reference Data | G31: RESMX000030 | H31: Bus_ExecuteOnboardingPartyV1 | I31: =IFERROR(VLOOKUP(F31, 'api-register-id'!B:I, 8, FALSE), "Not found path.") -> 1.7.0 | J31: /referenceData | K31: v1 | L31: PUT | M31: /v1/onboardingParty/execute | N31: =CONCATENATE(L31," ",J31,M31) -> PUT /referenceData/v1/onboardingParty/execute | O31: Servicio de negocio encargado de ejecutar el proceso de onboarding de consultar el prospecto de cliente y guardar sus información. | Q31: https://coppelmx.atlassian.net/wiki/x/NwDmPQ | R31: Design | S31: ="https://github.com/SF-Bancoppel/"&B31 -> https://github.com/SF-Bancoppel/mx-api-bc-bus-reference-data
A32: {=IFERROR( INDEX( 'api-register-id'!A:A, MATCH(F32, 'api-register-id'!B:B, 0) ), "Not found Organization" )} -> SSFF | B32: =IFERROR(VLOOKUP(F32, 'api-register-id'!B:F, 4, FALSE), "Not found path.") -> mx-api-bc-bus-reference-data | C32: RAML | D32: BUSINESS | E32: =IFERROR(VLOOKUP(F32, 'api-register-id'!B:F, 5, FALSE), "Not found path.") -> APIMX000003 | F32: Bus Reference Data | G32: RESMX000031 | H32: Bus_RetrieveCustomerV1 | I32: =IFERROR(VLOOKUP(F32, 'api-register-id'!B:I, 8, FALSE), "Not found path.") -> 1.7.0 | J32: /referenceData | K32: v1 | L32: POST | M32: /v1/customer/retrieve | N32: =CONCATENATE(L32," ",J32,M32) -> POST /referenceData/v1/customer/retrieve | O32: Realiza la consulta del cliente por diferentes parámetros. | Q32: https://coppelmx.atlassian.net/wiki/x/A4AHPg | R32: Design | S32: ="https://github.com/SF-Bancoppel/"&B32 -> https://github.com/SF-Bancoppel/mx-api-bc-bus-reference-data
A33: {=IFERROR( INDEX( 'api-register-id'!A:A, MATCH(F33, 'api-register-id'!B:B, 0) ), "Not found Organization" )} -> SSFF | B33: =IFERROR(VLOOKUP(F33, 'api-register-id'!B:F, 4, FALSE), "Not found path.") -> mx-api-bc-bus-reference-data | C33: RAML | D33: BUSINESS | E33: =IFERROR(VLOOKUP(F33, 'api-register-id'!B:F, 5, FALSE), "Not found path.") -> APIMX000003 | F33: Bus Reference Data | G33: RESMX000032 | H33: Bus_RetrieveCustomerCardV1 | I33: =IFERROR(VLOOKUP(F33, 'api-register-id'!B:I, 8, FALSE), "Not found path.") -> 1.7.0 | J33: /referenceData | K33: v1 | L33: POST | M33: /v1/customerCard/retrieve | N33: =CONCATENATE(L33," ",J33,M33) -> POST /referenceData/v1/customerCard/retrieve | O33: En este microservicio se realiza la consulta de datos (nombre(s), apellido(s), RFC y número de tarjeta) del cliente titular de una tarjeta de crédito de las tablas sd_maecred, sd_tarjeta y si_cliente. Estas consultas se realizan para consultar los datos del cliente titular. | Q33: Pending load documentation... | R33: Design | S33: ="https://github.com/SF-Bancoppel/"&B33 -> https://github.com/SF-Bancoppel/mx-api-bc-bus-reference-data | V33: Martha
A34: {=IFERROR( INDEX( 'api-register-id'!A:A, MATCH(F34, 'api-register-id'!B:B, 0) ), "Not found Organization" )} -> SSFF | B34: =IFERROR(VLOOKUP(F34, 'api-register-id'!B:F, 4, FALSE), "Not found path.") -> mx-api-bc-bus-reference-data | C34: RAML | D34: BUSINESS | E34: =IFERROR(VLOOKUP(F34, 'api-register-id'!B:F, 5, FALSE), "Not found path.") -> APIMX000003 | F34: Bus Reference Data | G34: RESMX000033 | H34: Bus_RetrieveLifeInsuranceV1 | I34: =IFERROR(VLOOKUP(F34, 'api-register-id'!B:I, 8, FALSE), "Not found path.") -> 1.7.0 | J34: /referenceData | K34: v1 | L34: POST | M34: /v1/lifeInsurance/retrieve | N34: =CONCATENATE(L34," ",J34,M34) -> POST /referenceData/v1/lifeInsurance/retrieve | O34: Este microservicio realiza la validación según el estado en que se encuentre el club de protección del cliente y valida que mensaje mostrar al usuario.. | Q34: Pending load documentation... | R34: Design | S34: ="https://github.com/SF-Bancoppel/"&B34 -> https://github.com/SF-Bancoppel/mx-api-bc-bus-reference-data | V34: Martha
A35: {=IFERROR( INDEX( 'api-register-id'!A:A, MATCH(F35, 'api-register-id'!B:B, 0) ), "Not found Organization" )} -> SSFF | B35: =IFERROR(VLOOKUP(F35, 'api-register-id'!B:F, 4, FALSE), "Not found path.") -> mx-api-bc-bus-sales-and-service | C35: RAML | D35: BUSINESS | E35: =IFERROR(VLOOKUP(F35, 'api-register-id'!B:F, 5, FALSE), "Not found path.") -> APIMX000004 | F35: Bus Sales and Service | G35: RESMX000034 | H35: Bus_InitiateOnBoardingPartyV1 | I35: =IFERROR(VLOOKUP(F35, 'api-register-id'!B:I, 8, FALSE), "Not found path.") -> 1.12.0 | J35: /salesAndService | K35: v1 | L35: POST | M35: /v1/onBoardingParty/initiate | N35: =CONCATENATE(L35," ",J35,M35) -> POST /salesAndService/v1/onBoardingParty/initiate | O35: Servicio de Negocio encargado de iniciar el proceso de onboarding. | Q35: https://coppelmx.atlassian.net/wiki/x/BoBhPQ | R35: Design | S35: ="https://github.com/SF-Bancoppel/"&B35 -> https://github.com/SF-Bancoppel/mx-api-bc-bus-sales-and-service
A36: {=IFERROR( INDEX( 'api-register-id'!A:A, MATCH(F36, 'api-register-id'!B:B, 0) ), "Not found Organization" )} -> SSFF | B36: =IFERROR(VLOOKUP(F36, 'api-register-id'!B:F, 4, FALSE), "Not found path.") -> mx-api-bc-bus-sales-and-service | C36: RAML | D36: BUSINESS | E36: =IFERROR(VLOOKUP(F36, 'api-register-id'!B:F, 5, FALSE), "Not found path.") -> APIMX000004 | F36: Bus Sales and Service | G36: RESMX000035 | H36: Bus_EvaluateOnBoardingPhonePartyV1 | I36: =IFERROR(VLOOKUP(F36, 'api-register-id'!B:I, 8, FALSE), "Not found path.") -> 1.12.0 | J36: /salesAndService | K36: v1 | L36: POST | M36: /v1/onBoardingPhoneParty/evaluate | N36: =CONCATENATE(L36," ",J36,M36) -> POST /salesAndService/v1/onBoardingPhoneParty/evaluate | O36: Servicio de experiencia encargado de agregar, consultar y validar número de teléfono. | Q36: https://coppelmx.atlassian.net/wiki/x/JgBiPQ | R36: Design | S36: ="https://github.com/SF-Bancoppel/"&B36 -> https://github.com/SF-Bancoppel/mx-api-bc-bus-sales-and-service
A37: {=IFERROR( INDEX( 'api-register-id'!A:A, MATCH(F37, 'api-register-id'!B:B, 0) ), "Not found Organization" )} -> SSFF | B37: =IFERROR(VLOOKUP(F37, 'api-register-id'!B:F, 4, FALSE), "Not found path.") -> mx-api-bc-bus-sales-and-service | C37: RAML | D37: BUSINESS | E37: =IFERROR(VLOOKUP(F37, 'api-register-id'!B:F, 5, FALSE), "Not found path.") -> APIMX000004 | F37: Bus Sales and Service | G37: RESMX000036 | H37: Bus_ExecuteGenerateBiometricManagementV1 | I37: =IFERROR(VLOOKUP(F37, 'api-register-id'!B:I, 8, FALSE), "Not found path.") -> 1.12.0 | J37: /salesAndService | K37: v1 | L37: PUT | M37: /v1/generateBiometricManagement/execute | N37: =CONCATENATE(L37," ",J37,M37) -> PUT /salesAndService/v1/generateBiometricManagement/execute | O37: Operación encargada de gestionar los datos biométricos del cliente. | Q37: https://coppelmx.atlassian.net/wiki/spaces/GAC/pages/2158821554/RESMX000036_Bus_ExecuteBiometricManagement_V1 | R37: Design | S37: ="https://github.com/SF-Bancoppel/"&B37 -> https://github.com/SF-Bancoppel/mx-api-bc-bus-sales-and-service
A38: {=IFERROR( INDEX( 'api-register-id'!A:A, MATCH(F38, 'api-register-id'!B:B, 0) ), "Not found Organization" )} -> SSFF | B38: =IFERROR(VLOOKUP(F38, 'api-register-id'!B:F, 4, FALSE), "Not found path.") -> mx-api-bc-bus-sales-and-service | C38: RAML | D38: BUSINESS | E38: =IFERROR(VLOOKUP(F38, 'api-register-id'!B:F, 5, FALSE), "Not found path.") -> APIMX000004 | F38: Bus Sales and Service | G38: RESMX000037 | H38: Bus_EvaluateCustomerContactOperationV1 | I38: =IFERROR(VLOOKUP(F38, 'api-register-id'!B:I, 8, FALSE), "Not found path.") -> 1.12.0 | J38: /salesAndService | K38: v1 | L38: POST | M38: /v1/customerContactOperation/evaluate | N38: =CONCATENATE(L38," ",J38,M38) -> POST /salesAndService/v1/customerContactOperation/evaluate | O38: API que permite verificar si el folio sms ya fue validado para un cliente | Q38: https://coppelmx.atlassian.net/wiki/spaces/GAC/pages/2159313123/RESMX000037_Bus_EvaluateCustomerContactOperation_V1 | R38: Design | S38: ="https://github.com/SF-Bancoppel/"&B38 -> https://github.com/SF-Bancoppel/mx-api-bc-bus-sales-and-service
A39: {=IFERROR( INDEX( 'api-register-id'!A:A, MATCH(F39, 'api-register-id'!B:B, 0) ), "Not found Organization" )} -> SSFF | B39: =IFERROR(VLOOKUP(F39, 'api-register-id'!B:F, 4, FALSE), "Not found path.") -> mx-api-bc-bus-sales-and-service | C39: RAML | D39: BUSINESS | E39: =IFERROR(VLOOKUP(F39, 'api-register-id'!B:F, 5, FALSE), "Not found path.") -> APIMX000004 | F39: Bus Sales and Service | G39: RESMX000038 | H39: Bus_EvaluateCustomerWorkbenchFinancialTransactionV1 | I39: =IFERROR(VLOOKUP(F39, 'api-register-id'!B:I, 8, FALSE), "Not found path.") -> 1.12.0 | J39: /salesAndService | K39: v1 | L39: POST | M39: /v1/customerWorkbenchFinancialTransaction/evaluate | N39: =CONCATENATE(L39," ",J39,M39) -> POST /salesAndService/v1/customerWorkbenchFinancialTransaction/evaluate | O39: Servicio encargado de validar si la información proporcionada por el cliente a través del IVR es correcta y si está registrada en la base de datos de Bancoppel. | Q39: https://coppelmx.atlassian.net/wiki/x/xYC4g | R39: Design | S39: ="https://github.com/SF-Bancoppel/"&B39 -> https://github.com/SF-Bancoppel/mx-api-bc-bus-sales-and-service
A40: {=IFERROR( INDEX( 'api-register-id'!A:A, MATCH(F40, 'api-register-id'!B:B, 0) ), "Not found Organization" )} -> SSFF | B40: =IFERROR(VLOOKUP(F40, 'api-register-id'!B:F, 4, FALSE), "Not found path.") -> mx-api-bc-bus-sales-and-service | C40: RAML | D40: BUSINESS | E40: =IFERROR(VLOOKUP(F40, 'api-register-id'!B:F, 5, FALSE), "Not found path.") -> APIMX000004 | F40: Bus Sales and Service | G40: RESMX000039 | H40: Bus_UpdateContactPointV1 | I40: =IFERROR(VLOOKUP(F40, 'api-register-id'!B:I, 8, FALSE), "Not found path.") -> 1.12.0 | J40: /salesAndService | K40: v1 | L40: PUT | M40: /v1/contactPoint/update | N40: =CONCATENATE(L40," ",J40,M40) -> PUT /salesAndService/v1/contactPoint/update | O40: API que permite actualizar la información de contacto del cliente, el telefono y el email | Q40: Pending load documentation... | R40: Design | S40: ="https://github.com/SF-Bancoppel/"&B40 -> https://github.com/SF-Bancoppel/mx-api-bc-bus-sales-and-service | V40: Martha
...

Sheet api-register-id
A1: Organization | B1: API Name | C1: API Operations | D1: API Type | E1: API Repository Name | F1: ID API | G1: Exchange Name | H1: Exchange Publish | I1: Exchange Publish Version | J1: MS Repository Name | K1: Deploy Type | L1: Deploy Name | M1: Deploy Name Target | N1: is Valid | O1: Longitud | P1: Deploy Publish | Q1: Deploy Version
A2: SSFF | B2: Bus Business Support | C2: =COUNTIF(develop!F2:F980,B2) -> 6 | D2: BUSINESS | E2: mx-api-bc-bus-business-support | F2: APIMX000001 | G2: =E2 -> mx-api-bc-bus-business-support | H2: =CONCATENATE("https://anypoint.mulesoft.com/exchange/834f46f4-ef08-4c50-81ae-56f917b413cc/", G2) -> https://anypoint.mulesoft.com/exchange/834f46f4-ef08-4c50-81ae-56f917b413cc/mx-api-bc-bus-business-support | I2: 1.3.0 | J2: =obtenerRepoMS(E2) -> mx-ms-bc-bus-business-support-mule | K2: MuleSoft | L2: =IFERROR(__xludf.DUMMYFUNCTION("REGEXREPLACE(REGEXREPLACE(REGEXREPLACE(J2, ""mx-ms-bc-"", """"), ""-mule"", ""-api-dev""), ""-apigee"", ""-api-dev"")"),"bus-business-support-api-dev") -> bus-business-support-api-dev | M2: =generarNombreDeploy(J2) -> bus-business-support-api-dev | N2: =validateAPIName(M2,D2) -> Valid | O2: =LEN(M2) -> 28
A3: SSFF | B3: Bus Operations and Execution | C3: =COUNTIF(develop!F3:F980,B3) -> 32 | D3: BUSINESS | E3: mx-api-bc-bus-operations-and-execution | F3: APIMX000002 | G3: =E3 -> mx-api-bc-bus-operations-and-execution | H3: =CONCATENATE("https://anypoint.mulesoft.com/exchange/834f46f4-ef08-4c50-81ae-56f917b413cc/", G3) -> https://anypoint.mulesoft.com/exchange/834f46f4-ef08-4c50-81ae-56f917b413cc/mx-api-bc-bus-operations-and-execution | I3: 1.16.1 | J3: =obtenerRepoMS(E3) -> mx-ms-bc-bus-operations-and-execution-mule | K3: MuleSoft | L3: =IFERROR(__xludf.DUMMYFUNCTION("REGEXREPLACE(REGEXREPLACE(REGEXREPLACE(J3, ""mx-ms-bc-"", """"), ""-mule"", ""-api-dev""), ""-apigee"", ""-api-dev"")"),"bus-operations-and-execution-api-dev") -> bus-operations-and-execution-api-dev | M3: =generarNombreDeploy(J3) -> bus-operations-and-execution-api-dev | N3: =validateAPIName(M3,D3) -> Valid | O3: =LEN(M3) -> 36
A4: SSFF | B4: Bus Reference Data | C4: =COUNTIF(develop!F4:F980,B4) -> 14 | D4: BUSINESS | E4: mx-api-bc-bus-reference-data | F4: APIMX000003 | G4: =E4 -> mx-api-bc-bus-reference-data | H4: =CONCATENATE("https://anypoint.mulesoft.com/exchange/834f46f4-ef08-4c50-81ae-56f917b413cc/", G4) -> https://anypoint.mulesoft.com/exchange/834f46f4-ef08-4c50-81ae-56f917b413cc/mx-api-bc-bus-reference-data | I4: 1.7.0 | J4: =obtenerRepoMS(E4) -> mx-ms-bc-bus-reference-data-mule | K4: MuleSoft | L4: bus-reference-data-api-dev | M4: =generarNombreDeploy(J4) -> bus-reference-data-api-dev | N4: =validateAPIName(M4,D4) -> Valid | O4: =LEN(M4) -> 26
A5: SSFF | B5: Bus Sales and Service | C5: =COUNTIF(develop!F5:F980,B5) -> 27 | D5: BUSINESS | E5: mx-api-bc-bus-sales-and-service | F5: APIMX000004 | G5: =E5 -> mx-api-bc-bus-sales-and-service | H5: =CONCATENATE("https://anypoint.mulesoft.com/exchange/834f46f4-ef08-4c50-81ae-56f917b413cc/", G5) -> https://anypoint.mulesoft.com/exchange/834f46f4-ef08-4c50-81ae-56f917b413cc/mx-api-bc-bus-sales-and-service | I5: 1.12.0 | J5: =obtenerRepoMS(E5) -> mx-ms-bc-bus-sales-and-service-mule | K5: MuleSoft | L5: bus-sales-and-service-api-dev | M5: =generarNombreDeploy(J5) -> bus-sales-and-service-api-dev | N5: =validateAPIName(M5,D5) -> Valid | O5: =LEN(M5) -> 29
A6: SSFF | B6: Dom Account Reconciliation | C6: =COUNTIF(develop!F6:F980,B6) -> 1 | D6: DOMAIN | E6: mx-api-bc-dom-account-reconciliation | F6: APIMX000005 | G6: =E6 -> mx-api-bc-dom-account-reconciliation | H6: =CONCATENATE("https://anypoint.mulesoft.com/exchange/834f46f4-ef08-4c50-81ae-56f917b413cc/", G6) -> https://anypoint.mulesoft.com/exchange/834f46f4-ef08-4c50-81ae-56f917b413cc/mx-api-bc-dom-account-reconciliation | I6: 1.1.0 | J6: =obtenerRepoMS(E6) -> mx-ms-bc-dom-account-reconciliation-mule | K6: MuleSoft | L6: =IFERROR(__xludf.DUMMYFUNCTION("REGEXREPLACE(REGEXREPLACE(REGEXREPLACE(J6, ""mx-ms-bc-"", """"), ""-mule"", ""-api-dev""), ""-apigee"", ""-api-dev"")"),"dom-account-reconciliation-api-dev") -> dom-account-reconciliation-api-dev | M6: =generarNombreDeploy(J6) -> dom-account-reconciliation-api-dev | N6: =validateAPIName(M6,D6) -> Valid | O6: =LEN(M6) -> 34
A7: SSFF | B7: Dom Branch Location Operations | C7: =COUNTIF(develop!F7:F980,B7) -> 2 | D7: DOMAIN | E7: mx-api-bc-dom-branch-location-operations | F7: APIMX000006 | G7: =E7 -> mx-api-bc-dom-branch-location-operations | H7: =CONCATENATE("https://anypoint.mulesoft.com/exchange/834f46f4-ef08-4c50-81ae-56f917b413cc/", G7) -> https://anypoint.mulesoft.com/exchange/834f46f4-ef08-4c50-81ae-56f917b413cc/mx-api-bc-dom-branch-location-operations | I7: 1.2.0 | J7: =obtenerRepoMS(E7) -> mx-ms-bc-dom-branch-location-operations-mule | K7: MuleSoft | L7: =IFERROR(__xludf.DUMMYFUNCTION("REGEXREPLACE(REGEXREPLACE(REGEXREPLACE(J7, ""mx-ms-bc-"", """"), ""-mule"", ""-api-dev""), ""-apigee"", ""-api-dev"")"),"dom-branch-location-operations-api-dev") -> dom-branch-location-operations-api-dev | M7: =generarNombreDeploy(J7) -> dom-branch-location-operations-api-dev | N7: =validateAPIName(M7,D7) -> Valid | O7: =LEN(M7) -> 38
A8: SSFF | B8: Dom Branch Network Management | C8: =COUNTIF(develop!F8:F980,B8) -> 1 | D8: DOMAIN | E8: mx-api-bc-dom-branch-network-management | F8: APIMX000007 | G8: =E8 -> mx-api-bc-dom-branch-network-management | H8: =CONCATENATE("https://anypoint.mulesoft.com/exchange/834f46f4-ef08-4c50-81ae-56f917b413cc/", G8) -> https://anypoint.mulesoft.com/exchange/834f46f4-ef08-4c50-81ae-56f917b413cc/mx-api-bc-dom-branch-network-management | I8: 1.1.0 | J8: =obtenerRepoMS(E8) -> mx-ms-bc-dom-branch-network-management-mule | K8: MuleSoft | L8: dom-branch-network-management-api-dev | M8: =generarNombreDeploy(J8) -> dom-branch-network-management-api-dev | N8: =validateAPIName(M8,D8) -> Valid | O8: =LEN(M8) -> 37
A9: SSFF | B9: Dom Card eCommerce Gateway | C9: =COUNTIF(develop!F9:F980,B9) -> 1 | D9: DOMAIN | E9: mx-api-bc-dom-card-ecommerce-gateway | F9: APIMX000008 | G9: =E9 -> mx-api-bc-dom-card-ecommerce-gateway | H9: =CONCATENATE("https://anypoint.mulesoft.com/exchange/834f46f4-ef08-4c50-81ae-56f917b413cc/", G9) -> https://anypoint.mulesoft.com/exchange/834f46f4-ef08-4c50-81ae-56f917b413cc/mx-api-bc-dom-card-ecommerce-gateway | I9: 1.0.0 | J9: =obtenerRepoMS(E9) -> mx-ms-bc-dom-card-ecommerce-gateway-mule | K9: MuleSoft | L9: =IFERROR(__xludf.DUMMYFUNCTION("REGEXREPLACE(REGEXREPLACE(REGEXREPLACE(J9, ""mx-ms-bc-"", """"), ""-mule"", ""-api-dev""), ""-apigee"", ""-api-dev"")"),"dom-card-ecommerce-gateway-api-dev") -> dom-card-ecommerce-gateway-api-dev | M9: =generarNombreDeploy(J9) -> dom-card-ecommerce-gateway-api-dev | N9: =validateAPIName(M9,D9) -> Valid | O9: =LEN(M9) -> 34
A10: SSFF | B10: Dom Corporate Current Account | C10: =COUNTIF(develop!F10:F980,B10) -> 1 | D10: DOMAIN | E10: mx-api-bc-dom-corporate-current-account | F10: APIMX000009 | G10: =E10 -> mx-api-bc-dom-corporate-current-account | H10: =CONCATENATE("https://anypoint.mulesoft.com/exchange/834f46f4-ef08-4c50-81ae-56f917b413cc/", G10) -> https://anypoint.mulesoft.com/exchange/834f46f4-ef08-4c50-81ae-56f917b413cc/mx-api-bc-dom-corporate-current-account | I10: 1.1.0 | J10: =obtenerRepoMS(E10) -> mx-ms-bc-dom-corporate-current-account-mule | K10: MuleSoft | L10: dom-corporate-current-account-api-dev | M10: =generarNombreDeploy(J10) -> dom-corporate-current-account-api-dev | N10: =validateAPIName(M10,D10) -> Valid | O10: =LEN(M10) -> 37
A11: SSFF | B11: Dom Correspondence | C11: =COUNTIF(develop!F11:F980,B11) -> 1 | D11: DOMAIN | E11: mx-api-bc-dom-correspondence | F11: APIMX000010 | G11: =E11 -> mx-api-bc-dom-correspondence | H11: =CONCATENATE("https://anypoint.mulesoft.com/exchange/834f46f4-ef08-4c50-81ae-56f917b413cc/", G11) -> https://anypoint.mulesoft.com/exchange/834f46f4-ef08-4c50-81ae-56f917b413cc/mx-api-bc-dom-correspondence | I11: 1.0.0 | J11: =obtenerRepoMS(E11) -> mx-ms-bc-dom-correspondence-mule | K11: MuleSoft | L11: =IFERROR(__xludf.DUMMYFUNCTION("REGEXREPLACE(REGEXREPLACE(REGEXREPLACE(J11, ""mx-ms-bc-"", """"), ""-mule"", ""-api-dev""), ""-apigee"", ""-api-dev"")"),"dom-correspondence-api-dev") -> dom-correspondence-api-dev | M11: =generarNombreDeploy(J11) -> dom-correspondence-api-dev | N11: =validateAPIName(M11,D11) -> Valid | O11: =LEN(M11) -> 26
A12: SSFF | B12: Dom Counterparty Risk | C12: =COUNTIF(develop!F12:F980,B12) -> 15 | D12: DOMAIN | E12: mx-api-bc-dom-counterparty-risk | F12: APIMX000011 | G12: =E12 -> mx-api-bc-dom-counterparty-risk | H12: =CONCATENATE("https://anypoint.mulesoft.com/exchange/834f46f4-ef08-4c50-81ae-56f917b413cc/", G12) -> https://anypoint.mulesoft.com/exchange/834f46f4-ef08-4c50-81ae-56f917b413cc/mx-api-bc-dom-counterparty-risk | I12: 1.2.0 | J12: =obtenerRepoMS(E12) -> mx-ms-bc-dom-counterparty-risk-mule | K12: MuleSoft | L12: =IFERROR(__xludf.DUMMYFUNCTION("REGEXREPLACE(REGEXREPLACE(REGEXREPLACE(J12, ""mx-ms-bc-"", """"), ""-mule"", ""-api-dev""), ""-apigee"", ""-api-dev"")"),"dom-counterparty-risk-api-dev") -> dom-counterparty-risk-api-dev | M12: =generarNombreDeploy(J12) -> dom-counterparty-risk-api-dev | N12: =validateAPIName(M12,D12) -> Valid | O12: =LEN(M12) -> 29
A13: SSFF | B13: Dom Credit Card | C13: =COUNTIF(develop!F13:F980,B13) -> 55 | D13: DOMAIN | E13: mx-api-bc-dom-credit-card | F13: APIMX000012 | G13: =E13 -> mx-api-bc-dom-credit-card | H13: =CONCATENATE("https://anypoint.mulesoft.com/exchange/834f46f4-ef08-4c50-81ae-56f917b413cc/", G13) -> https://anypoint.mulesoft.com/exchange/834f46f4-ef08-4c50-81ae-56f917b413cc/mx-api-bc-dom-credit-card | I13: 1.31.0 | J13: mx-ms-bc-dom-credit-card-mule | K13: MuleSoft | L13: dom-credit-card-api-dev | M13: =generarNombreDeploy(J13) -> dom-credit-card-api-dev | N13: =validateAPIName(M13,D13) -> Valid | O13: =LEN(M13) -> 23
A14: SSFF | B14: Dom Credit Card Position Keeping | C14: =COUNTIF(develop!F14:F980,B14) -> 5 | D14: DOMAIN | E14: mx-api-bc-dom-credit-card-position-keeping | F14: APIMX000013 | G14: =E14 -> mx-api-bc-dom-credit-card-position-keeping | H14: =CONCATENATE("https://anypoint.mulesoft.com/exchange/834f46f4-ef08-4c50-81ae-56f917b413cc/", G14) -> https://anypoint.mulesoft.com/exchange/834f46f4-ef08-4c50-81ae-56f917b413cc/mx-api-bc-dom-credit-card-position-keeping | I14: 1.4.3 | J14: =obtenerRepoMS(E14) -> mx-ms-bc-dom-credit-card-position-keeping-mule | K14: MuleSoft | L14: dom-credit-card-position-keeping-api-dev | M14: =generarNombreDeploy(J14) -> dom-credit-card-position-keeping-api-dev | N14: =validateAPIName(M14,D14) -> Valid | O14: =LEN(M14) -> 40
A15: SSFF | B15: Dom Credit Facility | C15: =COUNTIF(develop!F15:F980,B15) -> 2 | D15: DOMAIN | E15: mx-api-bc-dom-credit-facility | F15: APIMX000014 | G15: =E15 -> mx-api-bc-dom-credit-facility | H15: =CONCATENATE("https://anypoint.mulesoft.com/exchange/834f46f4-ef08-4c50-81ae-56f917b413cc/", G15) -> https://anypoint.mulesoft.com/exchange/834f46f4-ef08-4c50-81ae-56f917b413cc/mx-api-bc-dom-credit-facility | I15: 1.2.1 | J15: =obtenerRepoMS(E15) -> mx-ms-bc-dom-credit-facility-mule | K15: MuleSoft | L15: =IFERROR(__xludf.DUMMYFUNCTION("REGEXREPLACE(REGEXREPLACE(REGEXREPLACE(J15, ""mx-ms-bc-"", """"), ""-mule"", ""-api-dev""), ""-apigee"", ""-api-dev"")"),"dom-credit-facility-api-dev") -> dom-credit-facility-api-dev | M15: =generarNombreDeploy(J15) -> dom-credit-facility-api-dev | N15: =validateAPIName(M15,D15) -> Valid | O15: =LEN(M15) -> 27
A16: SSFF | B16: Dom Currency Exchange | C16: =COUNTIF(develop!F16:F980,B16) -> 1 | D16: DOMAIN | E16: mx-api-bc-dom-currency-exchange | F16: APIMX000015 | G16: =E16 -> mx-api-bc-dom-currency-exchange | H16: =CONCATENATE("https://anypoint.mulesoft.com/exchange/834f46f4-ef08-4c50-81ae-56f917b413cc/", G16) -> https://anypoint.mulesoft.com/exchange/834f46f4-ef08-4c50-81ae-56f917b413cc/mx-api-bc-dom-currency-exchange | I16: 1.0.0 | J16: =obtenerRepoMS(E16) -> mx-ms-bc-dom-currency-exchange-mule | K16: MuleSoft | L16: =IFERROR(__xludf.DUMMYFUNCTION("REGEXREPLACE(REGEXREPLACE(REGEXREPLACE(J16, ""mx-ms-bc-"", """"), ""-mule"", ""-api-dev""), ""-apigee"", ""-api-dev"")"),"dom-currency-exchange-api-dev") -> dom-currency-exchange-api-dev | M16: =generarNombreDeploy(J16) -> dom-currency-exchange-api-dev | N16: =validateAPIName(M16,D16) -> Valid | O16: =LEN(M16) -> 29
A17: SSFF | B17: Dom Current Account | C17: =COUNTIF(develop!F17:F980,B17) -> 1 | D17: DOMAIN | E17: mx-api-bc-dom-current-account | F17: APIMX000016 | G17: =E17 -> mx-api-bc-dom-current-account | H17: =CONCATENATE("https://anypoint.mulesoft.com/exchange/834f46f4-ef08-4c50-81ae-56f917b413cc/", G17) -> https://anypoint.mulesoft.com/exchange/834f46f4-ef08-4c50-81ae-56f917b413cc/mx-api-bc-dom-current-account | I17: 1.0.0 | J17: =obtenerRepoMS(E17) -> mx-ms-bc-dom-current-account-mule | K17: MuleSoft | L17: =IFERROR(__xludf.DUMMYFUNCTION("REGEXREPLACE(REGEXREPLACE(REGEXREPLACE(J17, ""mx-ms-bc-"", """"), ""-mule"", ""-api-dev""), ""-apigee"", ""-api-dev"")"),"dom-current-account-api-dev") -> dom-current-account-api-dev | M17: =generarNombreDeploy(J17) -> dom-current-account-api-dev | N17: =validateAPIName(M17,D17) -> Valid | O17: =LEN(M17) -> 27
A18: SSFF | B18: Dom Customer Access Entitlement | C18: =COUNTIF(develop!F18:F980,B18) -> 2 | D18: DOMAIN | E18: mx-api-bc-dom-customer-access-entitlement | F18: APIMX000017 | G18: =E18 -> mx-api-bc-dom-customer-access-entitlement | H18: =CONCATENATE("https://anypoint.mulesoft.com/exchange/834f46f4-ef08-4c50-81ae-56f917b413cc/", G18) -> https://anypoint.mulesoft.com/exchange/834f46f4-ef08-4c50-81ae-56f917b413cc/mx-api-bc-dom-customer-access-entitlement | I18: 1.1.1 | J18: =obtenerRepoMS(E18) -> mx-ms-bc-dom-customer-access-entitlement-mule | K18: MuleSoft | L18: =IFERROR(__xludf.DUMMYFUNCTION("REGEXREPLACE(REGEXREPLACE(REGEXREPLACE(J18, ""mx-ms-bc-"", """"), ""-mule"", ""-api-dev""), ""-apigee"", ""-api-dev"")"),"dom-customer-access-entitlement-api-dev") -> dom-customer-access-entitlement-api-dev | M18: =generarNombreDeploy(J18) -> dom-customer-access-entitlement-api-dev | N18: =validateAPIName(M18,D18) -> Valid | O18: =LEN(M18) -> 39
A19: SSFF | B19: Dom Customer Agreement | C19: =COUNTIF(develop!F19:F980,B19) -> 6 | D19: DOMAIN | E19: mx-api-bc-dom-customer-agreement | F19: APIMX000018 | G19: =E19 -> mx-api-bc-dom-customer-agreement | H19: =CONCATENATE("https://anypoint.mulesoft.com/exchange/834f46f4-ef08-4c50-81ae-56f917b413cc/", G19) -> https://anypoint.mulesoft.com/exchange/834f46f4-ef08-4c50-81ae-56f917b413cc/mx-api-bc-dom-customer-agreement | I19: 1.3.0 | J19: =obtenerRepoMS(E19) -> mx-ms-bc-dom-customer-agreement-mule | K19: MuleSoft | L19: dom-customer-agreement-api-dev | M19: =generarNombreDeploy(J19) -> dom-customer-agreement-api-dev | N19: =validateAPIName(M19,D19) -> Valid | O19: =LEN(M19) -> 30
A20: SSFF | B20: Dom Customer Credit Rating | C20: =COUNTIF(develop!F20:F980,B20) -> 17 | D20: DOMAIN | E20: mx-api-bc-dom-customer-credit-rating | F20: APIMX000019 | G20: =E20 -> mx-api-bc-dom-customer-credit-rating | H20: =CONCATENATE("https://anypoint.mulesoft.com/exchange/834f46f4-ef08-4c50-81ae-56f917b413cc/", G20) -> https://anypoint.mulesoft.com/exchange/834f46f4-ef08-4c50-81ae-56f917b413cc/mx-api-bc-dom-customer-credit-rating | I20: 1.5.1 | J20: =obtenerRepoMS(E20) -> mx-ms-bc-dom-customer-credit-rating-mule | K20: MuleSoft | L20: =IFERROR(__xludf.DUMMYFUNCTION("REGEXREPLACE(REGEXREPLACE(REGEXREPLACE(J20, ""mx-ms-bc-"", """"), ""-mule"", ""-api-dev""), ""-apigee"", ""-api-dev"")"),"dom-customer-credit-rating-api-dev") -> dom-customer-credit-rating-api-dev | M20: =generarNombreDeploy(J20) -> dom-customer-credit-rating-api-dev | N20: =validateAPIName(M20,D20) -> Valid | O20: =LEN(M20) -> 34
