Workbook

Sheet PH Vertical Expansion
A4: Nivel | B4: Secuencia | C4: =SUBSTITUTE(TRANSLATE(SUBSTITUTE('__TR_VERTICAL'!C1,"PID","XQZ0QX"),"en","es"),"XQZ0QX","PID") | D4: Nombre | E4: Descripción | F4: Propietario del proceso | G4: Nivel de interoperabilidad | H4: Núcleo o dominio | I4: Propósito en la arquitectura interoperable | J4: Estrategia de Abastecimiento (Indicativo) | K4: Soluciones BanCoppel utilizadas (proyecto)
A5: 1 | B5: 1 | C5: 5 | D5: Gestión API | E5: La capacidad de diseñar, publicar, asegurar, versionar, medir y retirar los contratos de servicios síncronos del banco, junto con el conjunto de viviendas orientadas al promotor que los rodea (catálogo, portal, sandbox). Cubre tanto el plano de ejecución (mediación de pasarela, enrutamiento, política de tráfico) como el plano de control (ciclo de vida, administración de políticas, análisis). | F5: Jefe de API y Arquitectura de Integración | G5: L0 | H5: Núcleo y Plataforma | I5: Instrumento principal de desacoplamiento de la arquitectura interoperable. Un contrato estable basado en estándares (alineado con BIAN o personalizado canónico) permite que un canal se re-platforme sin tocar un núcleo, y que un núcleo sea reemplazado sin tocar un canal. También es el punto de control semántico donde una petición deja de ser una llamada a un sistema específico y pasa a llamar a una capacidad bancaria. | J5: Plataforma de terceros + políticas personalizadas | K5: Apigee API Management/Gateway; MuleSoft; WebMethods; BIAN alineado APIs; Transact OFS/IRIS REST APIs; Modyo Connect/Amazon API Gateway para flujos Apolo.
A6: 2 | B6: 1 | C6: 5.1 | D6: Pasarela API y Mediación en tiempo de ejecución | E6: Plano de ejecución que termina, valida, media y enruta el tráfico API entre consumidores y proveedores, aplicando la política en el punto de invocación en lugar de dentro del código de la aplicación. | F6: Jefe de API y Arquitectura de Integración | G6: L1 | H6: Núcleo y Plataforma | I6: Hace cumplir el contrato en tiempo de ejecución, así que el desacoplamiento está garantizado por la plataforma en lugar de por la disciplina del desarrollador. | J6: Terceros | K6: Apigee API Gateway/API Management; integración/orquestación MuleSoft; WebMethods BPM/BRM; BIAN alineado APIs; Transact OFS/IRIS REST APIs.
A7: 3 | B7: 1 | C7: 5.1.1 | D7: Enrutamiento | E7: Resolución de un contrato lógico API a uno o más puntos finales físicos de servicio, incluyendo enrutamiento basado en host, versión y entorno. | F7: Jefe de API y Arquitectura de Integración | G7: L2 | H7: Núcleo y Plataforma | I7: Permite la reubicación del backend, la re-plataforma y el doble funcionamiento de procesadores antiguos y nuevos sin ningún cambio de consumidor. | J7: Terceros | K7: Apigee API Gateway/API Management; integración/orquestación MuleSoft; WebMethods BPM/BRM; BIAN alineado APIs; Transact OFS/IRIS REST APIs.
A8: 3 | B8: 2 | C8: 5.1.2 | D8: Mediación y transformación del mensaje | E8: Adaptación de protocolos y cargas útiles en el edge (REST, SOAP, gRPC, protocolos heredados), incluyendo manipulación de cabeceras y mapeo canónico-nativo. | F8: Jefe de API y Arquitectura de Integración | G8: L2 | H8: Núcleo y Plataforma | I8: Absorbe la heterogeneidad técnica de un conjunto híbrido de núcleo, de modo que los consumidores solo ven un estilo de interfaz. | J8: Terceros | K8: Apigee API Gateway/API Management; integración/orquestación MuleSoft; WebMethods BPM/BRM; BIAN alineado APIs; Transact OFS/IRIS REST APIs.
A9: 3 | B9: 3 | C9: 5.1.3 | D9: API Gestión de Tráfico | E9: Cuotas, límite de tarifa, limitación, arresto de picos y políticas de calidad de servicio aplicadas por consumidor, por API y por nivel. | F9: Jefe de API y Arquitectura de Integración | G9: L2 | H9: Núcleo y Plataforma | I9: Protege la capacidad finita heredada (MIPS, pools de conexión) frente a una demanda digital ilimitada y convierte la capacidad en un recurso gobernado y con precio. | J9: Terceros | K9: Apigee API Gateway/API Management; integración/orquestación MuleSoft; WebMethods BPM/BRM; BIAN alineado APIs; Transact OFS/IRIS REST APIs.
A10: 3 | B10: 4 | C10: 5.1.4 | D10: Validación de mensajes y protección de carga útil | E10: Validación de esquema, tamaño y contenido de mensajes entrantes y salientes, incluyendo protección contra ataques basados en contenido. | F10: Jefe de API y Arquitectura de Integración | G10: L2 | H10: Núcleo y Plataforma | I10: Detiene el tráfico malformado y hostil antes de que llegue al parque de procesamiento, donde la remediación es mucho más cara. | J10: Terceros | K10: Apigee API Gateway/API Management; integración/orquestación MuleSoft; WebMethods BPM/BRM; BIAN alineado APIs; Transact OFS/IRIS REST APIs.
A11: 3 | B11: 5 | C11: 5.1.5 | D11: Gestión de errores y normalización de fallos | E11: Taxonomía de errores estandarizada, mapeo de fallos y códigos de respuesta a través de backends heterogéneos. | F11: Jefe de API y Arquitectura de Integración | G11: L2 | H11: Núcleo y Plataforma | I11: Evita que la semántica de error específica del backend se filtre en los canales, que es una de las fuentes más comunes de acoplamiento oculto. | J11: Terceros | K11: Apigee API Gateway/API Management; integración/orquestación MuleSoft; WebMethods BPM/BRM; BIAN alineado APIs; Transact OFS/IRIS REST APIs.
A12: 2 | B12: 2 | C12: 5.2 | D12: Gestión del ciclo de vida API | E12: Plano de control que gobierna un API desde el diseño y la definición del contrato hasta la publicación, el cambio de versiones, la notificación de cambios y su eventual retirada. | F12: Jefe de API y Arquitectura de Integración | G12: L1 | H12: Núcleo y Plataforma | I12: Convierte las interfaces en activos empresariales gestionados con una ruta de cambio controlada, que es la condición previa para su reutilización entre entidades y países. | J12: Proceso de terceros + gobernanza | K12: Estándares BIAN API; Apigee API ciclo de vida/gobernanza; documentación al estilo OpenAPI/Swagger API para OfiWeb/Canales; El cambio API está controlado por la gobernanza de la arquitectura.
A13: 3 | B13: 1 | C13: 5.2.1 | D13: Normas de diseño y contratos API | E13: Definición y aplicación de estándares de interfaz, nombres canónicos o alineados con BIAN, y puertas de revisión de diseño antes de la publicación. | F13: Jefe de API y Arquitectura de Integración | G13: L2 | H13: Núcleo y Plataforma | I13: Garantiza que las nuevas interfaces aumenten la reutilización en lugar de añadir otra integración personalizada para mantener. | J13: Proceso de terceros + gobernanza | K13: Estándares BIAN API; Apigee API ciclo de vida/gobernanza; documentación al estilo OpenAPI/Swagger API para OfiWeb/Canales; El cambio API está controlado por la gobernanza de la arquitectura.
A14: 3 | B14: 2 | C14: 5.2.2 | D14: Versionado API | E14: Soporte simultáneo de múltiples versiones de contrato con reglas definidas de compatibilidad y deprecación. | F14: Jefe de API y Arquitectura de Integración | G14: L2 | H14: Núcleo y Plataforma | I14: Desacopla los ciclos de lanzamiento entre consumidores y proveedores, de modo que ningún cambio individual requiera un despliegue sincronizado de big bang. | J14: Proceso de terceros + gobernanza | K14: Estándares BIAN API; Apigee API ciclo de vida/gobernanza; documentación al estilo OpenAPI/Swagger API para OfiWeb/Canales; El cambio API está controlado por la gobernanza de la arquitectura.
A15: 3 | B15: 3 | C15: 5.2.3 | D15: Notificación de publicación y cambio API | E15: Promoción de APIs en entornos y notificación proactiva de cambios de contrato a los consumidores registrados. | F15: Jefe de API y Arquitectura de Integración | G15: L2 | H15: Núcleo y Plataforma | I15: Elimina la sobrecarga de coordinación que de otro modo hace que los equipos eviten reutilizar una interfaz compartida. | J15: Proceso de terceros + gobernanza | K15: Estándares BIAN API; Apigee API ciclo de vida/gobernanza; documentación al estilo OpenAPI/Swagger API para OfiWeb/Canales; El cambio API está controlado por la gobernanza de la arquitectura.
A16: 3 | B16: 4 | C16: 5.2.4 | D16: API Depreciación y Retiro | E16: Un control de la desaparición de interfaces, incluyendo el seguimiento de migración del consumidor y la aplicación de fechas de fin de vida. | F16: Jefe de API y Arquitectura de Integración | G16: L2 | H16: Núcleo y Plataforma | I16: Evita que la capa de interoperabilidad acumule la misma deuda de interfaz que fue creada para eliminar. | J16: Proceso de terceros + gobernanza | K16: Estándares BIAN API; Apigee API ciclo de vida/gobernanza; documentación al estilo OpenAPI/Swagger API para OfiWeb/Canales; El cambio API está controlado por la gobernanza de la arquitectura.
A17: 2 | B17: 3 | C17: 5.3 | D17: API Manager (Administración de Plataforma) | E17: Administración, configuración de políticas, operación e instrumentación comercial de la propia plataforma de gestión API, tanto en topologías locales, en la nube como en la nube o híbridas. | F17: Jefe de API y Arquitectura de Integración | G17: L1 | H17: Núcleo y Plataforma | I17: Mantiene la política administrada de forma centralizada y aplicada de forma consistente, para que las normas de seguridad y tráfico no se fragmenten por equipo API. | J17: Terceros | K17: Administración y políticas de la plataforma Apigee; Monitorización DataDog/API; tuberías DevSecOps; GCP alojado en Apigee con proveedores AWS/locales.
A18: 3 | B18: 1 | C18: 5.3.1 | D18: Administración y Seguimiento de Políticas | E18: Definición central, asignación y auditoría de políticas de pasarela (seguridad, tráfico, mediación, caché) a lo largo del patrimonio API. | F18: Jefe de API y Arquitectura de Integración | G18: L2 | H18: Núcleo y Plataforma | I18: Convierte la política en un elemento de configuración gobernado en lugar de código embebido, permitiendo cambios a nivel de estado en una sola acción. | J18: Terceros | K18: Administración y políticas de la plataforma Apigee; Monitorización DataDog/API; tuberías DevSecOps; GCP alojado en Apigee con proveedores AWS/locales.
A19: 3 | B19: 2 | C19: 5.3.2 | D19: API Monitorización, Analítica y Monetización | E19: Métricas de consumo, latencia y análisis de errores por API y por consumidor, con base de medición para devolución interna o monetización de socios. | F19: Jefe de API y Arquitectura de Integración | G19: L2 | H19: Núcleo y Plataforma | I19: Proporciona la base de evidencia para las afirmaciones de reutilización, la planificación de capacidades y los modelos comerciales de ecosistemas. | J19: Terceros | K19: Administración y políticas de la plataforma Apigee; Monitorización DataDog/API; tuberías DevSecOps; GCP alojado en Apigee con proveedores AWS/locales.
A20: 3 | B20: 3 | C20: 5.3.3 | D20: Despliegue y operaciones de la plataforma | E20: Topología de despliegue, automatización, actualización y soporte operativo de la plataforma de gestión API. | F20: Jefe de API y Arquitectura de Integración | G20: L2 | H20: Núcleo y Plataforma | I20: Garantiza que la capa de desacoplamiento sea en sí misma resiliente y actualizable, ya que se convierte en un punto único de dependencia para todo el tráfico. | J20: Terceros | K20: Administración y políticas de la plataforma Apigee; Monitorización DataDog/API; tuberías DevSecOps; GCP alojado en Apigee con proveedores AWS/locales.
A21: 2 | B21: 4 | C21: 5.4 | D21: Portal y catálogo para desarrolladores | E21: Superficie de autoservicio donde desarrolladores internos y externos descubren, evalúan, se registran y se apoyan en interfaces publicadas. | F21: Jefe de API y Arquitectura de Integración | G21: L1 | H21: Núcleo y Plataforma | I21: La reutilización solo ocurre si se pueden encontrar capacidades. El portal convierte un inventario técnico en un catálogo de productos consumibles. | J21: Terceros | K21: Catálogo/gobernanza API para Apificación de Canales y OfiWeb; Apigee como plano de gestión API. No se evidencia explícitamente ninguna herramienta de portal para desarrolladores independiente.
A22: 3 | B22: 1 | C22: 5.4.1 | D22: Catálogo, documentación y descubrimiento de metadatos API | E22: Inventario consultable de interfaces publicadas con especificaciones, ejemplos y metadatos. | F22: Jefe de API y Arquitectura de Integración | G22: L2 | H22: Núcleo y Plataforma | I22: Elimina el coste de redescubrimiento que impulsa a los equipos a construir una integración paralela punto a punto. | J22: Terceros | K22: Catálogo/gobernanza API para Apificación de Canales y OfiWeb; Apigee como plano de gestión API. No se evidencia explícitamente ninguna herramienta de portal para desarrolladores independiente.
A23: 3 | B23: 2 | C23: 5.4.2 | D23: Registro de desarrolladores y autoservicio | E23: Incorporación, emisión de credenciales, registro de solicitudes y gestión de derechos para consumidores de API. | F23: Jefe de API y Arquitectura de Integración | G23: L2 | H23: Núcleo y Plataforma | I23: Elimina el control humano del camino de consumo, que es lo que hace que la reutilización interna y la incorporación de parejas sea rápida. | J23: Terceros | K23: Catálogo/gobernanza API para Apificación de Canales y OfiWeb; Apigee como plano de gestión API. No se evidencia explícitamente ninguna herramienta de portal para desarrolladores independiente.
A24: 3 | B24: 3 | C24: 5.4.3 | D24: Colaboración, comunidad y autoapoyo | E24: Informes de problemas, bucles de retroalimentación, guía de uso, SDKs y ejemplos de referencia para equipos que consumen. | F24: Jefe de API y Arquitectura de Integración | G24: L2 | H24: Núcleo y Plataforma | I24: Proporciona la capa de habilitación sin la cual una capacidad publicada está técnicamente disponible pero prácticamente no se utiliza. | J24: Terceros | K24: Catálogo/gobernanza API para Apificación de Canales y OfiWeb; Apigee como plano de gestión API. No se evidencia explícitamente ninguna herramienta de portal para desarrolladores independiente.
A25: 1 | B25: 2 | C25: 4 | D25: Servicios de Gateway | E25: Controlado la entrada y salida a través del límite de confianza del banco en tres modalidades - API, archivo y evento - tanto en direcciones entrantes como salientes, además de los bordes especializados necesarios para tráfico regulado y de socios (borde de Open Banking, borde de filtro, servicio de token de seguridad, sandbox de socios, conmutación). | F25: Jefe de Perímetro y Arquitectura de Conectividad | G25: L0 | H25: Núcleo y Plataforma | I25: La interoperabilidad no es solo interna. Este dominio concentra la zonificación de red, terminación de protocolos, cifrado y política de tráfico para todas las contrapartes externas (banco central, procesadores de tarjetas, esquemas de pago, agencias, fintechs, canales corporativos) de modo que la participación en el ecosistema se convierta en un ejercicio de configuración en lugar de un proyecto. También es donde la mayoría de los bancos encuentran asimetría: las pasarelas API entrantes están maduras mientras que las pasarelas de archivos y eventos salientes están indefinidas, y esa brecha queda en la ruta crítica. | J25: Plataforma de terceros + servicios personalizados de borde | K25: Gateway Apigee de entrada/salida API; integración MuleSoft/WebMethods; Amazon API Gateway vía Modyo Connect; Borde de servicio EKS/Istio.
A26: 2 | B26: 1 | C26: 4.1 | D26: Servicios de pasarela entrantes | E26: Puntos de entrada gestionados para tráfico que se origina fuera del límite de confianza del banco, a través de API, canales de archivos y eventos, incluyendo el intercambio de aserturas de identidad en el borde. | F26: Jefe de Perímetro y Arquitectura de Conectividad | G26: L1 | H26: Núcleo y Plataforma | I26: Da al banco una puerta principal gobernada por modalidad en lugar de una proliferación de conexiones bilaterales con controles inconsistentes. | J26: Terceros | K26: Gateway Apigee de entrada/salida API; integración MuleSoft/WebMethods; Amazon API Gateway vía Modyo Connect; Borde de servicio EKS/Istio.
A27: 3 | B27: 1 | C27: 4.1.1 | D27: Pasarela entrante API | E27: Terminación, autenticación, aplicación de políticas y enrutamiento del tráfico API síncrono procedente de canales, socios y terceros. | F27: Jefe de Perímetro y Arquitectura de Conectividad | G27: L2 | H27: Núcleo y Plataforma | I27: Punto único de aplicación para demanda síncrona externa, desacoplando a las contrapartes de la topología interna del servicio. | J27: Terceros | K27: Gateway Apigee de entrada/salida API; integración MuleSoft/WebMethods; Amazon API Gateway vía Modyo Connect; Borde de servicio EKS/Istio.
A28: 3 | B28: 2 | C28: 4.1.2 | D28: Pasarela de Archivos Entrantes | E28: Recepción segura, validación, escaneo de virus y transferencia de archivos originados externamente, reemplazando la transferencia punto a punto no gestionada. | F28: Jefe de Perímetro y Arquitectura de Conectividad | G28: L2 | H28: Núcleo y Plataforma | I28: Coloca el gran conjunto residual de lotes bajo el mismo régimen de control y observabilidad que el tráfico API. | J28: Terceros | K28: DataStage ETL; interfaces batch/COB; Flujos de documentos OnBase; Interfaces de archivos/datos heredados PISA/Informix. No se evidencia explícitamente ningún producto dedicado MFT.
A29: 3 | B29: 3 | C29: 4.1.3 | D29: Pasarela entrante EventHub | E29: Gestión controlada de eventos y mensajes publicados externamente en la columna vertebral interna de eventos. | F29: Jefe de Perímetro y Arquitectura de Conectividad | G29: L2 | H29: Núcleo y Plataforma | I29: Permite la integración en tiempo real del ecosistema (esquemas, agregadores, datos de mercado) sin exponer temas internos. | J29: Terceros | K29: Kafka/Confluent; Amazon MQ; Amazon Kinesis; Temenos Events Framework; Componentes de procesador de eventos/router de eventos/limpieza de eventos.
A30: 3 | B30: 4 | C30: 4.1.4 | D30: Servicio de Token de Seguridad (STS) | E30: Emisión, intercambio y validación de tokens de seguridad en el perímetro, traduciendo las afirmaciones de identidad externas en credenciales internas. | F30: Jefe de Perímetro y Arquitectura de Conectividad | G30: L2 | H30: Núcleo y Plataforma | I30: Permite respetar las identidades federadas y de socios sin extender los límites internos de fideicomiso. | J30: Terceros | K30: OAuth 2.0 vía Apigee; Azure AD / Microsoft Entra ID; Token Party Identity; tokens de aplicación/usuario gestionados mediante la seguridad API.
A31: 2 | B31: 2 | C31: 4.2 | D31: Servicios de Pasarela de Salida | E31: Gestionó puntos de salida para tráfico originado por bancos hacia contrapartes aguas abajo, a través de API, canales de archivos y eventos, incluyendo el cambio de transacciones a esquemas y procesadores. | F31: Jefe de Perímetro y Arquitectura de Conectividad | G31: L1 | H31: Núcleo y Plataforma | I31: Externaliza la conectividad y credenciales específicas de la contraparte del código de la aplicación, de modo que un proveedor puede ser reemplazado sin tocar los servicios empresariales. | J31: Tercero + personalizado | K31: Gateway Apigee de entrada/salida API; integración MuleSoft/WebMethods; Amazon API Gateway vía Modyo Connect; Borde de servicio EKS/Istio.
A32: 3 | B32: 1 | C32: 4.2.1 | D32: Pasarela API de salida | E32: Mediación de salida, inyección de credenciales, reintentos y control de circuitos para llamadas a proveedores externos, expuesto a través de un DMZ. | F32: Jefe de Perímetro y Arquitectura de Conectividad | G32: L2 | H32: Núcleo y Plataforma | I32: Convierte la sustitución por terceros en un cambio de configuración de gateway en lugar de un proyecto de desarrollo. | J32: Tercero + personalizado | K32: Gateway Apigee de entrada/salida API; integración MuleSoft/WebMethods; Amazon API Gateway vía Modyo Connect; Borde de servicio EKS/Istio.
A33: 3 | B33: 2 | C33: 4.2.2 | D33: Pasarela de Archivos Salientes | E33: Generación, cifrado, programación y transmisión gestionada de archivos salientes, sustituyendo a los arreglos SFTP no gestionados. | F33: Jefe de Perímetro y Arquitectura de Conectividad | G33: L2 | H33: Núcleo y Plataforma | I33: Cierra la brecha de control y observabilidad más común en el estado externo. | J33: Tercero + personalizado | K33: DataStage ETL; interfaces batch/COB; Flujos de documentos OnBase; Interfaces de archivos/datos heredados PISA/Informix. No se evidencia explícitamente ningún producto dedicado MFT.
A34: 3 | B34: 3 | C34: 4.2.3 | D34: Pasarela EventHub de salida | E34: Publicación controlada de eventos internos a suscriptores externos mediante filtrado y gobernanza contractual. | F34: Jefe de Perímetro y Arquitectura de Conectividad | G34: L2 | H34: Núcleo y Plataforma | I34: Permite al banco ofrecer productos de datos en tiempo real al ecosistema sin conceder acceso a temas internos. | J34: Tercero + personalizado | K34: Kafka/Confluent; Amazon MQ; Amazon Kinesis; Temenos Events Framework; Componentes de procesador de eventos/router de eventos/limpieza de eventos.
A35: 3 | B35: 4 | C35: 4.2.4 | D35: Conmutación | E35: Enrutamiento y adaptación de protocolos del tráfico de transacciones a esquemas, procesadores y redes interbancarias, incluyendo la conmutación por error entre proveedores. | F35: Jefe de Perímetro y Arquitectura de Conectividad | G35: L2 | H35: Núcleo y Plataforma | I35: Proporciona redundancia de proveedores y enrutamiento de menor coste como propiedad arquitectónica más que como resultado de negociación. | J35: Tercero + personalizado | K35: BPC SmartVista/SVIP para conmutación y procesamiento de tarjetas; Hub de Pagos para SPEI, dispersión de nóminas y pagos multiplataforma; coexistencia legada con IST/PISA.
A36: 2 | B36: 3 | C36: 4.3 | D36: Ecosistema y ventaja bancaria abierta | E36: Bordes externos especializados para tráfico regulado de banca abierta, incorporación de socios y experimentación controlada, incluyendo bordes de filtrado y exposición al mercado. | F36: Jefe de Perímetro y Arquitectura de Conectividad | G36: L1 | H36: Núcleo y Plataforma | I36: Donde la capa de interoperabilidad se convierte en un canal de negocio: convierte capacidades internas en productos consumibles y contratados para terceros. | J36: Tercero + personalizado | K36: No se evidencia ningún producto específico de mercado abierto o sandbox asociado; las capacidades adyacentes utilizan entornos Apigee, API Gateway, BIAN APIs y entornos sandbox/UAT.
A37: 3 | B37: 1 | C37: 4.3.1 | D37: Borde de la Banca Abierta | E37: Exposición conforme a la normativa de cuentas, pagos y datos APIs con consentimiento, obligaciones sólidas de autenticación e informe. | F37: Jefe de Perímetro y Arquitectura de Conectividad | G37: L2 | H37: Núcleo y Plataforma | I37: Cumple con los mandatos regulatorios en una plataforma compartida en lugar de como un silo aislado de cumplimiento. | J37: Tercero + personalizado | K37: No se evidencia ningún producto específico de mercado abierto o sandbox asociado; las capacidades adyacentes utilizan entornos Apigee, API Gateway, BIAN APIs y entornos sandbox/UAT.
A38: 3 | B38: 2 | C38: 4.3.2 | D38: Borde del filtro | E38: Filtrado y filtro de tráfico externo basado en contenido, consumidores y geografía antes de la pasarela API. | F38: Jefe de Perímetro y Arquitectura de Conectividad | G38: L2 | H38: Núcleo y Plataforma | I38: Reduce la carga hostil y fuera de la política antes de que consuma la capacidad de gateway o backend. | J38: Tercero + personalizado | K38: Imperva WAF / Cloud Armor; AWS Shield; Zscaler TLS terminación; VPN/Direct Connect; Reglas Tetration; AWS/GCP/zonificación de red local.
A39: 3 | B39: 3 | C39: 4.3.3 | D39: Sandbox de socios | E39: Entorno aislado no productivo con datos representativos para el desarrollo y certificación de socios y fintech. | F39: Jefe de Perímetro y Arquitectura de Conectividad | G39: L2 | H39: Núcleo y Plataforma | I39: Comprime la incorporación de socios de meses a semanas, que es la limitación práctica en la estrategia del ecosistema. | J39: Tercero + personalizado | K39: No se evidencia ningún producto específico de mercado abierto o sandbox asociado; las capacidades adyacentes utilizan entornos Apigee, API Gateway, BIAN APIs y entornos sandbox/UAT.
A40: 3 | B40: 4 | C40: 4.3.4 | D40: Mercado API | E40: Catálogo comercial para envases, publicaciones y capacidades de contratación bancarias para consumidores externos. | F40: Jefe de Perímetro y Arquitectura de Conectividad | G40: L2 | H40: Núcleo y Plataforma | I40: Proporciona la interfaz para modelos de negocio no lineales de capacidad como producto. | J40: Tercero + personalizado | K40: No se evidencia ningún producto específico de mercado abierto o sandbox asociado; las capacidades adyacentes utilizan entornos Apigee, API Gateway, BIAN APIs y entornos sandbox/UAT.
A41: 2 | B41: 4 | C41: 4.4 | D41: Zonificación perimetral y conectividad | E41: Segmentación de red, modelo de exposición DMZ, terminación de seguridad del transporte y gestión de conectividad que sustentan todas las modalidades de gateway. | F41: Jefe de Perímetro y Arquitectura de Conectividad | G41: L1 | H41: Núcleo y Plataforma | I41: Establece la topología de confianza dentro de la cual operan todas las demás capacidades de pasarela; Sin él, el desacoplamiento aumenta la exposición en lugar de contenerla. | J41: Terceros | K41: Imperva WAF / Cloud Armor; AWS Shield; Zscaler TLS terminación; VPN/Direct Connect; Reglas Tetration; AWS/GCP/zonificación de red local.
A42: 3 | B42: 1 | C42: 4.4.1 | D42: Zonificación de red y exposición DMZ | E42: Definición y aplicación de zonas de seguridad, y el patrón DMZ mediante el cual las capacidades internas se exponen externamente. | F42: Jefe de Perímetro y Arquitectura de Conectividad | G42: L2 | H42: Núcleo y Plataforma | I42: Garantiza que las nuevas interfaces externas hereden un modelo de exposición aprobado en lugar de negociar uno por proyecto. | J42: Terceros | K42: Imperva WAF / Cloud Armor; AWS Shield; Zscaler TLS terminación; VPN/Direct Connect; Reglas Tetration; AWS/GCP/zonificación de red local.
A43: 3 | B43: 2 | C43: 4.4.2 | D43: Terminación de la seguridad del transporte | E43: Terminación TLS, autenticación mutua y gestión de políticas de cifrado en el edge. | F43: Jefe de Perímetro y Arquitectura de Conectividad | G43: L2 | H43: Núcleo y Plataforma | I43: Centraliza la moneda criptográfica, de modo que las deprecaciones de protocolo se gestionan una vez en vez de por aplicación. | J43: Terceros | K43: Imperva WAF / Cloud Armor; AWS Shield; Zscaler TLS terminación; VPN/Direct Connect; Reglas Tetration; AWS/GCP/zonificación de red local.
...

Sheet PH Horizontal Expansion
A1: Arquitectura de Interoperabilidad / Componibilidad - Jerarquía de Capacidades | Plataforma = dominio de capacidad L0, Subplataforma = grupo de capacidades L1, Proceso = capacidad L2
A4: PID de Plataforma | B4: Plataforma | C4: Descripción de la Plataforma | D4: PID de Subplataforma | E4: Subplataforma | F4: Descripción de la Subplataforma | G4: ID de Proceso | H4: Procesos | I4: Descripción/Definición | J4: Propósito en la Arquitectura Interoperable | K4: Soluciones BanCoppel Utilizadas (Proyecto)
A5: 5 | B5: =SUBSTITUTE(_xlfn.TRANSLATE(SUBSTITUTE(__TR_HORIZONTAL!B5,"API","XQZ0QX"),"en","es"),"XQZ0QX","API") -> Gestión API | C5: =SUBSTITUTE(_xlfn.TRANSLATE(SUBSTITUTE(__TR_HORIZONTAL!C5,"BIAN","XQZ0QX"),"en","es"),"XQZ0QX","BIAN") -> La capacidad de diseñar, publicar, asegurar, versionar, medir y retirar los contratos de servicios síncronos del banco, junto con el conjunto de viviendas orientadas al promotor que los rodea (catálogo, portal, sandbox). Cubre tanto el plano de ejecución (mediación de pasarela, enrutamiento, política de tráfico) como el plano de control (ciclo de vida, administración de políticas, análisis). | PROPÓSITO: Instrumento principal de desacoplamiento de la arquitectura interoperable. Un contrato estable basado en estándares (alineado con BIAN o personalizado canónico) permite que un canal se re-platforme sin tocar un núcleo, y que un núcleo sea reemplazado sin tocar un canal. También es el punto de control semántico donde una petición deja de ser una llamada a un sistema específico y pasa a llamar a una capacidad bancaria. | D5: 5.1 | E5: =SUBSTITUTE(_xlfn.TRANSLATE(SUBSTITUTE(__TR_HORIZONTAL!E5,"API","XQZ0QX"),"en","es"),"XQZ0QX","API") -> Pasarela API y Mediación en tiempo de ejecución | F5: =SUBSTITUTE(_xlfn.TRANSLATE(SUBSTITUTE(__TR_HORIZONTAL!F5,"API","XQZ0QX"),"en","es"),"XQZ0QX","API") -> Plano de ejecución que termina, valida, media y enruta el tráfico API entre consumidores y proveedores, aplicando la política en el punto de invocación en lugar de dentro del código de la aplicación. | PROPÓSITO: Hacer cumplir el contrato en tiempo de ejecución, para que el desacoplamiento esté garantizado por la plataforma en lugar de por la disciplina del desarrollador. | G5: 5.1.1 | H5: =_xlfn.TRANSLATE(__TR_HORIZONTAL!H5,"en","es") -> Enrutamiento | I5: =SUBSTITUTE(_xlfn.TRANSLATE(SUBSTITUTE(__TR_HORIZONTAL!I5,"API","XQZ0QX"),"en","es"),"XQZ0QX","API") -> Resolución de un contrato lógico API a uno o más puntos finales físicos de servicio, incluyendo enrutamiento basado en host, versión y entorno. | J5: =_xlfn.TRANSLATE(__TR_HORIZONTAL!J5,"en","es") -> Permite la reubicación del backend, la re-plataforma y el doble funcionamiento de procesadores antiguos y nuevos sin ningún cambio de consumidor. | K5: =SUBSTITUTE(SUBSTITUTE(SUBSTITUTE(SUBSTITUTE(SUBSTITUTE(SUBSTITUTE(SUBSTITUTE(SUBSTITUTE(SUBSTITUTE(_xlfn.TRANSLATE(SUBSTITUTE(SUBSTITUTE(SUBSTITUTE(SUBSTITUTE(SUBSTITUTE(SUBSTITUTE(SUBSTITUTE(SUBSTITUTE(SUBSTITUTE(__TR_HORIZONTAL!K5,"Apigee API Gateway/API Management","XQZ0QX"),"WebMethods","XQZ1QX"),"MuleSoft","XQZ2QX"),"BPM/BRM","XQZ3QX"),"OFS/IRIS","XQZ4QX"),"REST","XQZ5QX"),"BIAN","XQZ6QX"),"APIs","XQZ7QX"),"API","XQZ8QX"),"en","es"),"XQZ0QX","Apigee API Gateway/API Management"),"XQZ1QX","WebMethods"),"XQZ2QX","MuleSoft"),"XQZ3QX","BPM/BRM"),"XQZ4QX","OFS/IRIS"),"XQZ5QX","REST"),"XQZ6QX","BIAN"),"XQZ7QX","APIs"),"XQZ8QX","API") -> Apigee API Gateway/API Management; integración/orquestación MuleSoft; WebMethods BPM/BRM; BIAN alineado APIs; Transacta OFS/IRIS REST APIs.
G6: 5.1.2 | H6: =_xlfn.TRANSLATE(__TR_HORIZONTAL!H6,"en","es") -> Mediación y transformación del mensaje | I6: =SUBSTITUTE(SUBSTITUTE(SUBSTITUTE(_xlfn.TRANSLATE(SUBSTITUTE(SUBSTITUTE(SUBSTITUTE(__TR_HORIZONTAL!I6,"REST","XQZ0QX"),"SOAP","XQZ1QX"),"gRPC","XQZ2QX"),"en","es"),"XQZ0QX","REST"),"XQZ1QX","SOAP"),"XQZ2QX","gRPC") -> Adaptación de protocolos y cargas útiles en el edge (REST, SOAP, gRPC, protocolos heredados), incluyendo manipulación de cabeceras y mapeo canónico-nativo. | J6: =_xlfn.TRANSLATE(__TR_HORIZONTAL!J6,"en","es") -> Absorbe la heterogeneidad técnica de un conjunto híbrido de núcleo, de modo que los consumidores solo ven un estilo de interfaz. | K6: =SUBSTITUTE(SUBSTITUTE(SUBSTITUTE(SUBSTITUTE(SUBSTITUTE(SUBSTITUTE(SUBSTITUTE(SUBSTITUTE(SUBSTITUTE(_xlfn.TRANSLATE(SUBSTITUTE(SUBSTITUTE(SUBSTITUTE(SUBSTITUTE(SUBSTITUTE(SUBSTITUTE(SUBSTITUTE(SUBSTITUTE(SUBSTITUTE(__TR_HORIZONTAL!K6,"Apigee API Gateway/API Management","XQZ0QX"),"WebMethods","XQZ1QX"),"MuleSoft","XQZ2QX"),"BPM/BRM","XQZ3QX"),"OFS/IRIS","XQZ4QX"),"REST","XQZ5QX"),"BIAN","XQZ6QX"),"APIs","XQZ7QX"),"API","XQZ8QX"),"en","es"),"XQZ0QX","Apigee API Gateway/API Management"),"XQZ1QX","WebMethods"),"XQZ2QX","MuleSoft"),"XQZ3QX","BPM/BRM"),"XQZ4QX","OFS/IRIS"),"XQZ5QX","REST"),"XQZ6QX","BIAN"),"XQZ7QX","APIs"),"XQZ8QX","API") -> Apigee API Gateway/API Management; integración/orquestación MuleSoft; WebMethods BPM/BRM; BIAN alineado APIs; Transacta OFS/IRIS REST APIs.
G7: 5.1.3 | H7: =SUBSTITUTE(_xlfn.TRANSLATE(SUBSTITUTE(__TR_HORIZONTAL!H7,"API","XQZ0QX"),"en","es"),"XQZ0QX","API") -> API Gestión de Tráfico | I7: =SUBSTITUTE(_xlfn.TRANSLATE(SUBSTITUTE(__TR_HORIZONTAL!I7,"API","XQZ0QX"),"en","es"),"XQZ0QX","API") -> Cuotas, límites de tarifa, limitación, arresto de picos y políticas de calidad de servicio aplicadas por consumidor, por API y por nivel. | J7: =_xlfn.TRANSLATE(__TR_HORIZONTAL!J7,"en","es") -> Protege la capacidad finita heredada (MIPS, pools de conexión) frente a la demanda digital ilimitada y convierte la capacidad en un recurso gobernado y con precio. | K7: =SUBSTITUTE(SUBSTITUTE(SUBSTITUTE(SUBSTITUTE(SUBSTITUTE(SUBSTITUTE(SUBSTITUTE(SUBSTITUTE(SUBSTITUTE(_xlfn.TRANSLATE(SUBSTITUTE(SUBSTITUTE(SUBSTITUTE(SUBSTITUTE(SUBSTITUTE(SUBSTITUTE(SUBSTITUTE(SUBSTITUTE(SUBSTITUTE(__TR_HORIZONTAL!K7,"Apigee API Gateway/API Management","XQZ0QX"),"WebMethods","XQZ1QX"),"MuleSoft","XQZ2QX"),"BPM/BRM","XQZ3QX"),"OFS/IRIS","XQZ4QX"),"REST","XQZ5QX"),"BIAN","XQZ6QX"),"APIs","XQZ7QX"),"API","XQZ8QX"),"en","es"),"XQZ0QX","Apigee API Gateway/API Management"),"XQZ1QX","WebMethods"),"XQZ2QX","MuleSoft"),"XQZ3QX","BPM/BRM"),"XQZ4QX","OFS/IRIS"),"XQZ5QX","REST"),"XQZ6QX","BIAN"),"XQZ7QX","APIs"),"XQZ8QX","API") -> Apigee API Gateway/API Management; integración/orquestación MuleSoft; WebMethods BPM/BRM; BIAN alineado APIs; Transacta OFS/IRIS REST APIs.
G8: 5.1.4 | H8: =_xlfn.TRANSLATE(__TR_HORIZONTAL!H8,"en","es") -> Validación de mensajes y protección de carga útil | I8: =_xlfn.TRANSLATE(__TR_HORIZONTAL!I8,"en","es") -> Validación de esquema, tamaño y contenido de mensajes entrantes y salientes, incluyendo protección contra ataques basados en contenido. | J8: =_xlfn.TRANSLATE(__TR_HORIZONTAL!J8,"en","es") -> Detiene el tráfico malformado y hostil antes de que llegue al parque de procesamiento, donde la remediación es mucho más cara. | K8: =SUBSTITUTE(SUBSTITUTE(SUBSTITUTE(SUBSTITUTE(SUBSTITUTE(SUBSTITUTE(SUBSTITUTE(SUBSTITUTE(SUBSTITUTE(_xlfn.TRANSLATE(SUBSTITUTE(SUBSTITUTE(SUBSTITUTE(SUBSTITUTE(SUBSTITUTE(SUBSTITUTE(SUBSTITUTE(SUBSTITUTE(SUBSTITUTE(__TR_HORIZONTAL!K8,"Apigee API Gateway/API Management","XQZ0QX"),"WebMethods","XQZ1QX"),"MuleSoft","XQZ2QX"),"BPM/BRM","XQZ3QX"),"OFS/IRIS","XQZ4QX"),"REST","XQZ5QX"),"BIAN","XQZ6QX"),"APIs","XQZ7QX"),"API","XQZ8QX"),"en","es"),"XQZ0QX","Apigee API Gateway/API Management"),"XQZ1QX","WebMethods"),"XQZ2QX","MuleSoft"),"XQZ3QX","BPM/BRM"),"XQZ4QX","OFS/IRIS"),"XQZ5QX","REST"),"XQZ6QX","BIAN"),"XQZ7QX","APIs"),"XQZ8QX","API") -> Apigee API Gateway/API Management; integración/orquestación MuleSoft; WebMethods BPM/BRM; BIAN alineado APIs; Transacta OFS/IRIS REST APIs.
G9: 5.1.5 | H9: =_xlfn.TRANSLATE(__TR_HORIZONTAL!H9,"en","es") -> Gestión de errores y normalización de fallos | I9: =_xlfn.TRANSLATE(__TR_HORIZONTAL!I9,"en","es") -> Taxonomía de errores estandarizada, mapeo de fallos y códigos de respuesta a través de backends heterogéneos. | J9: =_xlfn.TRANSLATE(__TR_HORIZONTAL!J9,"en","es") -> Evita que la semántica de error específica del backend se filtre en los canales, que es una de las fuentes más comunes de acoplamiento oculto. | K9: =SUBSTITUTE(SUBSTITUTE(SUBSTITUTE(SUBSTITUTE(SUBSTITUTE(SUBSTITUTE(SUBSTITUTE(SUBSTITUTE(SUBSTITUTE(_xlfn.TRANSLATE(SUBSTITUTE(SUBSTITUTE(SUBSTITUTE(SUBSTITUTE(SUBSTITUTE(SUBSTITUTE(SUBSTITUTE(SUBSTITUTE(SUBSTITUTE(__TR_HORIZONTAL!K9,"Apigee API Gateway/API Management","XQZ0QX"),"WebMethods","XQZ1QX"),"MuleSoft","XQZ2QX"),"BPM/BRM","XQZ3QX"),"OFS/IRIS","XQZ4QX"),"REST","XQZ5QX"),"BIAN","XQZ6QX"),"APIs","XQZ7QX"),"API","XQZ8QX"),"en","es"),"XQZ0QX","Apigee API Gateway/API Management"),"XQZ1QX","WebMethods"),"XQZ2QX","MuleSoft"),"XQZ3QX","BPM/BRM"),"XQZ4QX","OFS/IRIS"),"XQZ5QX","REST"),"XQZ6QX","BIAN"),"XQZ7QX","APIs"),"XQZ8QX","API") -> Apigee API Gateway/API Management; integración/orquestación MuleSoft; WebMethods BPM/BRM; BIAN alineado APIs; Transacta OFS/IRIS REST APIs.
D10: 5.2 | E10: =SUBSTITUTE(_xlfn.TRANSLATE(SUBSTITUTE(__TR_HORIZONTAL!E10,"API","XQZ0QX"),"en","es"),"XQZ0QX","API") -> Gestión del ciclo de vida API | F10: =SUBSTITUTE(_xlfn.TRANSLATE(SUBSTITUTE(__TR_HORIZONTAL!F10,"API","XQZ0QX"),"en","es"),"XQZ0QX","API") -> Plano de control que gobierna un API desde el diseño y la definición del contrato hasta la publicación, el cambio de versiones, la notificación de cambios y su eventual retirada. | PROPÓSITO: Convierte las interfaces en activos empresariales gestionados con una ruta de cambio controlada, que es la condición previa para su reutilización entre entidades y países. | G10: 5.2.1 | H10: =SUBSTITUTE(_xlfn.TRANSLATE(SUBSTITUTE(__TR_HORIZONTAL!H10,"API","XQZ0QX"),"en","es"),"XQZ0QX","API") -> Normas de diseño y contratos API | I10: =SUBSTITUTE(_xlfn.TRANSLATE(SUBSTITUTE(__TR_HORIZONTAL!I10,"BIAN","XQZ0QX"),"en","es"),"XQZ0QX","BIAN") -> Definición y aplicación de estándares de interfaz, nombres canónicos o alineados con BIAN, y puertas de revisión de diseño antes de la publicación. | J10: =_xlfn.TRANSLATE(__TR_HORIZONTAL!J10,"en","es") -> Garantiza que las nuevas interfaces aumenten la reutilización en lugar de añadir otra integración personalizada para mantener. | K10: =SUBSTITUTE(SUBSTITUTE(SUBSTITUTE(SUBSTITUTE(_xlfn.TRANSLATE(SUBSTITUTE(SUBSTITUTE(SUBSTITUTE(SUBSTITUTE(__TR_HORIZONTAL!K10,"OpenAPI","XQZ0QX"),"Swagger","XQZ1QX"),"BIAN","XQZ2QX"),"API","XQZ3QX"),"en","es"),"XQZ0QX","OpenAPI"),"XQZ1QX","Swagger"),"XQZ2QX","BIAN"),"XQZ3QX","API") -> Estándares BIAN API; Apigee API ciclo de vida/gobernanza; Documentación al estilo OpenAPI/Swagger para OfiWeb/Canales; El cambio API está controlado por la gobernanza de la arquitectura.
G11: 5.2.2 | H11: =SUBSTITUTE(_xlfn.TRANSLATE(SUBSTITUTE(__TR_HORIZONTAL!H11,"API","XQZ0QX"),"en","es"),"XQZ0QX","API") -> Versionado API | I11: =_xlfn.TRANSLATE(__TR_HORIZONTAL!I11,"en","es") -> Soporte simultáneo de múltiples versiones de contrato con reglas definidas de compatibilidad y deprecación. | J11: =_xlfn.TRANSLATE(__TR_HORIZONTAL!J11,"en","es") -> Desacopla los ciclos de lanzamiento entre consumidores y proveedores, de modo que ningún cambio individual requiera un despliegue sincronizado de big bang. | K11: =SUBSTITUTE(SUBSTITUTE(SUBSTITUTE(SUBSTITUTE(_xlfn.TRANSLATE(SUBSTITUTE(SUBSTITUTE(SUBSTITUTE(SUBSTITUTE(__TR_HORIZONTAL!K11,"OpenAPI","XQZ0QX"),"Swagger","XQZ1QX"),"BIAN","XQZ2QX"),"API","XQZ3QX"),"en","es"),"XQZ0QX","OpenAPI"),"XQZ1QX","Swagger"),"XQZ2QX","BIAN"),"XQZ3QX","API") -> Estándares BIAN API; Apigee API ciclo de vida/gobernanza; Documentación al estilo OpenAPI/Swagger para OfiWeb/Canales; El cambio API está controlado por la gobernanza de la arquitectura.
G12: 5.2.3 | H12: =SUBSTITUTE(_xlfn.TRANSLATE(SUBSTITUTE(__TR_HORIZONTAL!H12,"API","XQZ0QX"),"en","es"),"XQZ0QX","API") -> Notificación de publicación y cambio API | I12: =SUBSTITUTE(SUBSTITUTE(_xlfn.TRANSLATE(SUBSTITUTE(SUBSTITUTE(__TR_HORIZONTAL!I12,"APIs","XQZ0QX"),"API","XQZ1QX"),"en","es"),"XQZ0QX","APIs"),"XQZ1QX","API") -> Promoción de APIs en entornos y notificación proactiva de cambios de contrato a los consumidores registrados. | J12: =_xlfn.TRANSLATE(__TR_HORIZONTAL!J12,"en","es") -> Elimina la sobrecarga de coordinación que de otro modo hace que los equipos eviten reutilizar una interfaz compartida. | K12: =SUBSTITUTE(SUBSTITUTE(SUBSTITUTE(SUBSTITUTE(_xlfn.TRANSLATE(SUBSTITUTE(SUBSTITUTE(SUBSTITUTE(SUBSTITUTE(__TR_HORIZONTAL!K12,"OpenAPI","XQZ0QX"),"Swagger","XQZ1QX"),"BIAN","XQZ2QX"),"API","XQZ3QX"),"en","es"),"XQZ0QX","OpenAPI"),"XQZ1QX","Swagger"),"XQZ2QX","BIAN"),"XQZ3QX","API") -> Estándares BIAN API; Apigee API ciclo de vida/gobernanza; Documentación al estilo OpenAPI/Swagger para OfiWeb/Canales; El cambio API está controlado por la gobernanza de la arquitectura.
G13: 5.2.4 | H13: =SUBSTITUTE(_xlfn.TRANSLATE(SUBSTITUTE(__TR_HORIZONTAL!H13,"API","XQZ0QX"),"en","es"),"XQZ0QX","API") -> API Depreciación y Retiro | I13: =_xlfn.TRANSLATE(__TR_HORIZONTAL!I13,"en","es") -> Un control de la desaparición de interfaces, incluyendo el seguimiento de migración del consumidor y la aplicación de fechas de fin de vida. | J13: =_xlfn.TRANSLATE(__TR_HORIZONTAL!J13,"en","es") -> Evita que la capa de interoperabilidad acumule la misma deuda de interfaz que fue creada para eliminar. | K13: =SUBSTITUTE(SUBSTITUTE(SUBSTITUTE(SUBSTITUTE(_xlfn.TRANSLATE(SUBSTITUTE(SUBSTITUTE(SUBSTITUTE(SUBSTITUTE(__TR_HORIZONTAL!K13,"OpenAPI","XQZ0QX"),"Swagger","XQZ1QX"),"BIAN","XQZ2QX"),"API","XQZ3QX"),"en","es"),"XQZ0QX","OpenAPI"),"XQZ1QX","Swagger"),"XQZ2QX","BIAN"),"XQZ3QX","API") -> Estándares BIAN API; Apigee API ciclo de vida/gobernanza; Documentación al estilo OpenAPI/Swagger para OfiWeb/Canales; El cambio API está controlado por la gobernanza de la arquitectura.
D14: 5.3 | E14: =SUBSTITUTE(_xlfn.TRANSLATE(SUBSTITUTE(__TR_HORIZONTAL!E14,"API","XQZ0QX"),"en","es"),"XQZ0QX","API") -> API Manager (Administración de Plataforma) | F14: =SUBSTITUTE(_xlfn.TRANSLATE(SUBSTITUTE(__TR_HORIZONTAL!F14,"API","XQZ0QX"),"en","es"),"XQZ0QX","API") -> Administración, configuración de políticas, operación e instrumentación comercial de la propia plataforma de gestión API, tanto en topologías locales, en la nube como en la nube o híbridas. | PROPÓSITO: Mantiene la política administrada de forma centralizada y aplicada de forma consistente, para que las normas de seguridad y tráfico no se fragmenten por equipo API. | G14: 5.3.1 | H14: =_xlfn.TRANSLATE(__TR_HORIZONTAL!H14,"en","es") -> Administración y Seguimiento de Políticas | I14: =SUBSTITUTE(_xlfn.TRANSLATE(SUBSTITUTE(__TR_HORIZONTAL!I14,"API","XQZ0QX"),"en","es"),"XQZ0QX","API") -> Definición central, asignación y auditoría de políticas de pasarela (seguridad, tráfico, mediación, caché) a lo largo del patrimonio API. | J14: =_xlfn.TRANSLATE(__TR_HORIZONTAL!J14,"en","es") -> Convierte la política en un elemento de configuración gobernado en lugar de código embebido, permitiendo cambios a nivel de estado en una sola acción. | K14: =SUBSTITUTE(SUBSTITUTE(SUBSTITUTE(SUBSTITUTE(SUBSTITUTE(_xlfn.TRANSLATE(SUBSTITUTE(SUBSTITUTE(SUBSTITUTE(SUBSTITUTE(SUBSTITUTE(__TR_HORIZONTAL!K14,"DataDog","XQZ0QX"),"DevSecOps","XQZ1QX"),"API","XQZ2QX"),"AWS","XQZ3QX"),"GCP","XQZ4QX"),"en","es"),"XQZ0QX","DataDog"),"XQZ1QX","DevSecOps"),"XQZ2QX","API"),"XQZ3QX","AWS"),"XQZ4QX","GCP") -> Administración y políticas de plataformas Apigee; Monitorización DataDog/API; tuberías DevSecOps; Apigee alojado en GCP con proveedores AWS/locales.
G15: 5.3.2 | H15: =SUBSTITUTE(_xlfn.TRANSLATE(SUBSTITUTE(__TR_HORIZONTAL!H15,"API","XQZ0QX"),"en","es"),"XQZ0QX","API") -> API Monitorización, Analítica y Monetización | I15: =SUBSTITUTE(_xlfn.TRANSLATE(SUBSTITUTE(__TR_HORIZONTAL!I15,"API","XQZ0QX"),"en","es"),"XQZ0QX","API") -> Métricas de consumo, latencia y análisis de errores por API y por consumidor, con base de medición para devolución interna o monetización de socios. | J15: =_xlfn.TRANSLATE(__TR_HORIZONTAL!J15,"en","es") -> Proporciona la base de evidencia para las afirmaciones de reutilización, la planificación de capacidades y los modelos comerciales de ecosistemas. | K15: =SUBSTITUTE(SUBSTITUTE(SUBSTITUTE(SUBSTITUTE(SUBSTITUTE(_xlfn.TRANSLATE(SUBSTITUTE(SUBSTITUTE(SUBSTITUTE(SUBSTITUTE(SUBSTITUTE(__TR_HORIZONTAL!K15,"DataDog","XQZ0QX"),"DevSecOps","XQZ1QX"),"API","XQZ2QX"),"AWS","XQZ3QX"),"GCP","XQZ4QX"),"en","es"),"XQZ0QX","DataDog"),"XQZ1QX","DevSecOps"),"XQZ2QX","API"),"XQZ3QX","AWS"),"XQZ4QX","GCP") -> Administración y políticas de plataformas Apigee; Monitorización DataDog/API; tuberías DevSecOps; Apigee alojado en GCP con proveedores AWS/locales.
G16: 5.3.3 | H16: =_xlfn.TRANSLATE(__TR_HORIZONTAL!H16,"en","es") -> Despliegue y operaciones de la plataforma | I16: =SUBSTITUTE(_xlfn.TRANSLATE(SUBSTITUTE(__TR_HORIZONTAL!I16,"API","XQZ0QX"),"en","es"),"XQZ0QX","API") -> Topología de despliegue, automatización, actualización y soporte operativo de la plataforma de gestión API. | J16: =_xlfn.TRANSLATE(__TR_HORIZONTAL!J16,"en","es") -> Garantiza que la capa de desacoplamiento sea en sí misma resiliente y actualizable, ya que se convierte en un punto único de dependencia para todo el tráfico. | K16: =SUBSTITUTE(SUBSTITUTE(SUBSTITUTE(SUBSTITUTE(SUBSTITUTE(_xlfn.TRANSLATE(SUBSTITUTE(SUBSTITUTE(SUBSTITUTE(SUBSTITUTE(SUBSTITUTE(__TR_HORIZONTAL!K16,"DataDog","XQZ0QX"),"DevSecOps","XQZ1QX"),"API","XQZ2QX"),"AWS","XQZ3QX"),"GCP","XQZ4QX"),"en","es"),"XQZ0QX","DataDog"),"XQZ1QX","DevSecOps"),"XQZ2QX","API"),"XQZ3QX","AWS"),"XQZ4QX","GCP") -> Administración y políticas de plataformas Apigee; Monitorización DataDog/API; tuberías DevSecOps; Apigee alojado en GCP con proveedores AWS/locales.
D17: 5.4 | E17: =_xlfn.TRANSLATE(__TR_HORIZONTAL!E17,"en","es") -> Portal y catálogo para desarrolladores | F17: =_xlfn.TRANSLATE(__TR_HORIZONTAL!F17,"en","es") -> Superficie de autoservicio donde desarrolladores internos y externos descubren, evalúan, se registran y se apoyan en interfaces publicadas. | PROPÓSITO: La reutilización solo ocurre si se pueden encontrar capacidades. El portal convierte un inventario técnico en un catálogo de productos consumibles. | G17: 5.4.1 | H17: =SUBSTITUTE(_xlfn.TRANSLATE(SUBSTITUTE(__TR_HORIZONTAL!H17,"API","XQZ0QX"),"en","es"),"XQZ0QX","API") -> Catálogo, documentación y descubrimiento de metadatos API | I17: =_xlfn.TRANSLATE(__TR_HORIZONTAL!I17,"en","es") -> Inventario consultable de interfaces publicadas con especificaciones, ejemplos y metadatos. | J17: =_xlfn.TRANSLATE(__TR_HORIZONTAL!J17,"en","es") -> Elimina el coste de redescubrimiento que impulsa a los equipos a construir una integración paralela punto a punto. | K17: =SUBSTITUTE(_xlfn.TRANSLATE(SUBSTITUTE(__TR_HORIZONTAL!K17,"API","XQZ0QX"),"en","es"),"XQZ0QX","API") -> Catálogo/gobernanza API para Apificación de Canales y OfiWeb; Apígeo como plano de gestión API. No se evidencia explícitamente ninguna herramienta de portal para desarrolladores independiente.
G18: 5.4.2 | H18: =_xlfn.TRANSLATE(__TR_HORIZONTAL!H18,"en","es") -> Registro de desarrolladores y autoservicio | I18: =SUBSTITUTE(_xlfn.TRANSLATE(SUBSTITUTE(__TR_HORIZONTAL!I18,"API","XQZ0QX"),"en","es"),"XQZ0QX","API") -> Incorporación, emisión de credenciales, registro de solicitudes y gestión de derechos para consumidores de API. | J18: =_xlfn.TRANSLATE(__TR_HORIZONTAL!J18,"en","es") -> Elimina el control humano del camino de consumo, que es lo que hace que la reutilización interna y la incorporación de parejas sea rápida. | K18: =SUBSTITUTE(_xlfn.TRANSLATE(SUBSTITUTE(__TR_HORIZONTAL!K18,"API","XQZ0QX"),"en","es"),"XQZ0QX","API") -> Catálogo/gobernanza API para Apificación de Canales y OfiWeb; Apígeo como plano de gestión API. No se evidencia explícitamente ninguna herramienta de portal para desarrolladores independiente.
G19: 5.4.3 | H19: =_xlfn.TRANSLATE(__TR_HORIZONTAL!H19,"en","es") -> Colaboración, comunidad y autoapoyo | I19: =_xlfn.TRANSLATE(__TR_HORIZONTAL!I19,"en","es") -> Informes de problemas, bucles de retroalimentación, guías de uso, SDKs y ejemplos de referencia para equipos que consumen. | J19: =_xlfn.TRANSLATE(__TR_HORIZONTAL!J19,"en","es") -> Proporciona la capa de habilitación sin la cual una capacidad publicada está técnicamente disponible pero prácticamente no se utiliza. | K19: =SUBSTITUTE(_xlfn.TRANSLATE(SUBSTITUTE(__TR_HORIZONTAL!K19,"API","XQZ0QX"),"en","es"),"XQZ0QX","API") -> Catálogo/gobernanza API para Apificación de Canales y OfiWeb; Apígeo como plano de gestión API. No se evidencia explícitamente ninguna herramienta de portal para desarrolladores independiente.
A20: 4 | B20: =_xlfn.TRANSLATE(__TR_HORIZONTAL!B20,"en","es") -> Servicios de Gateway | C20: =SUBSTITUTE(SUBSTITUTE(_xlfn.TRANSLATE(SUBSTITUTE(SUBSTITUTE(__TR_HORIZONTAL!C20,"Open Banking","XQZ0QX"),"API","XQZ1QX"),"en","es"),"XQZ0QX","Open Banking"),"XQZ1QX","API") -> Controlaba la entrada y salida a través del límite de confianza del banco en tres modalidades - API, archivo y evento - tanto en direcciones entrantes como salientes, además de los bordes especializados necesarios para tráfico regulado y de socios (borde Open Banking, borde de filtro, servicio de token de seguridad, sandbox de socios, conmutación). | PROPÓSITO: La interoperabilidad no es solo interna. Este dominio concentra la zonificación de red, terminación de protocolos, cifrado y política de tráfico para todas las contrapartes externas (banco central, procesadores de tarjetas, esquemas de pago, agencias, fintechs, canales corporativos) de modo que la participación en el ecosistema se convierta en un ejercicio de configuración en lugar de un proyecto. También es donde la mayoría de los bancos encuentran asimetría: las gateways entrantes API están maduras mientras que las gateways de archivos y eventos salientes no están definidas, y esa brecha queda en el camino crítico. | D20: 4.1 | E20: =_xlfn.TRANSLATE(__TR_HORIZONTAL!E20,"en","es") -> Servicios de pasarela entrantes | F20: =SUBSTITUTE(_xlfn.TRANSLATE(SUBSTITUTE(__TR_HORIZONTAL!F20,"API","XQZ0QX"),"en","es"),"XQZ0QX","API") -> Puntos de entrada gestionados para tráfico que se origina fuera del límite de confianza del banco, a través de API, canales de archivos y eventos, incluyendo el intercambio de aserturas de identidad en el borde. | PROPÓSITO: Da al banco una puerta principal gobernada por modalidad en lugar de una proliferación de conexiones bilaterales con controles inconsistentes. | G20: 4.1.1 | H20: =SUBSTITUTE(_xlfn.TRANSLATE(SUBSTITUTE(__TR_HORIZONTAL!H20,"API","XQZ0QX"),"en","es"),"XQZ0QX","API") -> Pasarela entrante API | I20: =SUBSTITUTE(_xlfn.TRANSLATE(SUBSTITUTE(__TR_HORIZONTAL!I20,"API","XQZ0QX"),"en","es"),"XQZ0QX","API") -> Terminación, autenticación, aplicación de políticas y enrutamiento del tráfico API síncrono procedente de canales, socios y terceros. | J20: =_xlfn.TRANSLATE(__TR_HORIZONTAL!J20,"en","es") -> Punto único de aplicación para demanda síncrona externa, desacoplando a las contrapartes de la topología interna del servicio. | K20: =SUBSTITUTE(SUBSTITUTE(SUBSTITUTE(SUBSTITUTE(SUBSTITUTE(SUBSTITUTE(_xlfn.TRANSLATE(SUBSTITUTE(SUBSTITUTE(SUBSTITUTE(SUBSTITUTE(SUBSTITUTE(SUBSTITUTE(__TR_HORIZONTAL!K20,"Amazon API Gateway","XQZ0QX"),"Modyo Connect","XQZ1QX"),"WebMethods","XQZ2QX"),"MuleSoft","XQZ3QX"),"API","XQZ4QX"),"EKS","XQZ5QX"),"en","es"),"XQZ0QX","Amazon API Gateway"),"XQZ1QX","Modyo Connect"),"XQZ2QX","WebMethods"),"XQZ3QX","MuleSoft"),"XQZ4QX","API"),"XQZ5QX","EKS") -> Gateway de entrada/salida API de Apigee; integración MuleSoft/WebMethods; Amazon API Gateway vía Modyo Connect; EKS/Istio Service Edge.
G21: 4.1.2 | H21: =_xlfn.TRANSLATE(__TR_HORIZONTAL!H21,"en","es") -> Pasarela de Archivos Entrantes | I21: =_xlfn.TRANSLATE(__TR_HORIZONTAL!I21,"en","es") -> Recepción segura, validación, escaneo de virus y transferencia de archivos originados externamente, reemplazando la transferencia punto a punto no gestionada. | J21: =SUBSTITUTE(_xlfn.TRANSLATE(SUBSTITUTE(__TR_HORIZONTAL!J21,"API","XQZ0QX"),"en","es"),"XQZ0QX","API") -> Coloca el gran conjunto residual de lotes bajo el mismo régimen de control y observabilidad que el tráfico API. | K21: =_xlfn.TRANSLATE(__TR_HORIZONTAL!K21,"en","es") -> DataStage ETL; interfaces por lotes/COB; Flujos de documentos OnBase; Interfaces heredadas de archivos/datos de PISA/Informix. No hay ningún producto MFT dedicado a evidencia explícita.
G22: 4.1.3 | H22: =SUBSTITUTE(_xlfn.TRANSLATE(SUBSTITUTE(__TR_HORIZONTAL!H22,"EventHub","XQZ0QX"),"en","es"),"XQZ0QX","EventHub") -> Pasarela entrante EventHub | I22: =_xlfn.TRANSLATE(__TR_HORIZONTAL!I22,"en","es") -> Gestión controlada de eventos y mensajes publicados externamente en la columna vertebral interna de eventos. | J22: =_xlfn.TRANSLATE(__TR_HORIZONTAL!J22,"en","es") -> Permite la integración en tiempo real del ecosistema (esquemas, agregadores, datos de mercado) sin exponer temas internos. | K22: =_xlfn.TRANSLATE(__TR_HORIZONTAL!K22,"en","es") -> Kafka/Confluent; Amazon MQ; Kinesis amazónica; Marco de Eventos Temenos; Componentes de procesador de eventos/router de eventos/limpieza de eventos.
G23: 4.1.4 | H23: =_xlfn.TRANSLATE(__TR_HORIZONTAL!H23,"en","es") -> Servicio de Token de Seguridad (STS) | I23: =_xlfn.TRANSLATE(__TR_HORIZONTAL!I23,"en","es") -> Emisión, intercambio y validación de tokens de seguridad en el perímetro, traduciendo las afirmaciones de identidad externas en credenciales internas. | J23: =_xlfn.TRANSLATE(__TR_HORIZONTAL!J23,"en","es") -> Permite respetar las identidades federadas y de socios sin extender los límites internos de fideicomiso. | K23: =SUBSTITUTE(SUBSTITUTE(SUBSTITUTE(_xlfn.TRANSLATE(SUBSTITUTE(SUBSTITUTE(SUBSTITUTE(__TR_HORIZONTAL!K23,"Microsoft Entra ID","XQZ0QX"),"API","XQZ1QX"),"OAuth 2.0","XQZ2QX"),"en","es"),"XQZ0QX","Microsoft Entra ID"),"XQZ1QX","API"),"XQZ2QX","OAuth 2.0") -> OAuth 2.0 vía Apigee; Azure AD / Microsoft Entra ID; Identidad del Partido Token; tokens de aplicación/usuario gestionados mediante la seguridad API.
D24: 4.2 | E24: =_xlfn.TRANSLATE(__TR_HORIZONTAL!E24,"en","es") -> Servicios de Pasarela de Salida | F24: =SUBSTITUTE(_xlfn.TRANSLATE(SUBSTITUTE(__TR_HORIZONTAL!F24,"API","XQZ0QX"),"en","es"),"XQZ0QX","API") -> Gestionó puntos de salida para tráfico originado por bancos hacia contrapartes aguas abajo, a través de API, canales de archivos y eventos, incluyendo el cambio de transacciones a esquemas y procesadores. | PROPÓSITO: Externaliza la conectividad y credenciales específicas de la contraparte del código de la aplicación, para que un proveedor pueda ser reemplazado sin tocar los servicios empresariales. | G24: 4.2.1 | H24: =SUBSTITUTE(_xlfn.TRANSLATE(SUBSTITUTE(__TR_HORIZONTAL!H24,"API","XQZ0QX"),"en","es"),"XQZ0QX","API") -> Pasarela API de salida | I24: =_xlfn.TRANSLATE(__TR_HORIZONTAL!I24,"en","es") -> Mediación de salida, inyección de credenciales, reintentos y control de circuitos para llamadas a proveedores externos, expuestas a través de una DMZ. | J24: =_xlfn.TRANSLATE(__TR_HORIZONTAL!J24,"en","es") -> Convierte la sustitución por terceros en un cambio de configuración de gateway en lugar de un proyecto de desarrollo. | K24: =SUBSTITUTE(SUBSTITUTE(SUBSTITUTE(SUBSTITUTE(SUBSTITUTE(SUBSTITUTE(_xlfn.TRANSLATE(SUBSTITUTE(SUBSTITUTE(SUBSTITUTE(SUBSTITUTE(SUBSTITUTE(SUBSTITUTE(__TR_HORIZONTAL!K24,"Amazon API Gateway","XQZ0QX"),"Modyo Connect","XQZ1QX"),"WebMethods","XQZ2QX"),"MuleSoft","XQZ3QX"),"API","XQZ4QX"),"EKS","XQZ5QX"),"en","es"),"XQZ0QX","Amazon API Gateway"),"XQZ1QX","Modyo Connect"),"XQZ2QX","WebMethods"),"XQZ3QX","MuleSoft"),"XQZ4QX","API"),"XQZ5QX","EKS") -> Gateway de entrada/salida API de Apigee; integración MuleSoft/WebMethods; Amazon API Gateway vía Modyo Connect; EKS/Istio Service Edge.
G25: 4.2.2 | H25: =_xlfn.TRANSLATE(__TR_HORIZONTAL!H25,"en","es") -> Pasarela de Archivos Salientes | I25: =_xlfn.TRANSLATE(__TR_HORIZONTAL!I25,"en","es") -> Generación, cifrado, programación y transmisión gestionadas de archivos salientes, sustituyendo a los arreglos SFTP no gestionados. | J25: =_xlfn.TRANSLATE(__TR_HORIZONTAL!J25,"en","es") -> Cierra la brecha de control y observabilidad más común en el estado externo. | K25: =_xlfn.TRANSLATE(__TR_HORIZONTAL!K25,"en","es") -> DataStage ETL; interfaces por lotes/COB; Flujos de documentos OnBase; Interfaces heredadas de archivos/datos de PISA/Informix. No hay ningún producto MFT dedicado a evidencia explícita.
G26: 4.2.3 | H26: =SUBSTITUTE(_xlfn.TRANSLATE(SUBSTITUTE(__TR_HORIZONTAL!H26,"EventHub","XQZ0QX"),"en","es"),"XQZ0QX","EventHub") -> Pasarela EventHub de salida | I26: =_xlfn.TRANSLATE(__TR_HORIZONTAL!I26,"en","es") -> Publicación controlada de eventos internos a suscriptores externos mediante filtrado y gobernanza contractual. | J26: =_xlfn.TRANSLATE(__TR_HORIZONTAL!J26,"en","es") -> Permite al banco ofrecer productos de datos en tiempo real al ecosistema sin conceder acceso a temas internos. | K26: =_xlfn.TRANSLATE(__TR_HORIZONTAL!K26,"en","es") -> Kafka/Confluent; Amazon MQ; Kinesis amazónica; Marco de Eventos Temenos; Componentes de procesador de eventos/router de eventos/limpieza de eventos.
G27: 4.2.4 | H27: =_xlfn.TRANSLATE(__TR_HORIZONTAL!H27,"en","es") -> Conmutación | I27: =_xlfn.TRANSLATE(__TR_HORIZONTAL!I27,"en","es") -> Enrutamiento y adaptación de protocolos del tráfico de transacciones a esquemas, procesadores y redes interbancarias, incluyendo la conmutación por error entre proveedores. | J27: =_xlfn.TRANSLATE(__TR_HORIZONTAL!J27,"en","es") -> Proporciona redundancia de proveedores y enrutamiento de menor coste como propiedad arquitectónica más que como resultado de negociación. | K27: =SUBSTITUTE(_xlfn.TRANSLATE(SUBSTITUTE(__TR_HORIZONTAL!K27,"SmartVista","XQZ0QX"),"en","es"),"XQZ0QX","SmartVista") -> BPC SmartVista/SVIP para conmutación y procesamiento de tarjetas; Hub de Pagos para SPEI, dispersión de nóminas y pagos multiplataforma; coexistencia legada entre IST y PISA.
D28: 4.3 | E28: =SUBSTITUTE(_xlfn.TRANSLATE(SUBSTITUTE(__TR_HORIZONTAL!E28,"Open Banking","XQZ0QX"),"en","es"),"XQZ0QX","Open Banking") -> Ecosistema & Open Banking Edge | F28: =_xlfn.TRANSLATE(__TR_HORIZONTAL!F28,"en","es") -> Bordes externos especializados para tráfico regulado de banca abierta, incorporación de socios y experimentación controlada, incluyendo bordes de filtrado y exposición al mercado. | PROPÓSITO: Cuando la capa de interoperabilidad se convierte en un canal de negocio: convierte capacidades internas en productos consumibles y contratados para terceros. | G28: 4.3.1 | H28: =SUBSTITUTE(_xlfn.TRANSLATE(SUBSTITUTE(__TR_HORIZONTAL!H28,"Open Banking","XQZ0QX"),"en","es"),"XQZ0QX","Open Banking") -> Open Banking Edge | I28: =SUBSTITUTE(SUBSTITUTE(_xlfn.TRANSLATE(SUBSTITUTE(SUBSTITUTE(__TR_HORIZONTAL!I28,"APIs","XQZ0QX"),"API","XQZ1QX"),"en","es"),"XQZ0QX","APIs"),"XQZ1QX","API") -> Exposición conforme a la normativa de cuentas, pagos y datos APIs con consentimiento, obligaciones sólidas de autenticación e informe. | J28: =_xlfn.TRANSLATE(__TR_HORIZONTAL!J28,"en","es") -> Cumple con los mandatos regulatorios en una plataforma compartida en lugar de como un silo aislado de cumplimiento. | K28: =SUBSTITUTE(SUBSTITUTE(SUBSTITUTE(SUBSTITUTE(_xlfn.TRANSLATE(SUBSTITUTE(SUBSTITUTE(SUBSTITUTE(SUBSTITUTE(__TR_HORIZONTAL!K28,"Open Banking","XQZ0QX"),"BIAN","XQZ1QX"),"APIs","XQZ2QX"),"API","XQZ3QX"),"en","es"),"XQZ0QX","Open Banking"),"XQZ1QX","BIAN"),"XQZ2QX","APIs"),"XQZ3QX","API") -> No se evidencia ningún producto sandbox específico de Open Banking en el marketplace o socio; las capacidades adyacentes utilizan Apigee, API Gateway, BIAN APIs y entornos sandbox/UAT.
G29: 4.3.2 | H29: =_xlfn.TRANSLATE(__TR_HORIZONTAL!H29,"en","es") -> Borde del filtro | I29: =SUBSTITUTE(_xlfn.TRANSLATE(SUBSTITUTE(__TR_HORIZONTAL!I29,"API","XQZ0QX"),"en","es"),"XQZ0QX","API") -> Filtrado y filtro de tráfico externo basado en contenido, consumidores y geografía antes de la pasarela API. | J29: =_xlfn.TRANSLATE(__TR_HORIZONTAL!J29,"en","es") -> Reduce la carga hostil y fuera de la política antes de que consuma la capacidad de gateway o backend. | K29: =SUBSTITUTE(SUBSTITUTE(SUBSTITUTE(SUBSTITUTE(_xlfn.TRANSLATE(SUBSTITUTE(SUBSTITUTE(SUBSTITUTE(SUBSTITUTE(__TR_HORIZONTAL!K29,"Cloud Armor","XQZ0QX"),"AWS","XQZ1QX"),"GCP","XQZ2QX"),"TLS","XQZ3QX"),"en","es"),"XQZ0QX","Cloud Armor"),"XQZ1QX","AWS"),"XQZ2QX","GCP"),"XQZ3QX","TLS") -> Imperva WAF / Cloud Armor; Escudo AWS; Terminación Zscaler TLS; VPN/Conexión Directa; Reglas de la tetración; AWS/GCP/zonificación de red local.
G30: 4.3.3 | H30: =_xlfn.TRANSLATE(__TR_HORIZONTAL!H30,"en","es") -> Sandbox de socios | I30: =_xlfn.TRANSLATE(__TR_HORIZONTAL!I30,"en","es") -> Entorno aislado no productivo con datos representativos para el desarrollo y certificación de socios y fintech. | J30: =_xlfn.TRANSLATE(__TR_HORIZONTAL!J30,"en","es") -> Comprime la incorporación de socios de meses a semanas, que es la limitación práctica en la estrategia del ecosistema. | K30: =SUBSTITUTE(SUBSTITUTE(SUBSTITUTE(SUBSTITUTE(_xlfn.TRANSLATE(SUBSTITUTE(SUBSTITUTE(SUBSTITUTE(SUBSTITUTE(__TR_HORIZONTAL!K30,"Open Banking","XQZ0QX"),"BIAN","XQZ1QX"),"APIs","XQZ2QX"),"API","XQZ3QX"),"en","es"),"XQZ0QX","Open Banking"),"XQZ1QX","BIAN"),"XQZ2QX","APIs"),"XQZ3QX","API") -> No se evidencia ningún producto sandbox específico de Open Banking en el marketplace o socio; las capacidades adyacentes utilizan Apigee, API Gateway, BIAN APIs y entornos sandbox/UAT.
