Workbook

Sheet Resumen
A1: Esfuerzo de Arquitectura de Solución — Proyectos APOLO N4 y TDC R4
A2: Análisis derivado de los planes de trabajo entregados · Corte de información según cada archivo
A4: NOTA METODOLÓGICA — Evidencia vs. Inferencia
A5: EVIDENCIA (dato del plan): ambos son planes de cronograma; la unidad registrada es DÍAS HÁBILES por actividad, no horas-hombre. Ningún archivo trae columna de horas ni HH asignadas a arquitectura. INFERENCIA (supuesto de este análisis): 'Horas' = Días hábiles × 8 h/día — es capacidad de calendario, no esfuerzo real. Las duraciones son de CALENDARIO y muchas corren en paralelo, por lo que las sumas reflejan CARGA AGREGADA DE TRABAJO, no la duración total del tramo.
A9: 1) RESUMEN DE ESFUERZO DE ARQUITECTURA
A10: # | B10: Proyecto | C10: # Actividades de arq. | D10: Días hábiles de arq. (∑) | E10: Horas de arq. (∑, ×8)
A11: 1 | B11: APOLO N4 — Certificación de Arquitectura (Sección 9) | C11: ='APOLO N4'!J1 -> 25 | D11: ='APOLO N4'!J2 -> 245 | E11: ='APOLO N4'!J3 -> 1960
A12: 2 | B12: TDC R4 — Actividades de Arquitectura de Solución | C12: ='TDC R4'!J1 -> 19 | D12: ='TDC R4'!J2 -> 350 | E12: ='TDC R4'!J3 -> 2800
B13: TOTAL AMBOS PROYECTOS | C13: =SUM(C11:C12) -> 44 | D13: =SUM(D11:D12) -> 595 | E13: =SUM(E11:E12) -> 4760
A15: 2) PROPORCIÓN: ARQUITECTURA vs. ESFUERZO TOTAL DEL PROYECTO
A16: # | B16: Proyecto | C16: Días de arq. (∑) | D16: Días TOTALES del proyecto (∑) | E16: % Arquitectura | F16: Relación aprox.
A17: 1 | B17: APOLO N4 | C17: =D11 -> 245 | D17: ='APOLO N4'!J4 -> 3560 | E17: =C17/D17 -> 0.068820225 | F17: ="1 de cada "&ROUND(D17/C17,0)&" días" -> 1 de cada 15 días
A18: 2 | B18: TDC R4 | C18: =D12 -> 350 | D18: ='TDC R4'!J4 -> 4913.75 | E18: =C18/D18 -> 0.071228695 | F18: ="1 de cada "&ROUND(D18/C18,0)&" días" -> 1 de cada 14 días
B19: TOTAL / PROMEDIO PONDERADO | C19: =SUM(C17:C18) -> 595 | D19: =SUM(D17:D18) -> 8473.75 | E19: =C19/D19 -> 0.070216846 | F19: ="1 de cada "&ROUND(D19/C19,0)&" días" -> 1 de cada 14 días
A21: Base de la proporción (evidencia): 'Días TOTALES del proyecto' = suma de la duración de TODAS las actividades-hoja de cada plan (APOLO: hoja 'Detallado Completo'; TDC: hoja 'UNITY R4 - COPIA'), no solo las de arquitectura. El % es la participación de la carga de arquitectura dentro de la carga total registrada en el cronograma. Como las tareas corren en paralelo, es un indicador de PROPORCIÓN DE ESFUERZO/CARGA, no de porcentaje del tiempo calendario del proyecto. Si el equipo de arquitectura trabaja a dedicación parcial, el % real de HH de arquitectura sería aún menor.

Sheet APOLO N4
A1: APOLO N4 · Esfuerzo de Arquitectura de Solución (Sección 9 – Certificación de Arquitectura) | J1: =B4 -> 25
A2: TOTALES DE ARQUITECTURA (solo actividades-hoja; filas de fase en azul NO suman): | J2: =D4 -> 245
A3: Concepto → | B3: # Actividades de arquitectura | D3: Días hábiles de trabajo de arquitectura (∑ duración de tareas) | F3: Horas-persona de arquitectura (∑ días × 8 h/día) · INFERENCIA | J3: =F4 -> 1960
A4: Valor → | B4: =SUM(H7:H41) -> 25 | D4: =SUMPRODUCT(F7:F41,H7:H41) -> 245 | F4: =SUMPRODUCT(G7:G41,H7:H41) -> 1960 | J4: 3560
A6: ID | B6: Actividad de Arquitectura | C6: Responsable / Equipo | D6: Fecha Inicio | E6: Fecha Fin | F6: Días hábiles | G6: Horas (días×8)
A7: 9 | B7: Certificación de Arquitectura (fase) | C7: Arquitectura de Solución | D7: 46121 | E7: 46266 | F7: 104 | H7: 0
A8: 9.1 | B8: Generación de artefacto Arquitectura General de Solución | C8: Arquitectura de Solución | D8: 46140 | E8: 46146 | F8: 5 | G8: =F8*8 -> 40 | H8: 1
A9: 9.1.1 | B9: Análisis de Matriz/Concentrado de Hallazgos de Unity | C9: Arquitectura de Solución | D9: 46140 | E9: 46141 | F9: 2 | G9: =F9*8 -> 16 | H9: 1
A10: 9.2 | B10: Generación de artefacto Modelado de Datos y MER | C10: Arquitectura de Solución | D10: 46140 | E10: 46146 | F10: 5 | G10: =F10*8 -> 40 | H10: 1
A11: 9.3 | B11: Generación de artefacto Especificación de Servicio | C11: Arquitectura de Solución | D11: 46121 | E11: 46203 | F11: 59 | H11: 0
A12: 9.3.1 | B12: Especificación del servicio | C12: Arquitectura de Solución | D12: 46121 | E12: 46168 | F12: 34 | G12: =F12*8 -> 272 | H12: 1
A13: 9.3.2 | B13: Tabla API Operations | C13: Arquitectura de Solución | D13: 46199 | E13: 46203 | F13: 3 | G13: =F13*8 -> 24 | H13: 1
A14: 9.4 | B14: Generación de artefacto Especificación Front End | C14: Arquitectura de Solución | D14: 46157 | E14: 46203 | F14: 33 | H14: 0
A15: 9.4.1 | B15: Especificación Front End | C15: Arquitectura de Solución | D15: 46157 | E15: 46162 | F15: 4 | G15: =F15*8 -> 32 | H15: 1
A16: 9.5 | B16: Levantar ticket de certificación de Arquitectura (#13045614) | C16: Arquitectura de Solución | D16: 46162 | E16: 46162 | F16: 1 | G16: =F16*8 -> 8 | H16: 1
A17: 9.6 | B17: Validar artefactos de Arquitectura | C17: Arquitectura de Solución | D17: 46162 | E17: 46209 | F17: 34 | H17: 0
A18: 9.6.1 | B18: Revisión de artefactos y atención de observaciones | C18: Arquitectura de Solución | D18: 46162 | E18: 46205 | F18: 32 | G18: =F18*8 -> 256 | H18: 1
A19: 9.6.2 | B19: JQ-01: Catálogo de errores tabla 5 — faltan ejemplos de logs | C19: Arquitectura de Solución | D19: 46184 | E19: 46203 | F19: 14 | G19: =F19*8 -> 112 | H19: 1
A20: 9.6.3 | B20: ME-01: Vista incremental TO BE vs AS IS (arquitectura cloud) | C20: Arquitectura de Solución | D20: 46183 | E20: 46198 | F20: 12 | G20: =F20*8 -> 96 | H20: 1
A21: 9.6.4 | B21: ME-02: Diagramas complementarios N4 con interfaces | C21: Arquitectura de Solución | D21: 46183 | E21: 46198 | F21: 12 | G21: =F21*8 -> 96 | H21: 1
A22: 9.6.5 | B22: ME-03: Matriz hallazgos Modyo→WebMethods | C22: Arquitectura de Solución | D22: 46183 | E22: 46203 | F22: 15 | G22: =F22*8 -> 120 | H22: 1
A23: 9.6.6 | B23: VoBo Arq. Industria (Ticket #13376605) | C23: Arq. de Industria y Arq. de Solución | D23: 46203 | E23: 46209 | F23: 5 | G23: =F23*8 -> 40 | H23: 1
A24: 9.7 | B24: Matriz de comunicaciones (para gestión de tickets) | C24: Arq. Soluciones | D24: 46176 | E24: 46227 | F24: 38 | H24: 0
A25: 9.7.1 | B25: Análisis para generación de matriz | C25: Arq. Soluciones / Homologación Ambientes | D25: 46183 | E25: 46227 | F25: 33 | G25: =F25*8 -> 264 | H25: 1
A26: 9.8 | B26: Solicitar validación Arquitectura por Capas | C26: Arq. de Industria y Arq. de Solución | D26: 46209 | E26: 46209 | F26: 1 | G26: =F26*8 -> 8 | H26: 1
A27: 9.8.1 | B27: Solicitar VoBo (Cloud, Seguridad, Integración, Desarrollo, Datos) | C27: Arq. de Industria y Arq. de Solución | D27: 46209 | E27: 46209 | F27: 1 | G27: =F27*8 -> 8 | H27: 1
A28: 9.9 | B28: Gestionar sesiones de entendimiento (arquitectos de capas) | C28: Arq. de Industria y Arq. de Solución | D28: 46210 | E28: 46212 | F28: 3 | G28: =F28*8 -> 24 | H28: 1
A29: 9.10 | B29: Validación con Arq. Cloud | C29: Arq. Cloud | D29: 46213 | E29: 46233 | F29: 15 | H29: 0
A30: 9.10.1 | B30: Revisión de artefactos de Arq. de Industria | C30: Arq. Cloud | D30: 46213 | E30: 46233 | F30: 15 | G30: =F30*8 -> 120 | H30: 1
A31: 9.11 | B31: Validación con Arq. Seguridad y Biometría | C31: Arq. Seguridad y Biometría | D31: 46234 | E31: 46241 | F31: 6 | H31: 0
A32: 9.11.1 | B32: Revisión de artefactos de Arq. Seguridad y atención de obs. | C32: Arq. Ind. / Sol. / Seg. y Biom. | D32: 46234 | E32: 46241 | F32: 6 | G32: =F32*8 -> 48 | H32: 1
A33: 9.12 | B33: Matriz de Configuraciones (Plantilla Mapeo Configuraciones) | C33: Apificación | D33: 46217 | E33: 46238 | F33: 16 | G33: =F33*8 -> 128 | H33: 1
A34: 9.13 | B34: Validación con Arq. Integración | C34: Arq. Integración | D34: 46244 | E34: 46251 | F34: 6 | H34: 0
A35: 9.13.1 | B35: Revisión de artefactos de Arq. de Integración | C35: Arq. Ind. / Sol. / Integración | D35: 46244 | E35: 46251 | F35: 6 | G35: =F35*8 -> 48 | H35: 1
A36: 9.14 | B36: Validación con Arq. Desarrollo | C36: Arq. Desarrollo | D36: 46252 | E36: 46262 | F36: 9 | H36: 0
A37: 9.14.1 | B37: Revisión de artefactos de Arq. Desarrollo | C37: Arq. Ind. / Sol. / Desarrollo | D37: 46252 | E37: 46262 | F37: 9 | G37: =F37*8 -> 72 | H37: 1
A38: 9.15 | B38: Validación con Arq. Datos | C38: Arq. Datos | D38: 46252 | E38: 46262 | F38: 9 | H38: 0
A39: 9.15.1 | B39: Revisión de artefactos de Arq. Datos | C39: Arq. Ind. / Sol. / Datos | D39: 46252 | E39: 46262 | F39: 9 | G39: =F39*8 -> 72 | H39: 1
A40: 9.16 | B40: Determinar resultado de la certificación | C40: Arquitectura de Industria | D40: 46265 | E40: 46265 | F40: 1 | G40: =F40*8 -> 8 | H40: 1
A41: 9.17 | B41: Entregar Certificación o Pre-certificación | C41: Arquitectura de Industria | D41: 46266 | E41: 46266 | F41: 1 | G41: =F41*8 -> 8 | H41: 1
...

Sheet TDC R4
A1: TDC R4 · Actividades consolidadas de Arquitectura de Solución | J1: =B4 -> 19
A2: TOTALES DE ARQUITECTURA (solo actividades-hoja; filas de fase en azul NO suman): | J2: =D4 -> 350
A3: Concepto → | B3: # Actividades de arquitectura | D3: Días hábiles de trabajo de arquitectura (∑ duración de tareas) | F3: Horas-persona de arquitectura (∑ días × 8 h/día) · INFERENCIA | J3: =F4 -> 2800
A4: Valor → | B4: =SUM(H7:H25) -> 19 | D4: =SUMPRODUCT(F7:F25,H7:H25) -> 350 | F4: =SUMPRODUCT(G7:G25,H7:H25) -> 2800 | J4: 4913.75
A6: ID | B6: Actividad de Arquitectura | C6: Responsable / Equipo | D6: Fecha Inicio | E6: Fecha Fin | F6: Días hábiles | G6: Horas (días×8)
A7: R4-73 | B7: Diagrama de Arquitectura de Solución (Maquila Automatizada) | C7: Arquitectura de Solución | D7: 46237 | E7: 46248 | F7: 10 | G7: =F7*8 -> 80 | H7: 1
A8: R4-74 | B8: Sizing para Componente Administración de Tarjetas | C8: Arquitectura de Solución | D8: 46237 | E8: 46248 | F8: 10 | G8: =F8*8 -> 80 | H8: 1
A9: R4-75 | B9: Identificar NFS SVCG - SVBO y Nuevo Componente | C9: Arquitectura de Solución | D9: 46237 | E9: 46248 | F9: 10 | G9: =F9*8 -> 80 | H9: 1
A10: R4-93 | B10: Validación de NFS para Intercambio de Archivos | C10: Arquitectura de Solución | D10: 46243 | E10: 46316 | F10: 54 | G10: =F10*8 -> 432 | H10: 1
A11: R4-127 | B11: Generación de NFS entre SVIP y SVCG (Ambientes SmartVista) | C11: Armando García Ortiz / Arq. | D11: 46352 | E11: 46367 | F11: 12 | G11: =F11*8 -> 96 | H11: 1
A12: R4-270 | B12: Solicitud de Sizing a BPC – Componente Fraud Management (SVFM) | C12: BPC / Arquitectura | D12: 46179 | E12: 46192 | F12: 10 | G12: =F12*8 -> 80 | H12: 1
A13: R4-279 | B13: Actualización de Diagrama de Solución (SVFM) | C13: Arquitectura de Solución | D13: 46199 | E13: 46220 | F13: 16 | G13: =F13*8 -> 128 | H13: 1
A14: R4-280 | B14: Generar ticket de arquitectura para contemplar el SVFM - DEV | C14: Armando García Ortiz / Arq. | D14: 46199 | E14: 46220 | F14: 16 | G14: =F14*8 -> 128 | H14: 1
A15: R4-281 | B15: Generar ticket de arquitectura para contemplar el SVFM - QA | C15: Armando García Ortiz / Arq. | D15: 46199 | E15: 46220 | F15: 16 | G15: =F15*8 -> 128 | H15: 1
A16: R4-282 | B16: Generar ticket de arquitectura para contemplar el SVFM - UAT | C16: Armando García Ortiz / Arq. | D16: 46199 | E16: 46220 | F16: 16 | G16: =F16*8 -> 128 | H16: 1
A17: R4-720 | B17: Diseño de Contratos de API y Arquitectura SV | C17: Patricia A. Tovar Moctezuma | D17: 46251 | E17: 46262 | F17: 10 | G17: =F17*8 -> 80 | H17: 1
A18: R4-751 | B18: Revisión Diseño de Arquitectura ICCAT | C18: Ramses Santos | D18: 46181 | E18: 46192 | F18: 10 | G18: =F18*8 -> 80 | H18: 1
... A25: R4-765 | B25: Diagrama de Secuencia | C25: Ramses Santos | D25: 46223 | E25: 46255 | F25: 25 | G25: =F25*8 -> 200 | H25: 1
A27: Fuente: 'Plan_de_Trabajo_UNITY_R4_200726' → hoja 'UNITY R4 - COPIA'. Se renombra el proyecto como TDC R4. Las tareas de arquitectura no están agrupadas: se consolidan aquí (diagramas, sizing, NFS/NFR, contratos API, tickets de arquitectura). Cifras en DÍAS HÁBILES (evidencia); horas por INFERENCIA (días×8). Diagramas duplicados (filas 775–780 del plan) omitidos por ser copia de 760–765.

Sheet Tipos de Actividad
A1: Tipos de actividad de Arquitectura de Solución identificados
A3: # | B3: Categoría | C3: Actividades incluidas
A4: 1 | B4: Generación de artefactos de diseño | C4: Arquitectura General de Solución, Modelado de Datos/MER, Especificación de Servicio, Tabla API Operations, Especificación Front End, Diagramas (General, Tecnológica/Seguridad, Componentes, Flujo, Interfaz, Secuencia).
A5: 2 | B5: Definición de integración / APIs | C5: Diseño de Contratos de API y Arquitectura SV, especificación de servicios/operaciones.
A6: 3 | B6: NFR / NFS (No Funcionales) | C6: Identificación y validación de NFS entre ambientes/componentes SmartVista (SVCG-SVBO-SVIP), NFS de intercambio de archivos.
A7: 4 | B7: Sizing y capacidad | C7: Sizing de componentes (Administración de Tarjetas, Fraud Management SVFM).
A8: 5 | B8: Gestión de certificación | C8: Levantar/gestionar tickets de certificación, matriz de comunicaciones, determinar y entregar certificación o pre-certificación.
A9: 6 | B9: Validación por capas (VoBo) | C9: Revisión y VoBo de Arq. Cloud, Seguridad y Biometría, Integración, Desarrollo, Datos e Industria; sesiones de entendimiento.
A10: 7 | B10: Atención de hallazgos | C10: Resolución de observaciones (JQ-01, ME-01/02/03), matriz de hallazgos Modyo→WebMethods, matriz de configuraciones.
