Workbook

Sheet Definiciones
B2: Inventario de HUs — Programa Unity / R4
B11: Definición de criterios
B13: Prioridad MoSCoW
B14: Must | C14: La historia es absolutamente necesaria para que R4 pueda salir a producción y cumplir sus objetivos. Si esta Historia no se implementa: - El release no puede desplegarse. - Se incumple un requisito regulatorio. - Se genera un riesgo operativo crítico. - El cliente no puede utilizar el producto. - Se rompe un proceso end-to-end imprescindible Pregunta clave --> ¿Cancelaríamos o retrasaríamos R4 si esta historia no estuviera disponible? Si la respuesta es "Sí", probablemente sea un MUST. Ejemplos:Alta de tarjeta de crédito clásica física para nuevos clientes desde canales digitales, creación de cuenta crédito en Apolo, generación y sincronización del contrato de crédito, Interfaces obligatorias con SmartVista para creación de tarjeta, validaciones regulatorias de KYC requeridas para la contratación, contabilización obligatoria de la apertura de producto, Servicios críticos necesarios para autorización de transacciones.
B15: Should | C15: La historia aporta mucho valor al negocio, pero el release podría salir sin ella mediante una solución temporal o con ciertas restricciones operativas. No compromete la viabilidad del Go-Live. Debe estar en R4 si la capacidad lo permite; si no, va a R4.1 Pregunta clave --> ¿Podemos salir a producción sin esta historia durante algunas semanas o meses, aunque genere incomodidades o trabajo manual? Si la respuesta es "Sí", probablemente sea un SHOULD. Ejemplos: Mejoras de experiencia de usuario en la solicitud, Notificaciones push adicionales, Consultas ampliadas de estatus de tarjeta., Automatización parcial de reportes internos., Dashboard operativo para monitoreo del proceso, Automatización de conciliaciones no críticas
B16: Could | C16: Historias deseables que aportan valor incremental, pero cuyo impacto es limitado. Si no llegan a R4, prácticamente no afectan los objetivos del release. Pregunta clave --> ¿El negocio seguiría funcionando prácticamente igual si esta historia se implementa después del Go-Live? Si la respuesta es "Sí", probablemente sea un COULD. Ejemplos: nuevos filtros de búsqueda, mejoras estéticas de pantalla, mensajería enriquecida al cliente, reportes complementarios, métricas avanzadas de monitoreo, funcionalidades de convivencia para usuarios internos
B17: Won't | C17: Historias explícitamente excluidas de R4/R4.1. No significa que sean malas ideas, significa que no forman parte del alcance comprometido para este release. Pregunta clave --> ¿Estamos de acuerdo en que esta historia se moverá a un release futuro? Ejemplos: funcionalidades previstas para R5 o posteriores, mejoras arquitectónicas no necesarias para R4, automatizaciones futuras, capacidades avanzadas que no afectan la expansión actual de TDC Física.
B19: Complejidad técnica
B20: Alta | C20: Basado en reglas que involucran número de integraciones, impacto y reusabilidad de la solución, número de pantallas y criterios de aceptación de la solución. Ver pestaña "Scoring Complejidad" donde se describe la lógica de estas reglas
B21: Media
B22: Baja
B24: Tipo de HU Solución / Integración
B25: Solución | C25: Los cambios necesarios se realizan exclusivamente dentro de una o varias aplicaciones o plataformas, sin necesidad de crear nuevas integraciones ni modificar integraciones existentes. La historia puede consumir información procedente de otras aplicaciones siempre que las interfaces existentes puedan reutilizarse sin cambios. Pregunta guia--> ¿La historia puede implementarse sin crear ni modificar ninguna interfaz existente? Si la respuesta es Sí, la HU debe clasificarse como Solución. Ejemplo 1: Nueva pantalla para visualizar información de una tarjeta utilizando APIs ya existentes (Motivo: existe desarrollo funcional, pero ninguna integración requiere cambios) Ejemplo 2: Nueva regla para determinar la elegibilidad de clientes para una Tarjeta de Crédito (Motivo: el cambio ocurre dentro del motor de negocio) Ejemplo 3: Nuevo dashboard operativo utilizando información ya disponible en la plataforma.(Motivo: no se crean ni modifican interfaces)
B26: Integración | C26: El objetivo principal es crear una nueva integración o modificar una integración existente entre sistemas — vía API, Batch, Evento, Archivo, MQ, SOAP o REST — . El valor de la historia reside en habilitar o modificar el intercambio de información entre aplicaciones. Importante: La simple utilización de una integración existente NO convierte una HU en Integración. Para ser considerada Integración debe existir: una nueva integración o una modificación de una interfaz existente Pregunta guia--> ¿La historia requiere crear una nueva integración o modificar una integración existente? Si la respuesta es Sí y no existen cambios funcionales relevantes, la HU debe clasificarse como Integración Ejemplo 1: Nueva API entre Apolo y SmartVista para creación de tarjetas Ejemplo 2: Modificación de una interfaz existente para incorporar nuevos atributos de la Tarjeta de Crédito Clásica Física. Ejemplo 3: Nuevo archivo batch diario para enviar movimientos a Contabilidad.
B27: Solución e integración | C27: Requiere simultáneamente: 1) Cambios funcionales dentro de una aplicación. 2) Creación de nuevas integraciones o modificaciones de integraciones existentes. Pregunta guia--> ¿La funcionalidad requiere cambios en la experiencia o proceso de negocio y además intercambio de información entre sistemas? Si la respuesta es sí, estamos ante una HU de Solución + Integración.
B29: Impacto Solución
B30: Caja | C30: La funcionalidad requerida ya está disponible y puede utilizarse sin realizar configuraciones relevantes ni desarrollos adicionales para R4.Esto incluye dos escenarios: -Funcionalidad estándar de la plataforma: la capacidad ya existe de forma nativa en la solución. -Funcionalidad ya desarrollada en releases previos:Aunque originalmente requirió desarrollo, dicho desarrollo ya existe y puede reutilizarse en R4 sin cambios adicionales
B31: Configuración | C31: La funcionalidad existe en la plataforma, pero requiere parametrización o ajustes de configuración para adaptarla a las necesidades de R4. No es necesario desarrollar software nuevo, lo que cambia son los parámetros, reglas o datos maestros Ejemplos: parametrización de productos, configuración de tarifas/límites/perfiles/catálogos, configuración de reglas ya soportadas por la plataforma
B32: Desarrollo | C32: Se requiere construir capacidades nuevas que actualmente no existen en la plataforma y que no pueden resolverse mediante configuración. La plataforma necesita código nuevo para satisfacer el requerimiento.
B33: Desarrollo + Configuración | C33: Una Historia de Usuario se clasifica como Desarrollo + Configuración cuando requiere simultáneamente: - Construcción de nuevas capacidades. - Parametrización de funcionalidades. - Configuración de productos o reglas. - Ajustes de la solución para habilitar el funcionamiento final.
B34: No Aplica | C34: La HU es de integración pura, por lo que el impacto de la solución no aplica como categoría de clasificación.

Sheet Inventario HUs
A1: IDENTIFICACIÓN | F1: ALCANCE | J1: PRIORIDAD E IMPACTO | Q1: MEDICIÓN DE COMPLEJIDAD | W1: Analisis (DEF, Mesas Trabajo, Refinamiento, VoBo) | Y1: Diseño (DTM, DTC , certificaciones Diagramas de flujo) | AA1: Implementación (construcción, pruebas unitarias, y pruebas Product Test) | AC1: Comentarios | AD1: Fecha de última modificación
A2: ID HU | B2: Track / Plataforma | C2: Descripción corta | D2: Producto | E2: Funcionalidad / BB | F2: Descripción Funcional (qué hace) | G2: Reglas de Negocio Clave | H2: Canal(es) Afectado(s) | I2: Usuario Final / Actor Principal | J2: Prioridad MoSCoW | K2: Solución / Integración | L2: # Integraciones | M2: Impacto Solución | N2: Reusabilidad de Solución | O2: # de Criterios de aceptación | P2: # de Pantallas (nuevas o modificadas) | Q2: Calificación Criterios de Aceptación | R2: Calificación Pantallas Asociadas | S2: Calificación Reusabilidad | T2: Calificación de Integraciones | U2: Score Ponderado | V2: Complejidad Total | W2: Fecha Inicio | X2: Fecha Fin | Y2: Fecha Inicio | Z2: Fecha Fin | AA2: Fecha Inicio | AB2: Fecha Fin+J1:ABW1:AB2
A3: HDU-SMART-R4-01 | B3: Smart Vista | C3: Certificar layouts de maquila con proveedores. | D3: TDC | E3: Automatización de Maquila | F3: Habilitar la certificación de layouts posicionales/planos homologados para los 4 proveedores de maquila (GID, Forza, TGS, Thomas Greg & Sons), con cifrado PGP por proveedor y HSM por tarjeta, para emitir tarjetas del producto 4900 de forma controlada y trazable. | G3: Layout único homologado para los 4 maquiladores. Campos alfanuméricos validados para rechazar caracteres no embosables. Cifrado PGP+HSM; vigencia de llaves validada antes de generar. Reproceso de archivo sin alterar números de tarjeta. Solo producto 4900 parametrizado en | H3: Smart Vista | I3: Área de Suministros / Administración de Tarjetas | J3: Must | K3: Solución | L3: 0 | M3: Desarrollo + Configuración | N3: Componentes existentes reutilizables >80% | O3: 5 | P3: 0 | Q3: {=+_xlfn.IFS(O3="","",O3<=1,"Baja",O3<=3,"Media",O3>3,"Alta")} -> Alta | R3: {=+_xlfn.IFS(P3="","",P3<=0,"Baja",P3<=2,"Media",P3>2,"Alta")} -> Baja | S3: {=+_xlfn.IFS(N3="","",N3="Componentes existentes reutilizables >80%","Baja",N3="No Aplica","Baja",N3="Reutilización parcial 30-70%","Media",N3="Nuevo Desarrollo <20%","Alta")} -> Baja | T3: {=+_xlfn.IFS(L3="","",L3=0,"Baja",L3<=2,"Media",L3>=3,"Alta")} -> Baja | U3: {=+IFERROR((+_xlfn.IFS(Q3="",0,Q3="Baja",1,Q3="Media",2,Q3="Alta",3)*'Scoring Complejidad'!$C$8+_xlfn.IFS(R3="Baja",1,R3="Media",2,R3="Alta",3)*'Scoring Complejidad'!$C$9+_xlfn.IFS(S3="Baja",1,S3="Media",2,S3="Alta",3)*'Scoring Complejidad'!$C$7+_xlfn.IFS(T3="",1,T3="Baja",1,T3="Media",2,T3="Alta",3)*'Scoring Complejidad'!$C$5+_xlfn.IFS(M3="Caja",1,M3="Configuración",2,M3="Desarrollo",3,M3="Desarrollo + Configuración",3,M3="No Aplica",0)*'Scoring Complejidad'!$C$6),"")} -> 1.8 | V3: {=IFERROR(_xlfn.IFS(U3="","",U3<=1.69,"Baja",U3<=2.29,"Media",U3<=3,"Alta",U3>3,"Error"),"")} -> Media | W3: 06/07/206 | X3: 20/07/206 | Y3: 21/07/206 | Z3: 04/09/206 | AA3: 17/08/206 | AB3: 30/10/206 | AC3: Certificación de layouts y llaves de PGP- Diseño Con tiempos controlados de desarrollo de la HU Considerar 15 días menos de implementación como supuesto de reducción de alcance a un solo proveedor (proveedor prioritario) de maquila. Considerar que Pruebas de maquila son independientes y no van por la ruta crítica | AD3: 46240
A4: HDU-SMART-R4-02 | B4: Smart Vista | C4: Consultar inventario de tarjetas por sucursal. | D4: TDC | E4: Automatización de Maquila | F4: Consulta del stock de tarjetas disponibles por sucursal distinguiendo 'en existencia', 'en ruta' y 'por fabricar'; cálculo de stock semanal sobre existencias reales; filtro por tipo de sucursal. El inventario vive íntegramente en Smart Vista, sin dependencia de Macweb. | G4: Stock semanal basado SOLO en existencias físicas (no en ruta/por fabricar). Filtro por Tipo de Sucursal. Detalle de lotes en proceso por producto/sucursal. Datos provienen de SV, ruptura con . | H4: Smart Vista | I4: Área de Suministros | J4: Should | K4: Solución | L4: 0 | M4: Desarrollo + Configuración | N4: Nuevo Desarrollo <20% | O4: 4 | P4: 1 | Q4: {=+_xlfn.IFS(O4="","",O4<=1,"Baja",O4<=3,"Media",O4>3,"Alta")} -> Alta | R4: {=+_xlfn.IFS(P4="","",P4<=0,"Baja",P4<=2,"Media",P4>2,"Alta")} -> Media | S4: {=+_xlfn.IFS(N4="","",N4="Componentes existentes reutilizables >80%","Baja",N4="No Aplica","Baja",N4="Reutilización parcial 30-70%","Media",N4="Nuevo Desarrollo <20%","Alta")} -> Alta | T4: {=+_xlfn.IFS(L4="","",L4=0,"Baja",L4<=2,"Media",L4>=3,"Alta")} -> Baja | U4: {=+IFERROR((+_xlfn.IFS(Q4="",0,Q4="Baja",1,Q4="Media",2,Q4="Alta",3)*'Scoring Complejidad'!$C$8+_xlfn.IFS(R4="Baja",1,R4="Media",2,R4="Alta",3)*'Scoring Complejidad'!$C$9+_xlfn.IFS(S4="Baja",1,S4="Media",2,S4="Alta",3)*'Scoring Complejidad'!$C$7+_xlfn.IFS(T4="",1,T4="Baja",1,T4="Media",2,T4="Alta",3)*'Scoring Complejidad'!$C$5+_xlfn.IFS(M4="Caja",1,M4="Configuración",2,M4="Desarrollo",3,M4="Desarrollo + Configuración",3,M4="No Aplica",0)*'Scoring Complejidad'!$C$6),"")} -> 2.3 | V4: {=IFERROR(_xlfn.IFS(U4="","",U4<=1.69,"Baja",U4<=2.29,"Media",U4<=3,"Alta",U4>3,"Error"),"")} -> Alta | W4: 06/07/206 | X4: 20/07/206 | Y4: 21/07/206 | Z4: 04/09/206 | AA4: 17/08/206 | AB4: 30/10/206 | AC4: Considerar 15 días menos de implementación como supuesto de reducción de alcance a un solo proveedor (proveedor prioritario) de maquila. Considerar que Pruebas de maquila son independientes y no van por la ruta crítica | AD4: 46240
A5: HDU-SMART-R4-03 | B5: Smart Vista | C5: Calcular maquila con parámetros de abasto. | D5: TDC | E5: Automatización de Maquila | F5: Cálculo diario automatizado (batch 6:00 AM) de la cantidad de tarjetas a reordenar por sucursal/producto, usando piso mínimo y semanas-a-dotar parametrizables, con redondeo a múltiplos de 250 plásticos y consumo calculado sobre mes calendario completo. | G5: Corrida batch 6:00 AM. Piso mínimo default 4 semanas, parametrizable por producto/sucursal . Semanas a dotar de 1 a N (hoy topado a 3). Redondeo a múltiplos de 250. Consumo sobre mes calendario completo, no ventana fija. | H5: Smart Vista | I5: Área de Suministros | J5: Should | K5: Solución | L5: 0 | M5: Desarrollo + Configuración | N5: Nuevo Desarrollo <20% | O5: 4 | P5: 0 | Q5: {=+_xlfn.IFS(O5="","",O5<=1,"Baja",O5<=3,"Media",O5>3,"Alta")} -> Alta | R5: {=+_xlfn.IFS(P5="","",P5<=0,"Baja",P5<=2,"Media",P5>2,"Alta")} -> Baja | S5: {=+_xlfn.IFS(N5="","",N5="Componentes existentes reutilizables >80%","Baja",N5="No Aplica","Baja",N5="Reutilización parcial 30-70%","Media",N5="Nuevo Desarrollo <20%","Alta")} -> Alta | T5: {=+_xlfn.IFS(L5="","",L5=0,"Baja",L5<=2,"Media",L5>=3,"Alta")} -> Baja | U5: {=+IFERROR((+_xlfn.IFS(Q5="",0,Q5="Baja",1,Q5="Media",2,Q5="Alta",3)*'Scoring Complejidad'!$C$8+_xlfn.IFS(R5="Baja",1,R5="Media",2,R5="Alta",3)*'Scoring Complejidad'!$C$9+_xlfn.IFS(S5="Baja",1,S5="Media",2,S5="Alta",3)*'Scoring Complejidad'!$C$7+_xlfn.IFS(T5="",1,T5="Baja",1,T5="Media",2,T5="Alta",3)*'Scoring Complejidad'!$C$5+_xlfn.IFS(M5="Caja",1,M5="Configuración",2,M5="Desarrollo",3,M5="Desarrollo + Configuración",3,M5="No Aplica",0)*'Scoring Complejidad'!$C$6),"")} -> 2.2 | V5: {=IFERROR(_xlfn.IFS(U5="","",U5<=1.69,"Baja",U5<=2.29,"Media",U5<=3,"Alta",U5>3,"Error"),"")} -> Media | W5: 06/07/206 | X5: 20/07/206 | Y5: 21/07/206 | Z5: 04/09/206 | AA5: 17/08/206 | AB5: 30/10/206 | AC5: Mayor complejidad para llegar a tiempo en fin de análisis Considerar 15 días menos de implementación como supuesto de reducción de alcance a un solo proveedor (proveedor prioritario) de maquila. Considerar que Pruebas de maquila son independientes y no van por la ruta crítica | AD5: 46240
A6: HDU-SMART-R4-04 | B6: Smart Vista | C6: Ejecutar solicitud automatizada de maquila. | D6: TDC | E6: Automatización de Maquila | F6: Detona el proceso de emisión masiva de tarjetas tras el cálculo de reorden. Incluye validación anti-duplicidad, pre-asignación de proveedor, notificación por correo a ~30 destinatarios usando número de lote. Dos pasos pendientes de automatizar en R4: generación OCG vía Cron y entrega Connect Direct. | G6: Solicitud se detona solo si layout tiene datos completos . Anti-duplicidad: si existe solicitud en mismo layout se rechaza . Pre-asignación de proveedor por matriz de capacidades o manual. Correo diario ~30 destinatarios con número de lote. | H6: Smart Vista | I6: Área de Suministros | J6: Must | K6: Solución | L6: 0 | M6: Desarrollo + Configuración | N6: Nuevo Desarrollo <20% | O6: 3 | P6: 0 | Q6: {=+_xlfn.IFS(O6="","",O6<=1,"Baja",O6<=3,"Media",O6>3,"Alta")} -> Media | R6: {=+_xlfn.IFS(P6="","",P6<=0,"Baja",P6<=2,"Media",P6>2,"Alta")} -> Baja | S6: {=+_xlfn.IFS(N6="","",N6="Componentes existentes reutilizables >80%","Baja",N6="No Aplica","Baja",N6="Reutilización parcial 30-70%","Media",N6="Nuevo Desarrollo <20%","Alta")} -> Alta | T6: {=+_xlfn.IFS(L6="","",L6=0,"Baja",L6<=2,"Media",L6>=3,"Alta")} -> Baja | U6: {=+IFERROR((+_xlfn.IFS(Q6="",0,Q6="Baja",1,Q6="Media",2,Q6="Alta",3)*'Scoring Complejidad'!$C$8+_xlfn.IFS(R6="Baja",1,R6="Media",2,R6="Alta",3)*'Scoring Complejidad'!$C$9+_xlfn.IFS(S6="Baja",1,S6="Media",2,S6="Alta",3)*'Scoring Complejidad'!$C$7+_xlfn.IFS(T6="",1,T6="Baja",1,T6="Media",2,T6="Alta",3)*'Scoring Complejidad'!$C$5+_xlfn.IFS(M6="Caja",1,M6="Configuración",2,M6="Desarrollo",3,M6="Desarrollo + Configuración",3,M6="No Aplica",0)*'Scoring Complejidad'!$C$6),"")} -> 2.05 | V6: {=IFERROR(_xlfn.IFS(U6="","",U6<=1.69,"Baja",U6<=2.29,"Media",U6<=3,"Alta",U6>3,"Error"),"")} -> Media | W6: 06/07/206 | X6: 20/07/206 | Y6: 21/07/206 | Z6: 04/09/206 | AA6: 17/08/206 | AB6: 30/10/206 | AC6: Mayor complejidad para llegar a tiempo en fin de análisis Considerar 15 días menos de implementación como supuesto de reducción de alcance a un solo proveedor (proveedor prioritario) de maquila. Considerar que Pruebas de maquila son independientes y no van por la ruta crítica | AD6: 46240
A7: HDU-SMART-R4-05 | B7: Smart Vista | C7: Ejecutar solicitud manual de maquila. | D7: TDC | E7: Automatización de Maquila | F7: Permite al área de Suministros generar solicitudes manuales de maquila para casos específicos (ej. apertura de sucursal), usando el mismo layout que la maquila automática. Restricción: un lote por día por sucursal. | G7: Solicitud manual usa layout único compartido con la automática. Dotación inicial garantizada ante apertura de sucursal nueva. Restricción: 1 lote/día/sucursal (proceso tarda 2-3 semanas). Funcionalidad demo confirmada en S1/S2. | H7: Smart Vista | I7: Área de Suministros | J7: Must | K7: Solución | L7: 0 | M7: Desarrollo + Configuración | N7: Reutilización parcial 30-70% | O7: 3 | P7: 1 | Q7: {=+_xlfn.IFS(O7="","",O7<=1,"Baja",O7<=3,"Media",O7>3,"Alta")} -> Media | R7: {=+_xlfn.IFS(P7="","",P7<=0,"Baja",P7<=2,"Media",P7>2,"Alta")} -> Media | S7: {=+_xlfn.IFS(N7="","",N7="Componentes existentes reutilizables >80%","Baja",N7="No Aplica","Baja",N7="Reutilización parcial 30-70%","Media",N7="Nuevo Desarrollo <20%","Alta")} -> Media | T7: {=+_xlfn.IFS(L7="","",L7=0,"Baja",L7<=2,"Media",L7>=3,"Alta")} -> Baja | U7: {=+IFERROR((+_xlfn.IFS(Q7="",0,Q7="Baja",1,Q7="Media",2,Q7="Alta",3)*'Scoring Complejidad'!$C$8+_xlfn.IFS(R7="Baja",1,R7="Media",2,R7="Alta",3)*'Scoring Complejidad'!$C$9+_xlfn.IFS(S7="Baja",1,S7="Media",2,S7="Alta",3)*'Scoring Complejidad'!$C$7+_xlfn.IFS(T7="",1,T7="Baja",1,T7="Media",2,T7="Alta",3)*'Scoring Complejidad'!$C$5+_xlfn.IFS(M7="Caja",1,M7="Configuración",2,M7="Desarrollo",3,M7="Desarrollo + Configuración",3,M7="No Aplica",0)*'Scoring Complejidad'!$C$6),"")} -> 1.95 | V7: {=IFERROR(_xlfn.IFS(U7="","",U7<=1.69,"Baja",U7<=2.29,"Media",U7<=3,"Alta",U7>3,"Error"),"")} -> Media | W7: 06/07/206 | X7: 20/07/206 | Y7: 21/07/206 | Z7: 04/09/206 | AA7: 17/08/206 | AB7: 30/10/206 | AC7: Considerar 15 días menos de implementación como supuesto de reducción de alcance a un solo proveedor (proveedor prioritario) de maquila. Considerar que Pruebas de maquila son independientes y no van por la ruta crítica | AD7: 46240
A8: HDU-SMART-R4-06 | B8: Smart Vista | C8: Generar archivos seguros de maquila. | D8: TDC | E8: Automatización de Maquila | F8: Generación y resguardo del archivo para el maquilador tras procesar la solicitud. Incluye cifrado PGP/HSM, flujo de 4 pasos (SVBO→OCG→Cargen→PGP→Connect Direct), trazabilidad Orden→Lote→Tarjeta, y alertamiento/reproceso ante error del maquilador. | G8: Flujo técnico: SVBO→OCG→Cargen→PGP→Connect Direct [Comentado en sesión]. Archivo cifrado con PGP del proveedor destino. Trazabilidad completa Orden→Lote→Tarjeta. Alertamiento y reproceso ante error de procesamiento en maquilador. | H8: Smart Vista | I8: Administrador de Maquila / Suministros | J8: Must | K8: Solución e Integración | L8: 2 | M8: Desarrollo + Configuración | N8: Reutilización parcial 30-70% | O8: 3 | P8: 1 | Q8: {=+_xlfn.IFS(O8="","",O8<=1,"Baja",O8<=3,"Media",O8>3,"Alta")} -> Media | R8: {=+_xlfn.IFS(P8="","",P8<=0,"Baja",P8<=2,"Media",P8>2,"Alta")} -> Media | S8: {=+_xlfn.IFS(N8="","",N8="Componentes existentes reutilizables >80%","Baja",N8="No Aplica","Baja",N8="Reutilización parcial 30-70%","Media",N8="Nuevo Desarrollo <20%","Alta")} -> Media | T8: {=+_xlfn.IFS(L8="","",L8=0,"Baja",L8<=2,"Media",L8>=3,"Alta")} -> Media | U8: {=+IFERROR((+_xlfn.IFS(Q8="",0,Q8="Baja",1,Q8="Media",2,Q8="Alta",3)*'Scoring Complejidad'!$C$8+_xlfn.IFS(R8="Baja",1,R8="Media",2,R8="Alta",3)*'Scoring Complejidad'!$C$9+_xlfn.IFS(S8="Baja",1,S8="Media",2,S8="Alta",3)*'Scoring Complejidad'!$C$7+_xlfn.IFS(T8="",1,T8="Baja",1,T8="Media",2,T8="Alta",3)*'Scoring Complejidad'!$C$5+_xlfn.IFS(M8="Caja",1,M8="Configuración",2,M8="Desarrollo",3,M8="Desarrollo + Configuración",3,M8="No Aplica",0)*'Scoring Complejidad'!$C$6),"")} -> 2.25 | V8: {=IFERROR(_xlfn.IFS(U8="","",U8<=1.69,"Baja",U8<=2.29,"Media",U8<=3,"Alta",U8>3,"Error"),"")} -> Media | W8: 06/07/206 | X8: 20/07/206 | Y8: 21/07/206 | Z8: 04/09/206 | AA8: 17/08/206 | AB8: 30/10/206 | AC8: Con tiempos controlados de desarrollo de la HU. Complejidad posterior podría estar en tiempos de llaves Integraciones archivo se baja a on premise y tarea programada que se manda a proveedor a través del canal seguro Considerar 15 días menos de implementación como supuesto de reducción de alcance a un solo proveedor (proveedor prioritario) de maquila. Considerar que Pruebas de maquila son independientes y no van por la ruta crítica | AD8: 46240
A9: HDU-SMART-R4-07 | B9: Smart Vista | C9: Dar seguimiento a estatus de lotes. | D9: TDC | E9: Automatización de Maquila | F9: Consulta del estatus de emisión y entrega de lotes por sucursal (Inventario POS), incluyendo seguimiento de paquetería desde recolección hasta entrega, reportería de existencia y detalle de lotes en proceso. | G9: Seguimiento de paquetería recolección→entrega, confirmación de recepción [DEF RF-01 Escenarios 5/6]. Consulta limitada al periodo máximo. Sin reposición proactiva ante vencimiento: cliente acude a sucursal. | H9: Smart Vista | I9: Área de Suministros / Operaciones | J9: Should | K9: Solución | L9: 0 | M9: Desarrollo + Configuración | N9: Nuevo Desarrollo <20% | O9: 2 | P9: 1 | Q9: {=+_xlfn.IFS(O9="","",O9<=1,"Baja",O9<=3,"Media",O9>3,"Alta")} -> Media | R9: {=+_xlfn.IFS(P9="","",P9<=0,"Baja",P9<=2,"Media",P9>2,"Alta")} -> Media | S9: {=+_xlfn.IFS(N9="","",N9="Componentes existentes reutilizables >80%","Baja",N9="No Aplica","Baja",N9="Reutilización parcial 30-70%","Media",N9="Nuevo Desarrollo <20%","Alta")} -> Alta | T9: {=+_xlfn.IFS(L9="","",L9=0,"Baja",L9<=2,"Media",L9>=3,"Alta")} -> Baja | U9: {=+IFERROR((+_xlfn.IFS(Q9="",0,Q9="Baja",1,Q9="Media",2,Q9="Alta",3)*'Scoring Complejidad'!$C$8+_xlfn.IFS(R9="Baja",1,R9="Media",2,R9="Alta",3)*'Scoring Complejidad'!$C$9+_xlfn.IFS(S9="Baja",1,S9="Media",2,S9="Alta",3)*'Scoring Complejidad'!$C$7+_xlfn.IFS(T9="",1,T9="Baja",1,T9="Media",2,T9="Alta",3)*'Scoring Complejidad'!$C$5+_xlfn.IFS(M9="Caja",1,M9="Configuración",2,M9="Desarrollo",3,M9="Desarrollo + Configuración",3,M9="No Aplica",0)*'Scoring Complejidad'!$C$6),"")} -> 2.15 | V9: {=IFERROR(_xlfn.IFS(U9="","",U9<=1.69,"Baja",U9<=2.29,"Media",U9<=3,"Alta",U9>3,"Error"),"")} -> Media | W9: 06/07/206 | X9: 20/07/206 | Y9: 21/07/206 | Z9: 04/09/206 | AA9: 17/08/206 | AB9: 30/10/206 | AC9: Considerar 15 días menos de implementación como supuesto de reducción de alcance a un solo proveedor (proveedor prioritario) de maquila. Considerar que Pruebas de maquila son independientes y no van por la ruta crítica | AD9: 46240
A10: HDU-SMART-R4-08 | B10: Smart Vista | C10: Controlar recepción y cancelación de lotes. | D10: TDC | E10: Automatización de Maquila | F10: Recepción de lotes en sucursal desde SIWEB con validación de lote correcto, baja de tarjetas dañadas/inexistentes, bloqueo de asignación para créditos vencidos, y validación obligatoria de huella del Gerente para cancelaciones. | G10: Recepción desde SIWEB; rechazo de lote incorrecto o de otra sucursal . Mensaje corregido 'tarjeta no existe' (hoy muestra erróneamente 'ya reportada'). Bloqueo con crédito vencido >1 mes. Huella de Gerente obligatoria para cancelar dañadas. Gap: baja por daño solo si tarjeta asignada (candidato R4.5). | H10: Smart Vista, SIWEB | I10: Gerente de Sucursal / Ejecutivo de Sucursal | J10: Must | K10: Integración | L10: 3 | M10: No Aplica | N10: No Aplica | O10: 0 | P10: 0 | Q10: {=+_xlfn.IFS(O10="","",O10<=1,"Baja",O10<=3,"Media",O10>3,"Alta")} -> Baja | R10: {=+_xlfn.IFS(P10="","",P10<=0,"Baja",P10<=2,"Media",P10>2,"Alta")} -> Baja | S10: {=+_xlfn.IFS(N10="","",N10="Componentes existentes reutilizables >80%","Baja",N10="No Aplica","Baja",N10="Reutilización parcial 30-70%","Media",N10="Nuevo Desarrollo <20%","Alta")} -> Baja | T10: {=+_xlfn.IFS(L10="","",L10=0,"Baja",L10<=2,"Media",L10>=3,"Alta")} -> Alta | U10: {=+IFERROR((+_xlfn.IFS(Q10="",0,Q10="Baja",1,Q10="Media",2,Q10="Alta",3)*'Scoring Complejidad'!$C$8+_xlfn.IFS(R10="Baja",1,R10="Media",2,R10="Alta",3)*'Scoring Complejidad'!$C$9+_xlfn.IFS(S10="Baja",1,S10="Media",2,S10="Alta",3)*'Scoring Complejidad'!$C$7+_xlfn.IFS(T10="",1,T10="Baja",1,T10="Media",2,T10="Alta",3)*'Scoring Complejidad'!$C$5+_xlfn.IFS(M10="Caja",1,M10="Configuración",2,M10="Desarrollo",3,M10="Desarrollo + Configuración",3,M10="No Aplica",0)*'Scoring Complejidad'!$C$6),"")} -> 1.35 | V10: {=IFERROR(_xlfn.IFS(U10="","",U10<=1.69,"Baja",U10<=2.29,"Media",U10<=3,"Alta",U10>3,"Error"),"")} -> Baja | W10: 06/07/206 | X10: 20/07/206 | Y10: 21/07/206 | Z10: 04/09/206 | AA10: 17/08/206 | AB10: 30/10/206 | AC10: Considerar 15 días menos de implementación como supuesto de reducción de alcance a un solo proveedor (proveedor prioritario) de maquila. Considerar que Pruebas de maquila son independientes y no van por la ruta crítica | AD10: 46240
A11: HDU-SMART-R4-09 | B11: Smart Vista | C11: Homologar conceptos de comisiones TDC. | D11: TDC | E11: Homologación omnicanal de comisiones | F11: Definición del catálogo normativo único de comisiones para TDC 4900 (17 comisiones replicando esquema 8500), alineado a BANXICO. Solo cambia la etiqueta visible; caídas y cuentas contables permanecen idénticas. Límites de longitud: 40 caracteres en EDC, 26 en ticket SIWEB. | G11: Catálogo normativo único alineado a BANXICO. 17 comisiones 4900=esquema 8500. Solo cambia etiqueta, NO la contabilidad [RF-03 Acuerdo S3]. Límites: 40 chars EDC / 26 chars ticket. Mapeo nombre-actual→nombre-nuevo con ID de comisión. | H11: Smart Vista, App, SIWEB | I11: Área Normativa / Negocio | J11: Must | K11: Solución | L11: 0 | M11: Desarrollo | N11: Componentes existentes reutilizables >80% | O11: 3 | P11: 0 | Q11: {=+_xlfn.IFS(O11="","",O11<=1,"Baja",O11<=3,"Media",O11>3,"Alta")} -> Media | R11: {=+_xlfn.IFS(P11="","",P11<=0,"Baja",P11<=2,"Media",P11>2,"Alta")} -> Baja | S11: {=+_xlfn.IFS(N11="","",N11="Componentes existentes reutilizables >80%","Baja",N11="No Aplica","Baja",N11="Reutilización parcial 30-70%","Media",N11="Nuevo Desarrollo <20%","Alta")} -> Baja | T11: {=+_xlfn.IFS(L11="","",L11=0,"Baja",L11<=2,"Media",L11>=3,"Alta")} -> Baja | U11: {=+IFERROR((+_xlfn.IFS(Q11="",0,Q11="Baja",1,Q11="Media",2,Q11="Alta",3)*'Scoring Complejidad'!$C$8+_xlfn.IFS(R11="Baja",1,R11="Media",2,R11="Alta",3)*'Scoring Complejidad'!$C$9+_xlfn.IFS(S11="Baja",1,S11="Media",2,S11="Alta",3)*'Scoring Complejidad'!$C$7+_xlfn.IFS(T11="",1,T11="Baja",1,T11="Media",2,T11="Alta",3)*'Scoring Complejidad'!$C$5+_xlfn.IFS(M11="Caja",1,M11="Configuración",2,M11="Desarrollo",3,M11="Desarrollo + Configuración",3,M11="No Aplica",0)*'Scoring Complejidad'!$C$6),"")} -> 1.65 | V11: {=IFERROR(_xlfn.IFS(U11="","",U11<=1.69,"Baja",U11<=2.29,"Media",U11<=3,"Alta",U11>3,"Error"),"")} -> Baja | W11: 46202 | X11: 46234 | Y11: Dependencia DTMs | Z11: Dependencia DTMs | AA11: Dependencia DTMs | AB11: Dependencia DTMs | AC11: Solicitudes de normatividad. Se parte de una base de APIs existentes en los canales SIWEB y App; IVR y CAT no requieren la homologación Pendiente verificación de fechas de Diseño (DTMs) e implementación - equipo APIFICACIÓN (Juan Carlos Valenzuela y Oscar Melo) asignados como responsables 7-Agosto Dependencia para generar DTMs insumos: Catalogo de reglas de negocio, errores, dependencias, diagrama funcional | AD11: 46241
A12: HDU-SMART-R4-10 | B12: Smart Vista | C12: Sincronizar nombres de comisiones en canales. | D12: TDC | E12: Homologación omnicanal de comisiones | F12: Verificación de que los nombres homologados de comisiones se muestran de forma idéntica en todos los canales de consulta (Smart Vista, App, SIWEB, EDC), cumpliendo la regulación BANXICO y los límites de longitud por canal. | G12: Nombres idénticos en SV, App, SIWEB, EDC . Verificación por punto de consulta. Auditoría BANXICO sin inconsistencias. Límites 40 EDC / 26 ticket. Depende de catálogo HDU-SMART-R4-09. | H12: Smart Vista, App, SIWEB, EDC | I12: Área Normativa / Todos los canales | J12: Must | K12: Solución e Integración | L12: 2 | M12: Desarrollo + Configuración | N12: Reutilización parcial 30-70% | O12: 3 | P12: 0 | Q12: {=+_xlfn.IFS(O12="","",O12<=1,"Baja",O12<=3,"Media",O12>3,"Alta")} -> Media | R12: {=+_xlfn.IFS(P12="","",P12<=0,"Baja",P12<=2,"Media",P12>2,"Alta")} -> Baja | S12: {=+_xlfn.IFS(N12="","",N12="Componentes existentes reutilizables >80%","Baja",N12="No Aplica","Baja",N12="Reutilización parcial 30-70%","Media",N12="Nuevo Desarrollo <20%","Alta")} -> Media | T12: {=+_xlfn.IFS(L12="","",L12=0,"Baja",L12<=2,"Media",L12>=3,"Alta")} -> Media | U12: {=+IFERROR((+_xlfn.IFS(Q12="",0,Q12="Baja",1,Q12="Media",2,Q12="Alta",3)*'Scoring Complejidad'!$C$8+_xlfn.IFS(R12="Baja",1,R12="Media",2,R12="Alta",3)*'Scoring Complejidad'!$C$9+_xlfn.IFS(S12="Baja",1,S12="Media",2,S12="Alta",3)*'Scoring Complejidad'!$C$7+_xlfn.IFS(T12="",1,T12="Baja",1,T12="Media",2,T12="Alta",3)*'Scoring Complejidad'!$C$5+_xlfn.IFS(M12="Caja",1,M12="Configuración",2,M12="Desarrollo",3,M12="Desarrollo + Configuración",3,M12="No Aplica",0)*'Scoring Complejidad'!$C$6),"")} -> 2.15 | V12: {=IFERROR(_xlfn.IFS(U12="","",U12<=1.69,"Baja",U12<=2.29,"Media",U12<=3,"Alta",U12>3,"Error"),"")} -> Media | W12: 46202 | X12: 46234 | Y12: Dependencia DTMs | Z12: Dependencia DTMs | AA12: Dependencia DTMs | AB12: Dependencia DTMs | AC12: Solicitudes de normatividad; Una integración por canal App, SIWEB, EDC, Smartvista Pendiente verificación de fechas de DTM- equipo APIFICACIÓN | AD12: 46241
A13: HDU-SMART-R4-11 | B13: Smart Vista | C13: Incorporar reglas del autorizador BPC. | D13: TDC | E13: Reglas del autorizador (88 reglas) | F13: Motor de 88 reglas del autorizador BPC en tiempo real: Módulo 1 (estatus/ISO 8583) y Fraud Management. Incluye rechazo con códigos ISO específicos, validación MIT sin OTID contra Whitelist, y mapeo de rechazos por bloqueo temporal. | G13: 88 reglas BPC divididas entre SV Frontend y Fraud Management [RF-06a Acuerdo S3]. Módulo 1: rechazo con código ISO (BIN desconocido ISO 14, robada ISO 43, extraviada ISO 41). MIT sin OTID: Regla 45 vs Whitelist + umbrales Regla 88. Sin afectación contable hasta batch cierre de día. Alerta 000916 por bloqueo temporal . | H13: Smart Vista (Autorizador BPC) | I13: Administrador de Tarjetas / BPC | J13: Must | K13: Solución | L13: 0 | M13: Desarrollo + Configuración | N13: Nuevo Desarrollo <20% | O13: 1 | P13: 0 | Q13: {=+_xlfn.IFS(O13="","",O13<=1,"Baja",O13<=3,"Media",O13>3,"Alta")} -> Baja | R13: {=+_xlfn.IFS(P13="","",P13<=0,"Baja",P13<=2,"Media",P13>2,"Alta")} -> Baja | S13: {=+_xlfn.IFS(N13="","",N13="Componentes existentes reutilizables >80%","Baja",N13="No Aplica","Baja",N13="Reutilización parcial 30-70%","Media",N13="Nuevo Desarrollo <20%","Alta")} -> Alta | T13: {=+_xlfn.IFS(L13="","",L13=0,"Baja",L13<=2,"Media",L13>=3,"Alta")} -> Baja | U13: {=+IFERROR((+_xlfn.IFS(Q13="",0,Q13="Baja",1,Q13="Media",2,Q13="Alta",3)*'Scoring Complejidad'!$C$8+_xlfn.IFS(R13="Baja",1,R13="Media",2,R13="Alta",3)*'Scoring Complejidad'!$C$9+_xlfn.IFS(S13="Baja",1,S13="Media",2,S13="Alta",3)*'Scoring Complejidad'!$C$7+_xlfn.IFS(T13="",1,T13="Baja",1,T13="Media",2,T13="Alta",3)*'Scoring Complejidad'!$C$5+_xlfn.IFS(M13="Caja",1,M13="Configuración",2,M13="Desarrollo",3,M13="Desarrollo + Configuración",3,M13="No Aplica",0)*'Scoring Complejidad'!$C$6),"")} -> 1.9 | V13: {=IFERROR(_xlfn.IFS(U13="","",U13<=1.69,"Baja",U13<=2.29,"Media",U13<=3,"Alta",U13>3,"Error"),"")} -> Media | W13: 46179 | X13: 46311 | Y13: No Aplica | Z13: No Aplica | AA13: 46223 | AB13: 46311 | AC13: Análisis y pruebas de comfort de las 88 reglas se trabaja en ciclos; Depende de ventana de pruebas con Eglobal , quien ejecuta esas reglas de confort y los resultados se comparten con negocio. Punto pendiente: seguimiento proceso de pruebas de Eglobal ; Dependencia con BPC para desarrollo y configuración de nuevas reglas, con fechas mostradas en las columnas de Implementación No aplica diseño porque BPC es el que hace el desarrollo y configuración, no SmartVista. | AD13: 46237
A14: HDU-SMART-R4-12 | B14: Smart Vista | C14: Parametrizar límite de saldo a favor. | D14: TDC | E14: Control de saldo a favor | F14: Interfaz de administración para configurar el parámetro único de límite de saldo a favor por TDC (monto o % de la línea), con switch on/off para TDC clásica 4900 y propagación consistente a todos los canales. | G14: Parámetro único: monto o % sobre línea de crédito. Switch apagar/prender para TDC clásica (4900); extensible a legado [RF-25]. Aplica a productos 6001 y 4900. Propagación automática a todos los canales. Solo rol autorizado puede modificar [RN-HU-021]. | H14: Smart Vista (todos los canales) | I14: Área de Negocio / Administrador | J14: Must | K14: Solución | L14: 0 | M14: Desarrollo + Configuración | N14: Reutilización parcial 30-70% | O14: 3 | P14: 0 | Q14: {=+_xlfn.IFS(O14="","",O14<=1,"Baja",O14<=3,"Media",O14>3,"Alta")} -> Media | R14: {=+_xlfn.IFS(P14="","",P14<=0,"Baja",P14<=2,"Media",P14>2,"Alta")} -> Baja | S14: {=+_xlfn.IFS(N14="","",N14="Componentes existentes reutilizables >80%","Baja",N14="No Aplica","Baja",N14="Reutilización parcial 30-70%","Media",N14="Nuevo Desarrollo <20%","Alta")} -> Media | T14: {=+_xlfn.IFS(L14="","",L14=0,"Baja",L14<=2,"Media",L14>=3,"Alta")} -> Baja | U14: {=+IFERROR((+_xlfn.IFS(Q14="",0,Q14="Baja",1,Q14="Media",2,Q14="Alta",3)*'Scoring Complejidad'!$C$8+_xlfn.IFS(R14="Baja",1,R14="Media",2,R14="Alta",3)*'Scoring Complejidad'!$C$9+_xlfn.IFS(S14="Baja",1,S14="Media",2,S14="Alta",3)*'Scoring Complejidad'!$C$7+_xlfn.IFS(T14="",1,T14="Baja",1,T14="Media",2,T14="Alta",3)*'Scoring Complejidad'!$C$5+_xlfn.IFS(M14="Caja",1,M14="Configuración",2,M14="Desarrollo",3,M14="Desarrollo + Configuración",3,M14="No Aplica",0)*'Scoring Complejidad'!$C$6),"")} -> 1.85 | V14: {=IFERROR(_xlfn.IFS(U14="","",U14<=1.69,"Baja",U14<=2.29,"Media",U14<=3,"Alta",U14>3,"Error"),"")} -> Media | W14: 46181 | X14: 46234 | Y14: No Aplica | Z14: No Aplica | AA14: 46237 | AB14: 46265 | AC14: No aplica diseño | AD14: 46237
A15: HDU-SMART-R4-13 | B15: Smart Vista | C15: Validar límite por línea de crédito. | D15: TDC | E15: Control de saldo a favor | F15: Validación transaccional del límite de saldo a favor según la línea: tope fijo $15,000 para líneas <$25,000; 20% para líneas ≥$25,000. Aplica acumulado mensual. Rechaza pago/depósito que excede el tope. | G15: Límite dinámico: $15,000 fijo (líneas ≤$24,999) o 20% de línea (líneas ≥$25,000) [RF-05 Acuerdo S3, RN-OP-APP-21]. Acumulado o en una sola exhibición. Rechazo si inicio de periodo ya con límite alcanzado. Conectado al HUB de Pagos. Reportería desde SV [RN-HU-022]. | H15: Smart Vista (todos los canales de pago) | I15: Cliente Final / Sistema | J15: Must | K15: Solución | L15: 0 | M15: Desarrollo + Configuración | N15: Nuevo Desarrollo <20% | O15: 2 | P15: 0 | Q15: {=+_xlfn.IFS(O15="","",O15<=1,"Baja",O15<=3,"Media",O15>3,"Alta")} -> Media | R15: {=+_xlfn.IFS(P15="","",P15<=0,"Baja",P15<=2,"Media",P15>2,"Alta")} -> Baja | S15: {=+_xlfn.IFS(N15="","",N15="Componentes existentes reutilizables >80%","Baja",N15="No Aplica","Baja",N15="Reutilización parcial 30-70%","Media",N15="Nuevo Desarrollo <20%","Alta")} -> Alta | T15: {=+_xlfn.IFS(L15="","",L15=0,"Baja",L15<=2,"Media",L15>=3,"Alta")} -> Baja | U15: {=+IFERROR((+_xlfn.IFS(Q15="",0,Q15="Baja",1,Q15="Media",2,Q15="Alta",3)*'Scoring Complejidad'!$C$8+_xlfn.IFS(R15="Baja",1,R15="Media",2,R15="Alta",3)*'Scoring Complejidad'!$C$9+_xlfn.IFS(S15="Baja",1,S15="Media",2,S15="Alta",3)*'Scoring Complejidad'!$C$7+_xlfn.IFS(T15="",1,T15="Baja",1,T15="Media",2,T15="Alta",3)*'Scoring Complejidad'!$C$5+_xlfn.IFS(M15="Caja",1,M15="Configuración",2,M15="Desarrollo",3,M15="Desarrollo + Configuración",3,M15="No Aplica",0)*'Scoring Complejidad'!$C$6),"")} -> 2.05 | V15: {=IFERROR(_xlfn.IFS(U15="","",U15<=1.69,"Baja",U15<=2.29,"Media",U15<=3,"Alta",U15>3,"Error"),"")} -> Media | W15: 46181 | X15: 46234 | Y15: No Aplica | Z15: No Aplica | AA15: 46237 | AB15: 46265 | AC15: No aplica diseño | AD15: 46237
A16: HDU-SMART-R4-14 | B16: Smart Vista | C16: Excluir abonos bancarios del límite. | D16: TDC | E16: Control de saldo a favor | F16: Los abonos originados por el banco (aclaraciones, correcciones, reversos, abonos CAT) no están sujetos al límite de saldo a favor y se procesan libremente sin sumar al tope del cliente. | G16: Abonos del banco (aclaración/corrección/reverso/CAT) exentos del límite [RN-OP-S3-01]. No suman al saldo a favor para efectos del tope. NOTA: Confirmado por negocio que se desestima para R4 y pasa al siguiente release. | H16: Smart Vista | I16: Área de Negocio / Sistema | J16: Wont | K16: Solución | L16: 0 | M16: Desarrollo + Configuración | N16: Nuevo Desarrollo <20% | O16: 0 | P16: 0 | Q16: {=+_xlfn.IFS(O16="","",O16<=1,"Baja",O16<=3,"Media",O16>3,"Alta")} -> Baja | R16: {=+_xlfn.IFS(P16="","",P16<=0,"Baja",P16<=2,"Media",P16>2,"Alta")} -> Baja | S16: {=+_xlfn.IFS(N16="","",N16="Componentes existentes reutilizables >80%","Baja",N16="No Aplica","Baja",N16="Reutilización parcial 30-70%","Media",N16="Nuevo Desarrollo <20%","Alta")} -> Alta | T16: {=+_xlfn.IFS(L16="","",L16=0,"Baja",L16<=2,"Media",L16>=3,"Alta")} -> Baja | U16: {=+IFERROR((+_xlfn.IFS(Q16="",0,Q16="Baja",1,Q16="Media",2,Q16="Alta",3)*'Scoring Complejidad'!$C$8+_xlfn.IFS(R16="Baja",1,R16="Media",2,R16="Alta",3)*'Scoring Complejidad'!$C$9+_xlfn.IFS(S16="Baja",1,S16="Media",2,S16="Alta",3)*'Scoring Complejidad'!$C$7+_xlfn.IFS(T16="",1,T16="Baja",1,T16="Media",2,T16="Alta",3)*'Scoring Complejidad'!$C$5+_xlfn.IFS(M16="Caja",1,M16="Configuración",2,M16="Desarrollo",3,M16="Desarrollo + Configuración",3,M16="No Aplica",0)*'Scoring Complejidad'!$C$6),"")} -> 1.9 | V16: {=IFERROR(_xlfn.IFS(U16="","",U16<=1.69,"Baja",U16<=2.29,"Media",U16<=3,"Alta",U16>3,"Error"),"")} -> Media | Y16: No Aplica | Z16: No Aplica | AC16: Negocio ya ha enviado correo confirmando que puede no considerarse para release 4. No aplica diseño | AD16: 46237
A17: HDU-SMART-R4-15 | B17: Smart Vista | C17: Mostrar mensaje por límite alcanzado. | D17: TDC | E17: Control de saldo a favor | F17: Mensaje homologado exacto al rechazar pagos/depósitos por límite de saldo a favor: 'No se puede completar la transacción.' Aplica en App, SIWEB, ATM, BPI y SPEI/corresponsales. | G17: Mensaje exacto homologado en todos los canales [RN-HU-022/023/024/065-068]. Frontend deshabilita 'Otra cantidad' para evitar Defecto 748001 [RN-OP-SF-02]. SPEI/corresponsales: rechaza, regresa fondos al emisor sin notificar al cliente [RN-HU-069/070]. Sin conteo de intentos en R4 [RN-OP-S3-02]. | H17: App, SIWEB,SPEI | I17: Cliente Final / Canales | J17: Must | K17: Solución e Integración | L17: 0 | M17: Desarrollo | N17: Reutilización parcial 30-70% | O17: 1 | P17: 0 | Q17: {=+_xlfn.IFS(O17="","",O17<=1,"Baja",O17<=3,"Media",O17>3,"Alta")} -> Baja | R17: {=+_xlfn.IFS(P17="","",P17<=0,"Baja",P17<=2,"Media",P17>2,"Alta")} -> Baja | S17: {=+_xlfn.IFS(N17="","",N17="Componentes existentes reutilizables >80%","Baja",N17="No Aplica","Baja",N17="Reutilización parcial 30-70%","Media",N17="Nuevo Desarrollo <20%","Alta")} -> Media | T17: {=+_xlfn.IFS(L17="","",L17=0,"Baja",L17<=2,"Media",L17>=3,"Alta")} -> Baja | U17: {=+IFERROR((+_xlfn.IFS(Q17="",0,Q17="Baja",1,Q17="Media",2,Q17="Alta",3)*'Scoring Complejidad'!$C$8+_xlfn.IFS(R17="Baja",1,R17="Media",2,R17="Alta",3)*'Scoring Complejidad'!$C$9+_xlfn.IFS(S17="Baja",1,S17="Media",2,S17="Alta",3)*'Scoring Complejidad'!$C$7+_xlfn.IFS(T17="",1,T17="Baja",1,T17="Media",2,T17="Alta",3)*'Scoring Complejidad'!$C$5+_xlfn.IFS(M17="Caja",1,M17="Configuración",2,M17="Desarrollo",3,M17="Desarrollo + Configuración",3,M17="No Aplica",0)*'Scoring Complejidad'!$C$6),"")} -> 1.7 | V17: {=IFERROR(_xlfn.IFS(U17="","",U17<=1.69,"Baja",U17<=2.29,"Media",U17<=3,"Alta",U17>3,"Error"),"")} -> Media | W17: 46181 | X17: 46234 | Y17: No Aplica | Z17: No Aplica | AA17: 46237 | AB17: 46265 | AC17: No aplica diseño. 3 integraciones consideradas en el alcance de pruebas de regresión pero no como nuevo desarrollo porque ya vienen de releases anteriores- | AD17: 46237
A18: HDU-SMARTVISTA-R4-16 | B18: Smart Vista | C18: Configurar campañas de compras diferidas. | D18: TDC | E18: Diferemiento de compra a MCI | F18: Configuración de campañas de Compras Diferidas (MCI) en Smart Vista: atributo permanente por toda la vida de la cuenta, campañas temporales con tasa promocional dentro de vigencia y portafolio elegible. Split: MSI libera en R4 con pruebas integrales; MCI solo backend en R4, consumo App en R4.5. | G18: Atributo permanente independiente de segmentación inicial [DEF RF-4 MCI]. Campaña temporal: tasa solo dentro de vigencia/portafolio [RN-HU-048]. Fuera del portafolio: no aplica la tasa. Split confirmado S4/S5: MSI solo pruebas en R4, MCI backend R4/App R4.5 [RN-OP-S4-02/03]. | H18: Smart Vista | I18: Administrador de Producto | J18: Should | K18: Solución | L18: 0 | M18: Desarrollo + Configuración | N18: Nuevo Desarrollo <20% | O18: 3 | P18: 0 | Q18: {=+_xlfn.IFS(O18="","",O18<=1,"Baja",O18<=3,"Media",O18>3,"Alta")} -> Media | R18: {=+_xlfn.IFS(P18="","",P18<=0,"Baja",P18<=2,"Media",P18>2,"Alta")} -> Baja | S18: {=+_xlfn.IFS(N18="","",N18="Componentes existentes reutilizables >80%","Baja",N18="No Aplica","Baja",N18="Reutilización parcial 30-70%","Media",N18="Nuevo Desarrollo <20%","Alta")} -> Alta | T18: {=+_xlfn.IFS(L18="","",L18=0,"Baja",L18<=2,"Media",L18>=3,"Alta")} -> Baja | U18: {=+IFERROR((+_xlfn.IFS(Q18="",0,Q18="Baja",1,Q18="Media",2,Q18="Alta",3)*'Scoring Complejidad'!$C$8+_xlfn.IFS(R18="Baja",1,R18="Media",2,R18="Alta",3)*'Scoring Complejidad'!$C$9+_xlfn.IFS(S18="Baja",1,S18="Media",2,S18="Alta",3)*'Scoring Complejidad'!$C$7+_xlfn.IFS(T18="",1,T18="Baja",1,T18="Media",2,T18="Alta",3)*'Scoring Complejidad'!$C$5+_xlfn.IFS(M18="Caja",1,M18="Configuración",2,M18="Desarrollo",3,M18="Desarrollo + Configuración",3,M18="No Aplica",0)*'Scoring Complejidad'!$C$6),"")} -> 2.05 | V18: {=IFERROR(_xlfn.IFS(U18="","",U18<=1.69,"Baja",U18<=2.29,"Media",U18<=3,"Alta",U18>3,"Error"),"")} -> Media | W18: 46216 | X18: 46262 | Y18: No Aplica | Z18: No Aplica | AA18: 46251 | AB18: 46353 | AC18: No impacta desde la perspectiva operativa pero es muy relevante desde el punto de vista comercial Análisis extenso en fechas por impacto en contabilidad y revisiones financieras. No aplica diseño porque directamente lo implementa BPC con los requerimientos. Fecha 27 de noviembre es la más pesimista y se podría acortar Las trabaja SmartVista no requieren pruebas integrales porque hasta el siguiente R se libera conexión con canales | AD18: 46241
A19: HDU-SMART-R4-17 | B19: Smart Vista | C19: Calcular oferta de compra diferida. | D19: TDC | E19: Diferemiento de compra a MCI | F19: Cálculo de la oferta de diferimiento para compras elegibles (>$1,000, no parcializadas, del periodo actual o último): plazos 3, 6, 9, 12, 18 y 24 meses con cuota mensual, capital e intereses. Validación de línea disponible neta al confirmar. | G19: Elegibilidad: compra >$1,000, no parcializada, del periodo o último [RN-HU-049-053]. Plazos 3/6/9/12/18/24 meses con cuota mensual e intereses [DEF RF-4]. Validación de línea neta al swipe/token [RN-OP-S4-01]. Sin sobregiro salvo capitalización de intereses [RN-OP-S4-11]. Desglose capital+intereses antes de confirmar. Umbral resuelto en $1,000. | H19: Smart Vista (motor de cálculo) | I19: Cliente Final TDC | J19: Should | K19: Solución | L19: 0 | M19: Desarrollo + Configuración | N19: Reutilización parcial 30-70% | O19: 3 | P19: 0 | Q19: {=+_xlfn.IFS(O19="","",O19<=1,"Baja",O19<=3,"Media",O19>3,"Alta")} -> Media | R19: {=+_xlfn.IFS(P19="","",P19<=0,"Baja",P19<=2,"Media",P19>2,"Alta")} -> Baja | S19: {=+_xlfn.IFS(N19="","",N19="Componentes existentes reutilizables >80%","Baja",N19="No Aplica","Baja",N19="Reutilización parcial 30-70%","Media",N19="Nuevo Desarrollo <20%","Alta")} -> Media | T19: {=+_xlfn.IFS(L19="","",L19=0,"Baja",L19<=2,"Media",L19>=3,"Alta")} -> Baja | U19: {=+IFERROR((+_xlfn.IFS(Q19="",0,Q19="Baja",1,Q19="Media",2,Q19="Alta",3)*'Scoring Complejidad'!$C$8+_xlfn.IFS(R19="Baja",1,R19="Media",2,R19="Alta",3)*'Scoring Complejidad'!$C$9+_xlfn.IFS(S19="Baja",1,S19="Media",2,S19="Alta",3)*'Scoring Complejidad'!$C$7+_xlfn.IFS(T19="",1,T19="Baja",1,T19="Media",2,T19="Alta",3)*'Scoring Complejidad'!$C$5+_xlfn.IFS(M19="Caja",1,M19="Configuración",2,M19="Desarrollo",3,M19="Desarrollo + Configuración",3,M19="No Aplica",0)*'Scoring Complejidad'!$C$6),"")} -> 1.85 | V19: {=IFERROR(_xlfn.IFS(U19="","",U19<=1.69,"Baja",U19<=2.29,"Media",U19<=3,"Alta",U19>3,"Error"),"")} -> Media | W19: 46209 | X19: 46248 | Y19: No Aplica | Z19: No Aplica | AA19: 46251 | AB19: 46353 | AC19: No impacta desde la perspectiva operativa pero es muy relevante desde el punto de vista comercial Análisis extenso en fechas por impacto en contabilidad y revisiones financieras. No aplica diseño porque directamente lo implementa BPC con los requerimientos. Fecha 27 de noviembre es la más pesimista y se podría acortar Las trabaja SmartVista no requieren pruebas integrales porque hasta el siguiente R se libera conexión con canales | AD19: 46241
A20: HDU-SMART-R4-18 | B20: Smart Vista | C20: Aplicar plan MCI/MSI a compra. | D20: TDC | E20: Diferemiento de compra a MCI | F20: Aplicación del plan de compras diferidas en línea (inmediata) con impacto de saldo, cuenta y estado. Por cada movimiento diferido se crea un Pago Fijo independiente; abono inverso reclasifica al grupo contable 13; intereses cobrados solo en fecha de corte. | G20: Aplicación en línea, no esperar cierre contable [DEF RF-4]. Producto Pago Fijo independiente por movimiento; saldo retenido = suma capital+intereses. Abono inverso reclasifica a grupo 13, no recircula a 2402/Eglobal [RN-OP-S4-04/05]. Intereses solo en corte [RN-OP-S4-06]. TRNT exacta pendiente guía contable formal. | H20: Smart Vista | I20: Cliente Final TDC | J20: Should | K20: Solución | L20: 0 | M20: Desarrollo + Configuración | N20: Reutilización parcial 30-70% | O20: 3 | P20: 0 | Q20: {=+_xlfn.IFS(O20="","",O20<=1,"Baja",O20<=3,"Media",O20>3,"Alta")} -> Media | R20: {=+_xlfn.IFS(P20="","",P20<=0,"Baja",P20<=2,"Media",P20>2,"Alta")} -> Baja | S20: {=+_xlfn.IFS(N20="","",N20="Componentes existentes reutilizables >80%","Baja",N20="No Aplica","Baja",N20="Reutilización parcial 30-70%","Media",N20="Nuevo Desarrollo <20%","Alta")} -> Media | T20: {=+_xlfn.IFS(L20="","",L20=0,"Baja",L20<=2,"Media",L20>=3,"Alta")} -> Baja | U20: {=+IFERROR((+_xlfn.IFS(Q20="",0,Q20="Baja",1,Q20="Media",2,Q20="Alta",3)*'Scoring Complejidad'!$C$8+_xlfn.IFS(R20="Baja",1,R20="Media",2,R20="Alta",3)*'Scoring Complejidad'!$C$9+_xlfn.IFS(S20="Baja",1,S20="Media",2,S20="Alta",3)*'Scoring Complejidad'!$C$7+_xlfn.IFS(T20="",1,T20="Baja",1,T20="Media",2,T20="Alta",3)*'Scoring Complejidad'!$C$5+_xlfn.IFS(M20="Caja",1,M20="Configuración",2,M20="Desarrollo",3,M20="Desarrollo + Configuración",3,M20="No Aplica",0)*'Scoring Complejidad'!$C$6),"")} -> 1.85 | V20: {=IFERROR(_xlfn.IFS(U20="","",U20<=1.69,"Baja",U20<=2.29,"Media",U20<=3,"Alta",U20>3,"Error"),"")} -> Media | W20: 46209 | X20: 46248 | Y20: No Aplica | Z20: No Aplica | AA20: 46251 | AB20: 46353 | AC20: No impacta desde la perspectiva operativa pero es muy relevante desde el punto de vista comercial Análisis extenso en fechas por impacto en contabilidad y revisiones financieras. No aplica diseño porque directamente lo implementa BPC con los requerimientos. Fecha 27 de noviembre es la más pesimista y se podría acortar Las trabaja SmartVista no requieren pruebas integrales porque hasta el siguiente R se libera conexión con canales | AD20: 46241
A21: HDU-SMART-R4-19 | B21: Smart Vista | C21: Aplicar pagos anticipados a pagos fijos. | D21: TDC | E21: Pagos anticipados y Liquidaciones de compras diferidas | F21: Pago anticipado parcial aplicado directo al capital de una compra diferida, reduciendo el plazo (no la mensualidad). Selección de compra específica. No exime la siguiente mensualidad. Registro via transacción SIWEB 623. | G21: Pago a capital reduce plazo, no monto de mensualidad [RN-OP-S4-07]. Sin límite de pagos parciales por corte. No exime siguiente mensualidad. Transacción SIWEB 623 'PAGO CGO A CTA DE CREDISOLUCIONES'. Pago directo a productos MSI/MCI (6900/8900). | H21: Smart Vista, SIWEB, App | I21: Cliente Final TDC / Ejecutivo de Sucursal | J21: Should | K21: Solución e Integración | L21: 2 | M21: Desarrollo + Configuración | N21: Nuevo Desarrollo <20% | O21: 3 | P21: 0 | Q21: {=+_xlfn.IFS(O21="","",O21<=1,"Baja",O21<=3,"Media",O21>3,"Alta")} -> Media | R21: {=+_xlfn.IFS(P21="","",P21<=0,"Baja",P21<=2,"Media",P21>2,"Alta")} -> Baja | S21: {=+_xlfn.IFS(N21="","",N21="Componentes existentes reutilizables >80%","Baja",N21="No Aplica","Baja",N21="Reutilización parcial 30-70%","Media",N21="Nuevo Desarrollo <20%","Alta")} -> Alta | T21: {=+_xlfn.IFS(L21="","",L21=0,"Baja",L21<=2,"Media",L21>=3,"Alta")} -> Media | U21: {=+IFERROR((+_xlfn.IFS(Q21="",0,Q21="Baja",1,Q21="Media",2,Q21="Alta",3)*'Scoring Complejidad'!$C$8+_xlfn.IFS(R21="Baja",1,R21="Media",2,R21="Alta",3)*'Scoring Complejidad'!$C$9+_xlfn.IFS(S21="Baja",1,S21="Media",2,S21="Alta",3)*'Scoring Complejidad'!$C$7+_xlfn.IFS(T21="",1,T21="Baja",1,T21="Media",2,T21="Alta",3)*'Scoring Complejidad'!$C$5+_xlfn.IFS(M21="Caja",1,M21="Configuración",2,M21="Desarrollo",3,M21="Desarrollo + Configuración",3,M21="No Aplica",0)*'Scoring Complejidad'!$C$6),"")} -> 2.35 | V21: {=IFERROR(_xlfn.IFS(U21="","",U21<=1.69,"Baja",U21<=2.29,"Media",U21<=3,"Alta",U21>3,"Error"),"")} -> Alta | W21: 46209 | X21: 46255 | Y21: No Aplica | Z21: No Aplica | AA21: 46244 | AB21: 46283 | AC21: Dependencia de APIs con SIWEB para pruebas integrales - DTMs son dependencia de SIWEB, Smart Vista solo disponibiliza No aplica diseño porque directamente lo implementa BPC con los requerimientos. | AD21: 46241
A22: HDU-SMART-R4-20 | B22: Smart Vista | C22: Liquidar totalmente compras diferidas. | D22: TDC | E22: Pagos anticipados y Liquidaciones de compras diferidas | F22: Liquidación total de compra diferida: capital pendiente + intereses devengados sin cobrar intereses futuros. Al liquidar, el pago fijo se cancela automáticamente. App solo permite liquidación total (no parcial). | G22: Monto = capital pendiente + intereses devengados, sin intereses futuros [RN-HU-058, RN-OP-S4-06]. Cancelación automática del pago fijo al liquidar [DEF RF-6]. Transacción SIWEB 623. App SOLO permite liquidación total, sucursal permite parcial y total [RN-HU-059]. Recálculo de intereses MCI para no cobrar no devengados. | H22: Smart Vista, App, SIWEB | I22: Cliente Final TDC | J22: Should | K22: Solución e Integración | L22: 2 | M22: Desarrollo + Configuración | N22: Nuevo Desarrollo <20% | O22: 2 | P22: 0 | Q22: {=+_xlfn.IFS(O22="","",O22<=1,"Baja",O22<=3,"Media",O22>3,"Alta")} -> Media | R22: {=+_xlfn.IFS(P22="","",P22<=0,"Baja",P22<=2,"Media",P22>2,"Alta")} -> Baja | S22: {=+_xlfn.IFS(N22="","",N22="Componentes existentes reutilizables >80%","Baja",N22="No Aplica","Baja",N22="Reutilización parcial 30-70%","Media",N22="Nuevo Desarrollo <20%","Alta")} -> Alta | T22: {=+_xlfn.IFS(L22="","",L22=0,"Baja",L22<=2,"Media",L22>=3,"Alta")} -> Media | U22: {=+IFERROR((+_xlfn.IFS(Q22="",0,Q22="Baja",1,Q22="Media",2,Q22="Alta",3)*'Scoring Complejidad'!$C$8+_xlfn.IFS(R22="Baja",1,R22="Media",2,R22="Alta",3)*'Scoring Complejidad'!$C$9+_xlfn.IFS(S22="Baja",1,S22="Media",2,S22="Alta",3)*'Scoring Complejidad'!$C$7+_xlfn.IFS(T22="",1,T22="Baja",1,T22="Media",2,T22="Alta",3)*'Scoring Complejidad'!$C$5+_xlfn.IFS(M22="Caja",1,M22="Configuración",2,M22="Desarrollo",3,M22="Desarrollo + Configuración",3,M22="No Aplica",0)*'Scoring Complejidad'!$C$6),"")} -> 2.35 | V22: {=IFERROR(_xlfn.IFS(U22="","",U22<=1.69,"Baja",U22<=2.29,"Media",U22<=3,"Alta",U22>3,"Error"),"")} -> Alta | W22: 46209 | X22: 46262 | Y22: No Aplica | Z22: No Aplica | AA22: 46244 | AB22: 46283 | AC22: Reutilización de APIs de R4-19 , validar con los DTMs que se generen para entender reutilización. Dependencia de APIs con SIWEB para pruebas integrales - DTMs son dependencia de SIWEB, Smart Vista solo disponibiliza No aplica diseño porque directamente lo implementa BPC con los requerimientos. | AD22: 46241
A23: HDU-SMART-R4-21 | B23: Smart Vista | C23: Cancelar compras diferidas en línea. | D23: TDC | E23: Pagos anticipados y Liquidaciones de compras diferidas | F23: Cancelación en línea del pago fijo desde el mismo día de apertura. Cancelación centralizada por impago (2 meses consecutivos) o aclaración de cargo no reconocido sin validación de identidad. Cargo en una exhibición al revolvente. Solo aplica a digital 4900. | G23: Cancelación posible desde el día de apertura [DEF RF-7]. Centralizada por 2 impagos consecutivos o aclaración, sin validación de identidad [RF-18/DEF RF-7]. Cargo 'Cargo por cancelación de CrediSoluciones'. Solo tarjetas digitales 4900 [RN-OP-S10-05]. NOTA: Estrategia E2E difiere RF-18 a R5 — validar con negocio. | H23: Smart Vista, App, SIWEB | I23: Cliente Final / Sistema (centralizado) | J23: Should | K23: Solución e Integración | L23: 2 | M23: Desarrollo | N23: Nuevo Desarrollo <20% | O23: 3 | P23: 0 | Q23: {=+_xlfn.IFS(O23="","",O23<=1,"Baja",O23<=3,"Media",O23>3,"Alta")} -> Media | R23: {=+_xlfn.IFS(P23="","",P23<=0,"Baja",P23<=2,"Media",P23>2,"Alta")} -> Baja | S23: {=+_xlfn.IFS(N23="","",N23="Componentes existentes reutilizables >80%","Baja",N23="No Aplica","Baja",N23="Reutilización parcial 30-70%","Media",N23="Nuevo Desarrollo <20%","Alta")} -> Alta | T23: {=+_xlfn.IFS(L23="","",L23=0,"Baja",L23<=2,"Media",L23>=3,"Alta")} -> Media | U23: {=+IFERROR((+_xlfn.IFS(Q23="",0,Q23="Baja",1,Q23="Media",2,Q23="Alta",3)*'Scoring Complejidad'!$C$8+_xlfn.IFS(R23="Baja",1,R23="Media",2,R23="Alta",3)*'Scoring Complejidad'!$C$9+_xlfn.IFS(S23="Baja",1,S23="Media",2,S23="Alta",3)*'Scoring Complejidad'!$C$7+_xlfn.IFS(T23="",1,T23="Baja",1,T23="Media",2,T23="Alta",3)*'Scoring Complejidad'!$C$5+_xlfn.IFS(M23="Caja",1,M23="Configuración",2,M23="Desarrollo",3,M23="Desarrollo + Configuración",3,M23="No Aplica",0)*'Scoring Complejidad'!$C$6),"")} -> 2.35 | V23: {=IFERROR(_xlfn.IFS(U23="","",U23<=1.69,"Baja",U23<=2.29,"Media",U23<=3,"Alta",U23>3,"Error"),"")} -> Alta | W23: 46209 | X23: 46262 | Y23: No Aplica | Z23: No Aplica | AA23: 46244 | AB23: 46283 | AC23: Reutilización de APIs de R4-19 , validar con los DTMs que se generen para entender reutilización. Dependencia de APIs con SIWEB para pruebas integrales - DTMs son dependencia de SIWEB, Smart Vista solo disponibiliza No aplica diseño porque directamente lo implementa BPC con los requerimientos. | AD23: 46241
A24: HDU-CAT-R4-01 | B24: CAT | C24: Alta producto 4900 en menú IVR. | D24: TDC | E24: Autoservicio TDC en IVR | F24: Alta del producto 4900 en el menú IVR del 800 BanCoppel con opciones 1-6. IVR acepta cuenta contrato a 18 dígitos (vs 12 del legado). Canal IVR parametrizado desde cero en SmartVista. Item 4 'Enviar CLABE por SMS' deshabilitado para 4900. | G24: Opciones 1-6 en menú IVR [DEF RF-13]. Cuenta contrato a 18 dígitos (vs 12 legado) [RN-OP-CAT-06]. Canal IVR parametrizado desde cero en SV [Comentado en sesión]. Item 4 CLABE por SMS deshabilitado para 4900 [RN-OP-CAT-07]. Validación ANI: coincidencia habilita consulta automática [RN-OP-CAT-01]. | H24: CAT (IVR) | I24: Cliente Final BanCoppel | J24: Must | K24: Solución e Integración | L24: 2 | M24: Desarrollo + Configuración | N24: Reutilización parcial 30-70% | O24: 3 | P24: 3 | Q24: {=+_xlfn.IFS(O24="","",O24<=1,"Baja",O24<=3,"Media",O24>3,"Alta")} -> Media | R24: {=+_xlfn.IFS(P24="","",P24<=0,"Baja",P24<=2,"Media",P24>2,"Alta")} -> Alta | S24: {=+_xlfn.IFS(N24="","",N24="Componentes existentes reutilizables >80%","Baja",N24="No Aplica","Baja",N24="Reutilización parcial 30-70%","Media",N24="Nuevo Desarrollo <20%","Alta")} -> Media | T24: {=+_xlfn.IFS(L24="","",L24=0,"Baja",L24<=2,"Media",L24>=3,"Alta")} -> Media | U24: {=+IFERROR((+_xlfn.IFS(Q24="",0,Q24="Baja",1,Q24="Media",2,Q24="Alta",3)*'Scoring Complejidad'!$C$8+_xlfn.IFS(R24="Baja",1,R24="Media",2,R24="Alta",3)*'Scoring Complejidad'!$C$9+_xlfn.IFS(S24="Baja",1,S24="Media",2,S24="Alta",3)*'Scoring Complejidad'!$C$7+_xlfn.IFS(T24="",1,T24="Baja",1,T24="Media",2,T24="Alta",3)*'Scoring Complejidad'!$C$5+_xlfn.IFS(M24="Caja",1,M24="Configuración",2,M24="Desarrollo",3,M24="Desarrollo + Configuración",3,M24="No Aplica",0)*'Scoring Complejidad'!$C$6),"")} -> 2.35 | V24: {=IFERROR(_xlfn.IFS(U24="","",U24<=1.69,"Baja",U24<=2.29,"Media",U24<=3,"Alta",U24>3,"Error"),"")} -> Alta | W24: 46167 | X24: 46234 | Y24: Dependencia DTMs | Z24: Dependencia DTMs | AA24: Dependencia DTMs | AB24: Dependencia DTMs | AC24: Fechas de implementación dependientes de proceso de contratación del proveedor nuevo (15 de Septiembre); Onboarding y habilitación de proveedor aproximado de 4 semanas. Pendiente revisar proveedor Fecha de fin de análisis pendiente de validar por Ramses Santos; Fechas de diseño e implementación dependientes de cierre de análisis y contratación de proveedor Consulta de clientes y cuentas - integraciones Considerar en etapas de diseño - certificación de arquitectura Fechas DTMS/ DTCs Appwhere - Alfredo | AD24: 46237
